{
    DataVersion: 3955,
    size: [9, 5, 5],
    data: [
        {pos: [0, 0, 0], state: "anvilcraft:cut_heavy_iron_block"},
        {pos: [0, 0, 1], state: "anvilcraft:cut_heavy_iron_block"},
        {pos: [0, 0, 2], state: "anvilcraft:cut_heavy_iron_block"},
        {pos: [0, 0, 3], state: "anvilcraft:cut_heavy_iron_block"},
        {pos: [0, 0, 4], state: "anvilcraft:cut_heavy_iron_block"},
        {pos: [1, 0, 0], state: "anvilcraft:cut_heavy_iron_block"},
        {pos: [1, 0, 1], state: "anvilcraft:cut_heavy_iron_slab{type:bottom,waterlogged:false}"},
        {pos: [1, 0, 2], state: "anvilcraft:cut_heavy_iron_slab{type:bottom,waterlogged:false}"},
        {pos: [1, 0, 3], state: "anvilcraft:cut_heavy_iron_slab{type:bottom,waterlogged:false}"},
        {pos: [1, 0, 4], state: "anvilcraft:cut_heavy_iron_block"},
        {pos: [2, 0, 0], state: "anvilcraft:cut_heavy_iron_block"},
        {pos: [2, 0, 1], state: "anvilcraft:cut_heavy_iron_slab{type:bottom,waterlogged:false}"},
        {pos: [2, 0, 2], state: "anvilcraft:cut_heavy_iron_block"},
        {pos: [2, 0, 3], state: "anvilcraft:cut_heavy_iron_slab{type:bottom,waterlogged:false}"},
        {pos: [2, 0, 4], state: "anvilcraft:cut_heavy_iron_block"},
        {pos: [3, 0, 0], state: "anvilcraft:cut_heavy_iron_block"},
        {pos: [3, 0, 1], state: "anvilcraft:cut_heavy_iron_slab{type:bottom,waterlogged:false}"},
        {pos: [3, 0, 2], state: "anvilcraft:cut_heavy_iron_slab{type:bottom,waterlogged:false}"},
        {pos: [3, 0, 3], state: "anvilcraft:cut_heavy_iron_slab{type:bottom,waterlogged:false}"},
        {pos: [3, 0, 4], state: "anvilcraft:cut_heavy_iron_block"},
        {pos: [4, 0, 0], state: "anvilcraft:cut_heavy_iron_block"},
        {pos: [4, 0, 1], state: "anvilcraft:cut_heavy_iron_block"},
        {pos: [4, 0, 2], state: "anvilcraft:cut_heavy_iron_block"},
        {pos: [4, 0, 3], state: "anvilcraft:cut_heavy_iron_block"},
        {pos: [4, 0, 4], state: "anvilcraft:cut_heavy_iron_block"},
        {pos: [0, 1, 0], state: "anvilcraft:tempering_glass"},
        {pos: [0, 1, 1], state: "anvilcraft:cut_heavy_iron_block"},
        {pos: [0, 1, 2], state: "anvilcraft:cut_heavy_iron_block"},
        {pos: [0, 1, 3], state: "anvilcraft:cut_heavy_iron_block"},
        {pos: [0, 1, 4], state: "anvilcraft:tempering_glass"},
        {pos: [1, 1, 0], state: "anvilcraft:tempering_glass"},
        {pos: [1, 1, 4], state: "anvilcraft:tempering_glass"},
        {pos: [2, 1, 0], state: "anvilcraft:tempering_glass"},
        {pos: [2, 1, 2], state: "anvilcraft:cut_heavy_iron_slab{type:bottom,waterlogged:false}"},
        {pos: [2, 1, 4], state: "anvilcraft:tempering_glass"},
        {pos: [3, 1, 0], state: "anvilcraft:tempering_glass"},
        {pos: [3, 1, 4], state: "anvilcraft:tempering_glass"},
        {pos: [4, 1, 0], state: "anvilcraft:tempering_glass"},
        {pos: [4, 1, 1], state: "anvilcraft:cut_heavy_iron_block"},
        {pos: [4, 1, 2], state: "anvilcraft:cut_heavy_iron_slab{type:bottom,waterlogged:false}"},
        {pos: [4, 1, 3], state: "anvilcraft:cut_heavy_iron_block"},
        {pos: [4, 1, 4], state: "anvilcraft:tempering_glass"},
        {pos: [0, 2, 0], state: "anvilcraft:tempering_glass"},
        {pos: [0, 2, 1], state: "anvilcraft:cut_heavy_iron_block"},
        {pos: [0, 2, 2], state: "anvilcraft:cut_heavy_iron_block"},
        {pos: [0, 2, 3], state: "anvilcraft:cut_heavy_iron_block"},
        {pos: [0, 2, 4], state: "anvilcraft:tempering_glass"},
        {pos: [1, 2, 0], state: "anvilcraft:tempering_glass"},
        {pos: [1, 2, 4], state: "anvilcraft:tempering_glass"},
        {pos: [2, 2, 0], state: "anvilcraft:tempering_glass"},
        {pos: [2, 2, 2], state: "minecraft:redstone_block"},
        {pos: [2, 2, 4], state: "anvilcraft:tempering_glass"},
        {pos: [3, 2, 0], state: "anvilcraft:tempering_glass"},
        {pos: [3, 2, 4], state: "anvilcraft:tempering_glass"},
        {pos: [4, 2, 0], state: "anvilcraft:tempering_glass"},
        {pos: [4, 2, 1], state: "anvilcraft:cut_heavy_iron_block"},
        {pos: [4, 2, 3], state: "anvilcraft:cut_heavy_iron_block"},
        {pos: [4, 2, 4], state: "anvilcraft:tempering_glass"},
        {pos: [6, 2, 2], state: "anvilcraft:arrow{facing:west}"},
        {pos: [8, 2, 2], state: "anvilcraft:royal_anvil{facing:west}"},
        {pos: [0, 3, 0], state: "anvilcraft:tempering_glass"},
        {pos: [0, 3, 1], state: "anvilcraft:cut_heavy_iron_block"},
        {pos: [0, 3, 2], state: "anvilcraft:cut_heavy_iron_block"},
        {pos: [0, 3, 3], state: "anvilcraft:cut_heavy_iron_block"},
        {pos: [0, 3, 4], state: "anvilcraft:tempering_glass"},
        {pos: [1, 3, 0], state: "anvilcraft:tempering_glass"},
        {pos: [1, 3, 4], state: "anvilcraft:tempering_glass"},
        {pos: [2, 3, 0], state: "anvilcraft:tempering_glass"},
        {pos: [2, 3, 2], state: "anvilcraft:cut_heavy_iron_slab{type:bottom,waterlogged:false}"},
        {pos: [2, 3, 4], state: "anvilcraft:tempering_glass"},
        {pos: [3, 3, 0], state: "anvilcraft:tempering_glass"},
        {pos: [3, 3, 4], state: "anvilcraft:tempering_glass"},
        {pos: [4, 3, 0], state: "anvilcraft:tempering_glass"},
        {pos: [4, 3, 1], state: "anvilcraft:cut_heavy_iron_block"},
        {pos: [4, 3, 2], state: "anvilcraft:cut_heavy_iron_block"},
        {pos: [4, 3, 3], state: "anvilcraft:cut_heavy_iron_block"},
        {pos: [4, 3, 4], state: "anvilcraft:tempering_glass"},
        {pos: [0, 4, 0], state: "anvilcraft:cut_heavy_iron_slab{type:bottom,waterlogged:false}"},
        {pos: [0, 4, 1], state: "anvilcraft:cut_heavy_iron_slab{type:bottom,waterlogged:false}"},
        {pos: [0, 4, 2], state: "anvilcraft:cut_heavy_iron_slab{type:bottom,waterlogged:false}"},
        {pos: [0, 4, 3], state: "anvilcraft:cut_heavy_iron_slab{type:bottom,waterlogged:false}"},
        {pos: [0, 4, 4], state: "anvilcraft:cut_heavy_iron_slab{type:bottom,waterlogged:false}"},
        {pos: [1, 4, 0], state: "anvilcraft:cut_heavy_iron_slab{type:bottom,waterlogged:false}"},
        {pos: [1, 4, 4], state: "anvilcraft:cut_heavy_iron_slab{type:bottom,waterlogged:false}"},
        {pos: [2, 4, 0], state: "anvilcraft:cut_heavy_iron_slab{type:bottom,waterlogged:false}"},
        {pos: [2, 4, 4], state: "anvilcraft:cut_heavy_iron_slab{type:bottom,waterlogged:false}"},
        {pos: [3, 4, 0], state: "anvilcraft:cut_heavy_iron_slab{type:bottom,waterlogged:false}"},
        {pos: [3, 4, 4], state: "anvilcraft:cut_heavy_iron_slab{type:bottom,waterlogged:false}"},
        {pos: [4, 4, 0], state: "anvilcraft:cut_heavy_iron_slab{type:bottom,waterlogged:false}"},
        {pos: [4, 4, 1], state: "anvilcraft:cut_heavy_iron_slab{type:bottom,waterlogged:false}"},
        {pos: [4, 4, 2], state: "anvilcraft:cut_heavy_iron_slab{type:bottom,waterlogged:false}"},
        {pos: [4, 4, 3], state: "anvilcraft:cut_heavy_iron_slab{type:bottom,waterlogged:false}"},
        {pos: [4, 4, 4], state: "anvilcraft:cut_heavy_iron_slab{type:bottom,waterlogged:false}"}
    ],
    entities: [],
    palette: [
        "anvilcraft:cut_heavy_iron_block",
        "anvilcraft:tempering_glass",
        "minecraft:redstone_block",
        "anvilcraft:cut_heavy_iron_slab{type:bottom,waterlogged:false}",
        "anvilcraft:arrow{facing:west}",
        "anvilcraft:royal_anvil{facing:west}"
    ]
}