{
    DataVersion: 3955,
    size: [4, 5, 5],
    data: [
        {pos: [0, 0, 1], state: "minecraft:iron_block"},
        {pos: [0, 0, 2], state: "minecraft:iron_block"},
        {pos: [0, 0, 3], state: "minecraft:iron_block"},
        {pos: [1, 0, 1], state: "minecraft:iron_block"},
        {pos: [1, 0, 2], state: "minecraft:iron_block"},
        {pos: [1, 0, 3], state: "minecraft:iron_block"},
        {pos: [2, 0, 1], state: "minecraft:iron_block"},
        {pos: [2, 0, 2], state: "minecraft:iron_block"},
        {pos: [2, 0, 3], state: "minecraft:iron_block"},
        {pos: [0, 1, 1], state: "minecraft:chest{facing:north,type:single,waterlogged:false}", nbt: {Items: [], id: "minecraft:chest"}},
        {pos: [0, 1, 3], state: "minecraft:note_block{instrument:iron_xylophone,note:1,powered:false}"},
        {pos: [1, 1, 1], state: "anvilcraft:chute{enabled:true,facing:west}", nbt: {Cooldown: 0, Inventory: {FilterEnabled: 0b, Inventory: [{Disabled: 0b, IsEmptySlot: 1b, Slot: 0, SlotFilterEnabled: 0b, SlotLimit: 64}, {Disabled: 0b, IsEmptySlot: 1b, Slot: 1, SlotFilterEnabled: 0b, SlotLimit: 64}, {Disabled: 0b, IsEmptySlot: 1b, Slot: 2, SlotFilterEnabled: 0b, SlotLimit: 64}, {Disabled: 0b, IsEmptySlot: 1b, Slot: 3, SlotFilterEnabled: 0b, SlotLimit: 64}, {Disabled: 0b, IsEmptySlot: 1b, Slot: 4, SlotFilterEnabled: 0b, SlotLimit: 64}, {Disabled: 0b, IsEmptySlot: 1b, Slot: 5, SlotFilterEnabled: 0b, SlotLimit: 64}, {Disabled: 0b, IsEmptySlot: 1b, Slot: 6, SlotFilterEnabled: 0b, SlotLimit: 64}, {Disabled: 0b, IsEmptySlot: 1b, Slot: 7, SlotFilterEnabled: 0b, SlotLimit: 64}, {Disabled: 0b, IsEmptySlot: 1b, Slot: 8, SlotFilterEnabled: 0b, SlotLimit: 64}], Size: 9}, id: "anvilcraft:chute"}},
        {pos: [1, 1, 2], state: "anvilcraft:corrupted_beacon{lit:true}", nbt: {id: "anvilcraft:corrupted_beacon"}},
        {pos: [1, 1, 3], state: "minecraft:observer{facing:east,powered:false}"},
        {pos: [2, 1, 2], state: "anvilcraft:heater{overload:false}", nbt: {id: "anvilcraft:heater"}},
        {pos: [2, 1, 3], state: "minecraft:observer{facing:up,powered:false}"},
        {pos: [3, 1, 3], state: "minecraft:smooth_stone"},
        {pos: [0, 2, 2], state: "minecraft:sticky_piston{extended:true,facing:east}"},
        {pos: [0, 2, 3], state: "minecraft:observer{facing:down,powered:false}"},
        {pos: [1, 2, 2], state: "minecraft:piston_head{facing:east,short:false,type:sticky}"},
        {pos: [1, 2, 3], state: "minecraft:observer{facing:down,powered:false}"},
        {pos: [2, 2, 1], state: "anvilcraft:chute{enabled:true,facing:south}", nbt: {Cooldown: 0, Inventory: {FilterEnabled: 0b, Inventory: [{Disabled: 0b, IsEmptySlot: 1b, Slot: 0, SlotFilterEnabled: 0b, SlotLimit: 64}, {Disabled: 0b, IsEmptySlot: 1b, Slot: 1, SlotFilterEnabled: 0b, SlotLimit: 64}, {Disabled: 0b, IsEmptySlot: 1b, Slot: 2, SlotFilterEnabled: 0b, SlotLimit: 64}, {Disabled: 0b, IsEmptySlot: 1b, Slot: 3, SlotFilterEnabled: 0b, SlotLimit: 64}, {Disabled: 0b, IsEmptySlot: 1b, Slot: 4, SlotFilterEnabled: 0b, SlotLimit: 64}, {Disabled: 0b, IsEmptySlot: 1b, Slot: 5, SlotFilterEnabled: 0b, SlotLimit: 64}, {Disabled: 0b, IsEmptySlot: 1b, Slot: 6, SlotFilterEnabled: 0b, SlotLimit: 64}, {Disabled: 0b, IsEmptySlot: 1b, Slot: 7, SlotFilterEnabled: 0b, SlotLimit: 64}, {Disabled: 0b, IsEmptySlot: 1b, Slot: 8, SlotFilterEnabled: 0b, SlotLimit: 64}], Size: 9}, id: "anvilcraft:chute"}},
        {pos: [2, 2, 2], state: "minecraft:cauldron"},
        {pos: [2, 2, 3], state: "minecraft:observer{facing:north,powered:false}"},
        {pos: [2, 2, 4], state: "minecraft:smooth_stone"},
        {pos: [3, 2, 1], state: "minecraft:dropper{facing:west,triggered:true}", nbt: {Items: [], id: "minecraft:dropper"}},
        {pos: [3, 2, 2], state: "minecraft:dropper{facing:west,triggered:true}", nbt: {Items: [], id: "minecraft:dropper"}},
        {pos: [3, 2, 3], state: "minecraft:comparator{facing:south,mode:compare,powered:true}", nbt: {OutputSignal: 15, id: "minecraft:comparator"}},
        {pos: [3, 2, 4], state: "minecraft:weathered_copper_bulb{lit:true,powered:false}"},
        {pos: [0, 3, 2], state: "minecraft:note_block{instrument:harp,note:2,powered:true}"},
        {pos: [0, 3, 3], state: "minecraft:smooth_stone"},
        {pos: [1, 3, 2], state: "anvilcraft:spectral_anvil{facing:west,powered:false}"},
        {pos: [1, 3, 3], state: "minecraft:observer{facing:down,powered:false}"},
        {pos: [2, 3, 2], state: "anvilcraft:spectral_anvil{facing:west,powered:true}"},
        {pos: [2, 3, 3], state: "minecraft:observer{facing:down,powered:false}"},
        {pos: [3, 3, 4], state: "minecraft:oak_button{face:floor,facing:south,powered:false}"},
        {pos: [0, 4, 2], state: "minecraft:lever{face:floor,facing:west,powered:true}"},
        {pos: [1, 4, 2], state: "anvilcraft:hollow_magnet_block{lit:true,waterlogged:false}"},
        {pos: [1, 4, 3], state: "minecraft:smooth_stone"},
        {pos: [2, 4, 2], state: "anvilcraft:hollow_magnet_block{lit:false,waterlogged:false}"},
        {pos: [2, 4, 3], state: "minecraft:smooth_stone"}
    ],
    entities: [],
    palette: [
        "minecraft:iron_block",
        "minecraft:note_block{instrument:iron_xylophone,note:1,powered:false}",
        "minecraft:observer{facing:east,powered:false}",
        "minecraft:observer{facing:up,powered:false}",
        "minecraft:smooth_stone",
        "minecraft:observer{facing:down,powered:false}",
        "minecraft:observer{facing:north,powered:false}",
        "minecraft:weathered_copper_bulb{lit:true,powered:false}",
        "minecraft:note_block{instrument:harp,note:2,powered:true}",
        "minecraft:sticky_piston{extended:true,facing:east}",
        "minecraft:piston_head{facing:east,short:false,type:sticky}",
        "minecraft:cauldron",
        "anvilcraft:spectral_anvil{facing:west,powered:false}",
        "anvilcraft:spectral_anvil{facing:west,powered:true}",
        "minecraft:oak_button{face:floor,facing:south,powered:false}",
        "minecraft:lever{face:floor,facing:west,powered:true}",
        "anvilcraft:hollow_magnet_block{lit:true,waterlogged:false}",
        "anvilcraft:hollow_magnet_block{lit:false,waterlogged:false}",
        "minecraft:chest{facing:north,type:single,waterlogged:false}",
        "anvilcraft:chute{enabled:true,facing:west}",
        "anvilcraft:corrupted_beacon{lit:true}",
        "anvilcraft:heater{overload:false}",
        "anvilcraft:chute{enabled:true,facing:south}",
        "minecraft:dropper{facing:west,triggered:true}",
        "minecraft:comparator{facing:south,mode:compare,powered:true}"
    ]
}