{
    DataVersion: 3955,
    size: [8, 11, 3],
    data: [
        {pos: [0, 0, 0], state: "anvilcraft:piezoelectric_crystal"},
        {pos: [1, 0, 0], state: "anvilcraft:piezoelectric_crystal"},
        {pos: [2, 0, 0], state: "anvilcraft:piezoelectric_crystal"},
        {pos: [3, 0, 0], state: "anvilcraft:piezoelectric_crystal"},
        {pos: [4, 0, 0], state: "anvilcraft:piezoelectric_crystal"},
        {pos: [0, 1, 0], state: "anvilcraft:piezoelectric_crystal"},
        {pos: [1, 1, 0], state: "anvilcraft:piezoelectric_crystal"},
        {pos: [1, 1, 1], state: "anvilcraft:charge_collector{powered:false}", nbt: {ChargeCount: 0.0d, Charges: [I; 0, 0, 0, 60, 0, 0, 0, 0, 0, 0, 0], InputCooldownCount: 2, OutputCooldownCount: 10, Power: 5, id: "anvilcraft:charge_collector"}},
        {pos: [2, 1, 0], state: "anvilcraft:piezoelectric_crystal"},
        {pos: [3, 1, 0], state: "anvilcraft:piezoelectric_crystal"},
        {pos: [3, 1, 1], state: "anvilcraft:charge_collector{powered:false}", nbt: {ChargeCount: 0.0d, Charges: [I; 0, 0, 0, 45, 45, 0, 0, 0, 0, 0, 0], InputCooldownCount: 1, OutputCooldownCount: 1, Power: 8, id: "anvilcraft:charge_collector"}},
        {pos: [4, 1, 0], state: "anvilcraft:piezoelectric_crystal"},
        {pos: [0, 2, 0], state: "anvilcraft:piezoelectric_crystal"},
        {pos: [1, 2, 0], state: "anvilcraft:piezoelectric_crystal"},
        {pos: [2, 2, 0], state: "anvilcraft:piezoelectric_crystal"},
        {pos: [3, 2, 0], state: "anvilcraft:piezoelectric_crystal"},
        {pos: [4, 2, 0], state: "anvilcraft:piezoelectric_crystal"},
        {pos: [0, 3, 0], state: "anvilcraft:piezoelectric_crystal"},
        {pos: [1, 3, 0], state: "anvilcraft:piezoelectric_crystal"},
        {pos: [2, 3, 0], state: "anvilcraft:piezoelectric_crystal"},
        {pos: [3, 3, 0], state: "anvilcraft:piezoelectric_crystal"},
        {pos: [4, 3, 0], state: "anvilcraft:piezoelectric_crystal"},
        {pos: [7, 3, 1], state: "minecraft:lever{face:wall,facing:north,powered:false}"},
        {pos: [7, 3, 2], state: "minecraft:smooth_stone"},
        {pos: [7, 4, 2], state: "minecraft:redstone_torch{lit:true}"},
        {pos: [7, 5, 2], state: "minecraft:smooth_stone"},
        {pos: [7, 6, 2], state: "minecraft:redstone_torch{lit:false}"},
        {pos: [7, 7, 2], state: "minecraft:smooth_stone"},
        {pos: [0, 8, 0], state: "anvilcraft:royal_anvil{facing:west}"},
        {pos: [1, 8, 0], state: "anvilcraft:royal_anvil{facing:west}"},
        {pos: [2, 8, 0], state: "anvilcraft:royal_anvil{facing:west}"},
        {pos: [3, 8, 0], state: "anvilcraft:royal_anvil{facing:west}"},
        {pos: [4, 8, 0], state: "anvilcraft:royal_anvil{facing:west}"},
        {pos: [7, 8, 2], state: "minecraft:redstone_torch{lit:true}"},
        {pos: [0, 9, 0], state: "anvilcraft:hollow_magnet_block{lit:false,waterlogged:false}"},
        {pos: [0, 9, 1], state: "minecraft:slime_block"},
        {pos: [1, 9, 0], state: "anvilcraft:hollow_magnet_block{lit:false,waterlogged:false}"},
        {pos: [1, 9, 1], state: "minecraft:slime_block"},
        {pos: [2, 9, 0], state: "anvilcraft:hollow_magnet_block{lit:false,waterlogged:false}"},
        {pos: [2, 9, 1], state: "minecraft:slime_block"},
        {pos: [3, 9, 0], state: "anvilcraft:hollow_magnet_block{lit:false,waterlogged:false}"},
        {pos: [3, 9, 1], state: "minecraft:slime_block"},
        {pos: [4, 9, 0], state: "anvilcraft:hollow_magnet_block{lit:false,waterlogged:false}"},
        {pos: [4, 9, 1], state: "minecraft:slime_block"},
        {pos: [4, 9, 2], state: "minecraft:sticky_piston{extended:false,facing:north}"},
        {pos: [5, 9, 2], state: "minecraft:smooth_stone"},
        {pos: [6, 9, 2], state: "anvilcraft:pulse_generator{facing:east,powered:false}", nbt: {ExtraData: {Inputting: 1b, OutputMode: 0b, SignalDuration: 9, StartMode: 2b, State: 0b, WaitingTime: 1}, id: "anvilcraft:pulse_generator"}},
        {pos: [7, 9, 2], state: "minecraft:smooth_stone"},
        {pos: [4, 10, 1], state: "minecraft:sticky_piston{extended:false,facing:down}"},
        {pos: [5, 10, 0], state: "minecraft:smooth_stone"},
        {pos: [5, 10, 1], state: "anvilcraft:pulse_generator{facing:south,powered:false}", nbt: {ExtraData: {Inputting: 0b, OutputMode: 0b, SignalDuration: 3, StartMode: 0b, State: 0b, WaitingTime: 3}, id: "anvilcraft:pulse_generator"}},
        {pos: [5, 10, 2], state: "minecraft:redstone_wire{east:none,north:side,power:0,south:side,west:none}"}
    ],
    entities: [],
    palette: [
        "minecraft:smooth_stone",
        "minecraft:slime_block",
        "minecraft:sticky_piston{extended:false,facing:north}",
        "minecraft:sticky_piston{extended:false,facing:down}",
        "anvilcraft:piezoelectric_crystal",
        "minecraft:lever{face:wall,facing:north,powered:false}",
        "minecraft:redstone_torch{lit:true}",
        "minecraft:redstone_torch{lit:false}",
        "anvilcraft:royal_anvil{facing:west}",
        "anvilcraft:hollow_magnet_block{lit:false,waterlogged:false}",
        "minecraft:redstone_wire{east:none,north:side,power:0,south:side,west:none}",
        "anvilcraft:charge_collector{powered:false}",
        "anvilcraft:pulse_generator{facing:east,powered:false}",
        "anvilcraft:pulse_generator{facing:south,powered:false}"
    ]
}