{
    DataVersion: 3955,
    size: [6, 5, 3],
    data: [
        {pos: [0, 0, 0], state: "anvilcraft:piezoelectric_crystal"},
        {pos: [0, 0, 2], state: "anvilcraft:piezoelectric_crystal"},
        {pos: [1, 0, 0], state: "anvilcraft:piezoelectric_crystal"},
        {pos: [1, 0, 1], state: "anvilcraft:charge_collector{powered:false}", nbt: {ChargeCount: 0.0d, Charges: [I; 0, 0, 0, 0, 0, 0, 0, 0, 0, 0, 0], InputCooldownCount: 1, OutputCooldownCount: 5, Power: 0, id: "anvilcraft:charge_collector"}},
        {pos: [1, 0, 2], state: "anvilcraft:piezoelectric_crystal"},
        {pos: [2, 0, 0], state: "anvilcraft:piezoelectric_crystal"},
        {pos: [2, 0, 2], state: "anvilcraft:piezoelectric_crystal"},
        {pos: [3, 0, 0], state: "anvilcraft:piezoelectric_crystal"},
        {pos: [3, 0, 2], state: "anvilcraft:piezoelectric_crystal"},
        {pos: [0, 2, 0], state: "minecraft:damaged_anvil{facing:west}"},
        {pos: [0, 2, 2], state: "minecraft:damaged_anvil{facing:west}"},
        {pos: [1, 2, 0], state: "minecraft:damaged_anvil{facing:west}"},
        {pos: [1, 2, 2], state: "minecraft:damaged_anvil{facing:west}"},
        {pos: [2, 2, 0], state: "minecraft:damaged_anvil{facing:west}"},
        {pos: [2, 2, 2], state: "minecraft:damaged_anvil{facing:west}"},
        {pos: [3, 2, 0], state: "minecraft:damaged_anvil{facing:west}"},
        {pos: [3, 2, 2], state: "minecraft:damaged_anvil{facing:west}"},
        {pos: [5, 2, 1], state: "minecraft:lever{face:ceiling,facing:west,powered:true}"},
        {pos: [0, 3, 0], state: "anvilcraft:hollow_magnet_block{lit:false,waterlogged:false}"},
        {pos: [0, 3, 1], state: "minecraft:smooth_stone"},
        {pos: [0, 3, 2], state: "anvilcraft:hollow_magnet_block{lit:false,waterlogged:false}"},
        {pos: [1, 3, 0], state: "anvilcraft:hollow_magnet_block{lit:false,waterlogged:false}"},
        {pos: [1, 3, 1], state: "minecraft:smooth_stone"},
        {pos: [1, 3, 2], state: "anvilcraft:hollow_magnet_block{lit:false,waterlogged:false}"},
        {pos: [2, 3, 0], state: "anvilcraft:hollow_magnet_block{lit:false,waterlogged:false}"},
        {pos: [2, 3, 1], state: "minecraft:smooth_stone"},
        {pos: [2, 3, 2], state: "anvilcraft:hollow_magnet_block{lit:false,waterlogged:false}"},
        {pos: [3, 3, 0], state: "anvilcraft:hollow_magnet_block{lit:false,waterlogged:false}"},
        {pos: [3, 3, 1], state: "minecraft:smooth_stone"},
        {pos: [3, 3, 2], state: "anvilcraft:hollow_magnet_block{lit:false,waterlogged:false}"},
        {pos: [4, 3, 1], state: "anvilcraft:pulse_generator{facing:east,powered:false}", nbt: {ExtraData: {Inputting: 1b, OutputMode: 0b, SignalDuration: 4, StartMode: 2b, State: 0b, WaitingTime: 5}, id: "anvilcraft:pulse_generator"}},
        {pos: [5, 3, 1], state: "minecraft:smooth_stone"},
        {pos: [0, 4, 1], state: "minecraft:redstone_wire{east:side,north:none,power:0,south:none,west:side}"},
        {pos: [1, 4, 1], state: "minecraft:redstone_wire{east:side,north:none,power:0,south:none,west:side}"},
        {pos: [2, 4, 1], state: "minecraft:redstone_wire{east:side,north:none,power:0,south:none,west:side}"},
        {pos: [3, 4, 1], state: "minecraft:redstone_wire{east:side,north:none,power:0,south:none,west:side}"}
    ],
    entities: [],
    palette: [
        "minecraft:smooth_stone",
        "anvilcraft:piezoelectric_crystal",
        "minecraft:damaged_anvil{facing:west}",
        "minecraft:lever{face:ceiling,facing:west,powered:true}",
        "anvilcraft:hollow_magnet_block{lit:false,waterlogged:false}",
        "minecraft:redstone_wire{east:side,north:none,power:0,south:none,west:side}",
        "anvilcraft:charge_collector{powered:false}",
        "anvilcraft:pulse_generator{facing:east,powered:false}"
    ]
}