{
    DataVersion: 3955,
    size: [23, 4, 23],
    data: [
        {pos: [0, 0, 0], state: "anvilcraft:deflection_ring{facing:down,half:bottom_wn,overload:false,switch:on}", nbt: {id: "anvilcraft:deflection_ring", lastEntitySpeed: 0.0d}},
        {pos: [0, 0, 1], state: "anvilcraft:deflection_ring{facing:down,half:bottom_w,overload:false,switch:on}", nbt: {id: "anvilcraft:deflection_ring", lastEntitySpeed: 0.0d}},
        {pos: [0, 0, 2], state: "anvilcraft:deflection_ring{facing:down,half:bottom_ws,overload:false,switch:on}", nbt: {id: "anvilcraft:deflection_ring", lastEntitySpeed: 0.0d}},
        {pos: [0, 0, 3], state: "anvilcraft:acceleration_ring{facing:north,half:bottom_wn,overload:false,switch:on}", nbt: {id: "anvilcraft:acceleration_ring"}},
        {pos: [0, 0, 4], state: "anvilcraft:acceleration_ring{facing:north,half:bottom_w,overload:false,switch:on}", nbt: {id: "anvilcraft:acceleration_ring"}},
        {pos: [0, 0, 5], state: "anvilcraft:acceleration_ring{facing:north,half:bottom_ws,overload:false,switch:on}", nbt: {id: "anvilcraft:acceleration_ring"}},
        {pos: [0, 0, 17], state: "anvilcraft:acceleration_ring{facing:north,half:bottom_wn,overload:false,switch:on}", nbt: {id: "anvilcraft:acceleration_ring"}},
        {pos: [0, 0, 18], state: "anvilcraft:acceleration_ring{facing:north,half:bottom_w,overload:false,switch:on}", nbt: {id: "anvilcraft:acceleration_ring"}},
        {pos: [0, 0, 19], state: "anvilcraft:acceleration_ring{facing:north,half:bottom_ws,overload:false,switch:on}", nbt: {id: "anvilcraft:acceleration_ring"}},
        {pos: [0, 0, 20], state: "anvilcraft:deflection_ring{facing:down,half:bottom_wn,overload:false,switch:on}", nbt: {id: "anvilcraft:deflection_ring", lastEntitySpeed: 0.0d}},
        {pos: [0, 0, 21], state: "anvilcraft:deflection_ring{facing:down,half:bottom_w,overload:false,switch:on}", nbt: {id: "anvilcraft:deflection_ring", lastEntitySpeed: 0.0d}},
        {pos: [0, 0, 22], state: "anvilcraft:deflection_ring{facing:down,half:bottom_ws,overload:false,switch:on}", nbt: {id: "anvilcraft:deflection_ring", lastEntitySpeed: 0.0d}},
        {pos: [1, 0, 0], state: "anvilcraft:deflection_ring{facing:down,half:bottom_n,overload:false,switch:on}", nbt: {id: "anvilcraft:deflection_ring", lastEntitySpeed: 0.0d}},
        {pos: [1, 0, 1], state: "anvilcraft:deflection_ring{facing:down,half:bottom_center,overload:false,switch:on}", nbt: {id: "anvilcraft:deflection_ring", lastEntitySpeed: 0.0d}},
        {pos: [1, 0, 2], state: "anvilcraft:deflection_ring{facing:down,half:bottom_s,overload:false,switch:on}", nbt: {id: "anvilcraft:deflection_ring", lastEntitySpeed: 0.0d}},
        {pos: [1, 0, 3], state: "anvilcraft:acceleration_ring{facing:north,half:bottom_n,overload:false,switch:on}", nbt: {id: "anvilcraft:acceleration_ring"}},
        {pos: [1, 0, 4], state: "anvilcraft:acceleration_ring{facing:north,half:bottom_center,overload:false,switch:on}", nbt: {id: "anvilcraft:acceleration_ring"}},
        {pos: [1, 0, 5], state: "anvilcraft:acceleration_ring{facing:north,half:bottom_s,overload:false,switch:on}", nbt: {id: "anvilcraft:acceleration_ring"}},
        {pos: [1, 0, 6], state: "minecraft:smooth_stone"},
        {pos: [1, 0, 7], state: "minecraft:smooth_stone"},
        {pos: [1, 0, 8], state: "minecraft:smooth_stone"},
        {pos: [1, 0, 9], state: "minecraft:smooth_stone"},
        {pos: [1, 0, 10], state: "minecraft:smooth_stone"},
        {pos: [1, 0, 11], state: "minecraft:smooth_stone"},
        {pos: [1, 0, 12], state: "minecraft:smooth_stone"},
        {pos: [1, 0, 13], state: "minecraft:smooth_stone"},
        {pos: [1, 0, 14], state: "minecraft:smooth_stone"},
        {pos: [1, 0, 15], state: "minecraft:smooth_stone"},
        {pos: [1, 0, 16], state: "minecraft:smooth_stone"},
        {pos: [1, 0, 17], state: "anvilcraft:acceleration_ring{facing:north,half:bottom_n,overload:false,switch:on}", nbt: {id: "anvilcraft:acceleration_ring"}},
        {pos: [1, 0, 18], state: "anvilcraft:acceleration_ring{facing:north,half:bottom_center,overload:false,switch:on}", nbt: {id: "anvilcraft:acceleration_ring"}},
        {pos: [1, 0, 19], state: "anvilcraft:acceleration_ring{facing:north,half:bottom_s,overload:false,switch:on}", nbt: {id: "anvilcraft:acceleration_ring"}},
        {pos: [1, 0, 20], state: "anvilcraft:deflection_ring{facing:down,half:bottom_n,overload:false,switch:on}", nbt: {id: "anvilcraft:deflection_ring", lastEntitySpeed: 0.0d}},
        {pos: [1, 0, 21], state: "anvilcraft:deflection_ring{facing:down,half:bottom_center,overload:false,switch:on}", nbt: {id: "anvilcraft:deflection_ring", lastEntitySpeed: 0.0d}},
        {pos: [1, 0, 22], state: "anvilcraft:deflection_ring{facing:down,half:bottom_s,overload:false,switch:on}", nbt: {id: "anvilcraft:deflection_ring", lastEntitySpeed: 0.0d}},
        {pos: [2, 0, 0], state: "anvilcraft:deflection_ring{facing:down,half:bottom_en,overload:false,switch:on}", nbt: {id: "anvilcraft:deflection_ring", lastEntitySpeed: 0.0d}},
        {pos: [2, 0, 1], state: "anvilcraft:deflection_ring{facing:down,half:bottom_e,overload:false,switch:on}", nbt: {id: "anvilcraft:deflection_ring", lastEntitySpeed: 0.0d}},
        {pos: [2, 0, 2], state: "anvilcraft:deflection_ring{facing:down,half:bottom_es,overload:false,switch:on}", nbt: {id: "anvilcraft:deflection_ring", lastEntitySpeed: 0.0d}},
        {pos: [2, 0, 3], state: "anvilcraft:acceleration_ring{facing:north,half:bottom_en,overload:false,switch:on}", nbt: {id: "anvilcraft:acceleration_ring"}},
        {pos: [2, 0, 4], state: "anvilcraft:acceleration_ring{facing:north,half:bottom_e,overload:false,switch:on}", nbt: {id: "anvilcraft:acceleration_ring"}},
        {pos: [2, 0, 5], state: "anvilcraft:acceleration_ring{facing:north,half:bottom_es,overload:false,switch:on}", nbt: {id: "anvilcraft:acceleration_ring"}},
        {pos: [2, 0, 17], state: "anvilcraft:acceleration_ring{facing:north,half:bottom_en,overload:false,switch:on}", nbt: {id: "anvilcraft:acceleration_ring"}},
        {pos: [2, 0, 18], state: "anvilcraft:acceleration_ring{facing:north,half:bottom_e,overload:false,switch:on}", nbt: {id: "anvilcraft:acceleration_ring"}},
        {pos: [2, 0, 19], state: "anvilcraft:acceleration_ring{facing:north,half:bottom_es,overload:false,switch:on}", nbt: {id: "anvilcraft:acceleration_ring"}},
        {pos: [2, 0, 20], state: "anvilcraft:deflection_ring{facing:down,half:bottom_en,overload:false,switch:on}", nbt: {id: "anvilcraft:deflection_ring", lastEntitySpeed: 0.0d}},
        {pos: [2, 0, 21], state: "anvilcraft:deflection_ring{facing:down,half:bottom_e,overload:false,switch:on}", nbt: {id: "anvilcraft:deflection_ring", lastEntitySpeed: 0.0d}},
        {pos: [2, 0, 22], state: "anvilcraft:deflection_ring{facing:down,half:bottom_es,overload:false,switch:on}", nbt: {id: "anvilcraft:deflection_ring", lastEntitySpeed: 0.0d}},
        {pos: [3, 0, 0], state: "anvilcraft:acceleration_ring{facing:east,half:bottom_wn,overload:false,switch:on}", nbt: {id: "anvilcraft:acceleration_ring"}},
        {pos: [3, 0, 1], state: "anvilcraft:acceleration_ring{facing:east,half:bottom_w,overload:false,switch:on}", nbt: {id: "anvilcraft:acceleration_ring"}},
        {pos: [3, 0, 2], state: "anvilcraft:acceleration_ring{facing:east,half:bottom_ws,overload:false,switch:on}", nbt: {id: "anvilcraft:acceleration_ring"}},
        {pos: [3, 0, 20], state: "anvilcraft:acceleration_ring{facing:west,half:bottom_wn,overload:false,switch:on}", nbt: {id: "anvilcraft:acceleration_ring"}},
        {pos: [3, 0, 21], state: "anvilcraft:acceleration_ring{facing:west,half:bottom_w,overload:false,switch:on}", nbt: {id: "anvilcraft:acceleration_ring"}},
        {pos: [3, 0, 22], state: "anvilcraft:acceleration_ring{facing:west,half:bottom_ws,overload:false,switch:on}", nbt: {id: "anvilcraft:acceleration_ring"}},
        {pos: [4, 0, 0], state: "anvilcraft:acceleration_ring{facing:east,half:bottom_n,overload:false,switch:on}", nbt: {id: "anvilcraft:acceleration_ring"}},
        {pos: [4, 0, 1], state: "anvilcraft:acceleration_ring{facing:east,half:bottom_center,overload:false,switch:on}", nbt: {id: "anvilcraft:acceleration_ring"}},
        {pos: [4, 0, 2], state: "anvilcraft:acceleration_ring{facing:east,half:bottom_s,overload:false,switch:on}", nbt: {id: "anvilcraft:acceleration_ring"}},
        {pos: [4, 0, 20], state: "anvilcraft:acceleration_ring{facing:west,half:bottom_n,overload:false,switch:on}", nbt: {id: "anvilcraft:acceleration_ring"}},
        {pos: [4, 0, 21], state: "anvilcraft:acceleration_ring{facing:west,half:bottom_center,overload:false,switch:on}", nbt: {id: "anvilcraft:acceleration_ring"}},
        {pos: [4, 0, 22], state: "anvilcraft:acceleration_ring{facing:west,half:bottom_s,overload:false,switch:on}", nbt: {id: "anvilcraft:acceleration_ring"}},
        {pos: [5, 0, 0], state: "anvilcraft:acceleration_ring{facing:east,half:bottom_en,overload:false,switch:on}", nbt: {id: "anvilcraft:acceleration_ring"}},
        {pos: [5, 0, 1], state: "anvilcraft:acceleration_ring{facing:east,half:bottom_e,overload:false,switch:on}", nbt: {id: "anvilcraft:acceleration_ring"}},
        {pos: [5, 0, 2], state: "anvilcraft:acceleration_ring{facing:east,half:bottom_es,overload:false,switch:on}", nbt: {id: "anvilcraft:acceleration_ring"}},
        {pos: [5, 0, 20], state: "anvilcraft:acceleration_ring{facing:west,half:bottom_en,overload:false,switch:on}", nbt: {id: "anvilcraft:acceleration_ring"}},
        {pos: [5, 0, 21], state: "anvilcraft:acceleration_ring{facing:west,half:bottom_e,overload:false,switch:on}", nbt: {id: "anvilcraft:acceleration_ring"}},
        {pos: [5, 0, 22], state: "anvilcraft:acceleration_ring{facing:west,half:bottom_es,overload:false,switch:on}", nbt: {id: "anvilcraft:acceleration_ring"}},
        {pos: [6, 0, 1], state: "minecraft:smooth_stone"},
        {pos: [6, 0, 21], state: "minecraft:smooth_stone"},
        {pos: [7, 0, 1], state: "minecraft:smooth_stone"},
        {pos: [7, 0, 21], state: "minecraft:smooth_stone"},
        {pos: [8, 0, 1], state: "minecraft:smooth_stone"},
        {pos: [8, 0, 21], state: "minecraft:smooth_stone"},
        {pos: [9, 0, 1], state: "minecraft:smooth_stone"},
        {pos: [9, 0, 21], state: "minecraft:smooth_stone"},
        {pos: [10, 0, 1], state: "minecraft:smooth_stone"},
        {pos: [10, 0, 21], state: "minecraft:smooth_stone"},
        {pos: [11, 0, 1], state: "minecraft:smooth_stone"},
        {pos: [11, 0, 11], state: "anvilcraft:remote_transmission_pole{half:bottom,overload:true,switch:on}", nbt: {id: "anvilcraft:remote_transmission_pole"}},
        {pos: [11, 0, 21], state: "minecraft:smooth_stone"},
        {pos: [12, 0, 1], state: "minecraft:smooth_stone"},
        {pos: [12, 0, 21], state: "minecraft:smooth_stone"},
        {pos: [13, 0, 1], state: "minecraft:smooth_stone"},
        {pos: [13, 0, 21], state: "minecraft:smooth_stone"},
        {pos: [14, 0, 1], state: "minecraft:smooth_stone"},
        {pos: [14, 0, 21], state: "minecraft:smooth_stone"},
        {pos: [15, 0, 1], state: "minecraft:smooth_stone"},
        {pos: [15, 0, 21], state: "minecraft:smooth_stone"},
        {pos: [16, 0, 1], state: "minecraft:smooth_stone"},
        {pos: [16, 0, 21], state: "minecraft:smooth_stone"},
        {pos: [17, 0, 0], state: "anvilcraft:acceleration_ring{facing:east,half:bottom_wn,overload:false,switch:on}", nbt: {id: "anvilcraft:acceleration_ring"}},
        {pos: [17, 0, 1], state: "anvilcraft:acceleration_ring{facing:east,half:bottom_w,overload:false,switch:on}", nbt: {id: "anvilcraft:acceleration_ring"}},
        {pos: [17, 0, 2], state: "anvilcraft:acceleration_ring{facing:east,half:bottom_ws,overload:false,switch:on}", nbt: {id: "anvilcraft:acceleration_ring"}},
        {pos: [17, 0, 20], state: "anvilcraft:acceleration_ring{facing:west,half:bottom_wn,overload:false,switch:on}", nbt: {id: "anvilcraft:acceleration_ring"}},
        {pos: [17, 0, 21], state: "anvilcraft:acceleration_ring{facing:west,half:bottom_w,overload:false,switch:on}", nbt: {id: "anvilcraft:acceleration_ring"}},
        {pos: [17, 0, 22], state: "anvilcraft:acceleration_ring{facing:west,half:bottom_ws,overload:false,switch:on}", nbt: {id: "anvilcraft:acceleration_ring"}},
        {pos: [18, 0, 0], state: "anvilcraft:acceleration_ring{facing:east,half:bottom_n,overload:false,switch:on}", nbt: {id: "anvilcraft:acceleration_ring"}},
        {pos: [18, 0, 1], state: "anvilcraft:acceleration_ring{facing:east,half:bottom_center,overload:false,switch:on}", nbt: {id: "anvilcraft:acceleration_ring"}},
        {pos: [18, 0, 2], state: "anvilcraft:acceleration_ring{facing:east,half:bottom_s,overload:false,switch:on}", nbt: {id: "anvilcraft:acceleration_ring"}},
        {pos: [18, 0, 20], state: "anvilcraft:acceleration_ring{facing:west,half:bottom_n,overload:false,switch:on}", nbt: {id: "anvilcraft:acceleration_ring"}},
        {pos: [18, 0, 21], state: "anvilcraft:acceleration_ring{facing:west,half:bottom_center,overload:false,switch:on}", nbt: {id: "anvilcraft:acceleration_ring"}},
        {pos: [18, 0, 22], state: "anvilcraft:acceleration_ring{facing:west,half:bottom_s,overload:false,switch:on}", nbt: {id: "anvilcraft:acceleration_ring"}},
        {pos: [19, 0, 0], state: "anvilcraft:acceleration_ring{facing:east,half:bottom_en,overload:false,switch:on}", nbt: {id: "anvilcraft:acceleration_ring"}},
        {pos: [19, 0, 1], state: "anvilcraft:acceleration_ring{facing:east,half:bottom_e,overload:false,switch:on}", nbt: {id: "anvilcraft:acceleration_ring"}},
        {pos: [19, 0, 2], state: "anvilcraft:acceleration_ring{facing:east,half:bottom_es,overload:false,switch:on}", nbt: {id: "anvilcraft:acceleration_ring"}},
        {pos: [19, 0, 20], state: "anvilcraft:acceleration_ring{facing:west,half:bottom_en,overload:false,switch:on}", nbt: {id: "anvilcraft:acceleration_ring"}},
        {pos: [19, 0, 21], state: "anvilcraft:acceleration_ring{facing:west,half:bottom_e,overload:false,switch:on}", nbt: {id: "anvilcraft:acceleration_ring"}},
        {pos: [19, 0, 22], state: "anvilcraft:acceleration_ring{facing:west,half:bottom_es,overload:false,switch:on}", nbt: {id: "anvilcraft:acceleration_ring"}},
        {pos: [20, 0, 0], state: "anvilcraft:deflection_ring{facing:down,half:bottom_wn,overload:false,switch:on}", nbt: {id: "anvilcraft:deflection_ring", lastEntitySpeed: 0.0d}},
        {pos: [20, 0, 1], state: "anvilcraft:deflection_ring{facing:down,half:bottom_w,overload:false,switch:on}", nbt: {id: "anvilcraft:deflection_ring", lastEntitySpeed: 0.0d}},
        {pos: [20, 0, 2], state: "anvilcraft:deflection_ring{facing:down,half:bottom_ws,overload:false,switch:on}", nbt: {id: "anvilcraft:deflection_ring", lastEntitySpeed: 0.0d}},
        {pos: [20, 0, 3], state: "anvilcraft:acceleration_ring{facing:south,half:bottom_wn,overload:false,switch:on}", nbt: {id: "anvilcraft:acceleration_ring"}},
        {pos: [20, 0, 4], state: "anvilcraft:acceleration_ring{facing:south,half:bottom_w,overload:false,switch:on}", nbt: {id: "anvilcraft:acceleration_ring"}},
        {pos: [20, 0, 5], state: "anvilcraft:acceleration_ring{facing:south,half:bottom_ws,overload:false,switch:on}", nbt: {id: "anvilcraft:acceleration_ring"}},
        {pos: [20, 0, 17], state: "anvilcraft:acceleration_ring{facing:south,half:bottom_wn,overload:false,switch:on}", nbt: {id: "anvilcraft:acceleration_ring"}},
        {pos: [20, 0, 18], state: "anvilcraft:acceleration_ring{facing:south,half:bottom_w,overload:false,switch:on}", nbt: {id: "anvilcraft:acceleration_ring"}},
        {pos: [20, 0, 19], state: "anvilcraft:acceleration_ring{facing:south,half:bottom_ws,overload:false,switch:on}", nbt: {id: "anvilcraft:acceleration_ring"}},
        {pos: [20, 0, 20], state: "anvilcraft:deflection_ring{facing:down,half:bottom_wn,overload:false,switch:on}", nbt: {id: "anvilcraft:deflection_ring", lastEntitySpeed: 0.0d}},
        {pos: [20, 0, 21], state: "anvilcraft:deflection_ring{facing:down,half:bottom_w,overload:false,switch:on}", nbt: {id: "anvilcraft:deflection_ring", lastEntitySpeed: 0.0d}},
        {pos: [20, 0, 22], state: "anvilcraft:deflection_ring{facing:down,half:bottom_ws,overload:false,switch:on}", nbt: {id: "anvilcraft:deflection_ring", lastEntitySpeed: 0.0d}},
        {pos: [21, 0, 0], state: "anvilcraft:deflection_ring{facing:down,half:bottom_n,overload:false,switch:on}", nbt: {id: "anvilcraft:deflection_ring", lastEntitySpeed: 0.0d}},
        {pos: [21, 0, 1], state: "anvilcraft:deflection_ring{facing:down,half:bottom_center,overload:false,switch:on}", nbt: {id: "anvilcraft:deflection_ring", lastEntitySpeed: 0.0d}},
        {pos: [21, 0, 2], state: "anvilcraft:deflection_ring{facing:down,half:bottom_s,overload:false,switch:on}", nbt: {id: "anvilcraft:deflection_ring", lastEntitySpeed: 0.0d}},
        {pos: [21, 0, 3], state: "anvilcraft:acceleration_ring{facing:south,half:bottom_n,overload:false,switch:on}", nbt: {id: "anvilcraft:acceleration_ring"}},
        {pos: [21, 0, 4], state: "anvilcraft:acceleration_ring{facing:south,half:bottom_center,overload:false,switch:on}", nbt: {id: "anvilcraft:acceleration_ring"}},
        {pos: [21, 0, 5], state: "anvilcraft:acceleration_ring{facing:south,half:bottom_s,overload:false,switch:on}", nbt: {id: "anvilcraft:acceleration_ring"}},
        {pos: [21, 0, 6], state: "minecraft:smooth_stone"},
        {pos: [21, 0, 7], state: "minecraft:smooth_stone"},
        {pos: [21, 0, 8], state: "minecraft:smooth_stone"},
        {pos: [21, 0, 9], state: "minecraft:smooth_stone"},
        {pos: [21, 0, 10], state: "minecraft:smooth_stone"},
        {pos: [21, 0, 11], state: "minecraft:smooth_stone"},
        {pos: [21, 0, 12], state: "minecraft:smooth_stone"},
        {pos: [21, 0, 13], state: "minecraft:smooth_stone"},
        {pos: [21, 0, 14], state: "minecraft:smooth_stone"},
        {pos: [21, 0, 15], state: "minecraft:smooth_stone"},
        {pos: [21, 0, 16], state: "minecraft:smooth_stone"},
        {pos: [21, 0, 17], state: "anvilcraft:acceleration_ring{facing:south,half:bottom_n,overload:false,switch:on}", nbt: {id: "anvilcraft:acceleration_ring"}},
        {pos: [21, 0, 18], state: "anvilcraft:acceleration_ring{facing:south,half:bottom_center,overload:false,switch:on}", nbt: {id: "anvilcraft:acceleration_ring"}},
        {pos: [21, 0, 19], state: "anvilcraft:acceleration_ring{facing:south,half:bottom_s,overload:false,switch:on}", nbt: {id: "anvilcraft:acceleration_ring"}},
        {pos: [21, 0, 20], state: "anvilcraft:deflection_ring{facing:down,half:bottom_n,overload:false,switch:on}", nbt: {id: "anvilcraft:deflection_ring", lastEntitySpeed: 0.0d}},
        {pos: [21, 0, 21], state: "anvilcraft:deflection_ring{facing:down,half:bottom_center,overload:false,switch:on}", nbt: {id: "anvilcraft:deflection_ring", lastEntitySpeed: 0.0d}},
        {pos: [21, 0, 22], state: "anvilcraft:deflection_ring{facing:down,half:bottom_s,overload:false,switch:on}", nbt: {id: "anvilcraft:deflection_ring", lastEntitySpeed: 0.0d}},
        {pos: [22, 0, 0], state: "anvilcraft:deflection_ring{facing:down,half:bottom_en,overload:false,switch:on}", nbt: {id: "anvilcraft:deflection_ring", lastEntitySpeed: 0.0d}},
        {pos: [22, 0, 1], state: "anvilcraft:deflection_ring{facing:down,half:bottom_e,overload:false,switch:on}", nbt: {id: "anvilcraft:deflection_ring", lastEntitySpeed: 0.0d}},
        {pos: [22, 0, 2], state: "anvilcraft:deflection_ring{facing:down,half:bottom_es,overload:false,switch:on}", nbt: {id: "anvilcraft:deflection_ring", lastEntitySpeed: 0.0d}},
        {pos: [22, 0, 3], state: "anvilcraft:acceleration_ring{facing:south,half:bottom_en,overload:false,switch:on}", nbt: {id: "anvilcraft:acceleration_ring"}},
        {pos: [22, 0, 4], state: "anvilcraft:acceleration_ring{facing:south,half:bottom_e,overload:false,switch:on}", nbt: {id: "anvilcraft:acceleration_ring"}},
        {pos: [22, 0, 5], state: "anvilcraft:acceleration_ring{facing:south,half:bottom_es,overload:false,switch:on}", nbt: {id: "anvilcraft:acceleration_ring"}},
        {pos: [22, 0, 17], state: "anvilcraft:acceleration_ring{facing:south,half:bottom_en,overload:false,switch:on}", nbt: {id: "anvilcraft:acceleration_ring"}},
        {pos: [22, 0, 18], state: "anvilcraft:acceleration_ring{facing:south,half:bottom_e,overload:false,switch:on}", nbt: {id: "anvilcraft:acceleration_ring"}},
        {pos: [22, 0, 19], state: "anvilcraft:acceleration_ring{facing:south,half:bottom_es,overload:false,switch:on}", nbt: {id: "anvilcraft:acceleration_ring"}},
        {pos: [22, 0, 20], state: "anvilcraft:deflection_ring{facing:down,half:bottom_en,overload:false,switch:on}", nbt: {id: "anvilcraft:deflection_ring", lastEntitySpeed: 0.0d}},
        {pos: [22, 0, 21], state: "anvilcraft:deflection_ring{facing:down,half:bottom_e,overload:false,switch:on}", nbt: {id: "anvilcraft:deflection_ring", lastEntitySpeed: 0.0d}},
        {pos: [22, 0, 22], state: "anvilcraft:deflection_ring{facing:down,half:bottom_es,overload:false,switch:on}", nbt: {id: "anvilcraft:deflection_ring", lastEntitySpeed: 0.0d}},
        {pos: [0, 1, 0], state: "anvilcraft:deflection_ring{facing:down,half:mid_wn,overload:false,switch:on}", nbt: {id: "anvilcraft:deflection_ring", lastEntitySpeed: 0.0d}},
        {pos: [0, 1, 1], state: "anvilcraft:deflection_ring{facing:down,half:mid_w,overload:false,switch:on}", nbt: {id: "anvilcraft:deflection_ring", lastEntitySpeed: 0.0d}},
        {pos: [0, 1, 2], state: "anvilcraft:deflection_ring{facing:down,half:mid_ws,overload:false,switch:on}", nbt: {id: "anvilcraft:deflection_ring", lastEntitySpeed: 0.0d}},
        {pos: [0, 1, 3], state: "anvilcraft:acceleration_ring{facing:north,half:mid_wn,overload:false,switch:on}", nbt: {id: "anvilcraft:acceleration_ring"}},
        {pos: [0, 1, 4], state: "anvilcraft:acceleration_ring{facing:north,half:mid_w,overload:false,switch:on}", nbt: {id: "anvilcraft:acceleration_ring"}},
        {pos: [0, 1, 5], state: "anvilcraft:acceleration_ring{facing:north,half:mid_ws,overload:false,switch:on}", nbt: {id: "anvilcraft:acceleration_ring"}},
        {pos: [0, 1, 17], state: "anvilcraft:acceleration_ring{facing:north,half:mid_wn,overload:false,switch:on}", nbt: {id: "anvilcraft:acceleration_ring"}},
        {pos: [0, 1, 18], state: "anvilcraft:acceleration_ring{facing:north,half:mid_w,overload:false,switch:on}", nbt: {id: "anvilcraft:acceleration_ring"}},
        {pos: [0, 1, 19], state: "anvilcraft:acceleration_ring{facing:north,half:mid_ws,overload:false,switch:on}", nbt: {id: "anvilcraft:acceleration_ring"}},
        {pos: [0, 1, 20], state: "anvilcraft:deflection_ring{facing:down,half:mid_wn,overload:false,switch:on}", nbt: {id: "anvilcraft:deflection_ring", lastEntitySpeed: 0.0d}},
        {pos: [0, 1, 21], state: "anvilcraft:deflection_ring{facing:down,half:mid_w,overload:false,switch:on}", nbt: {id: "anvilcraft:deflection_ring", lastEntitySpeed: 0.0d}},
        {pos: [0, 1, 22], state: "anvilcraft:deflection_ring{facing:down,half:mid_ws,overload:false,switch:on}", nbt: {id: "anvilcraft:deflection_ring", lastEntitySpeed: 0.0d}},
        {pos: [1, 1, 0], state: "anvilcraft:deflection_ring{facing:down,half:mid_n,overload:false,switch:on}", nbt: {id: "anvilcraft:deflection_ring", lastEntitySpeed: 0.0d}},
        {pos: [1, 1, 1], state: "anvilcraft:deflection_ring{facing:down,half:mid_center,overload:false,switch:on}", nbt: {id: "anvilcraft:deflection_ring", lastEntitySpeed: 0.0d}},
        {pos: [1, 1, 2], state: "anvilcraft:deflection_ring{facing:down,half:mid_s,overload:false,switch:on}", nbt: {id: "anvilcraft:deflection_ring", lastEntitySpeed: 0.0d}},
        {pos: [1, 1, 3], state: "anvilcraft:acceleration_ring{facing:north,half:mid_n,overload:false,switch:on}", nbt: {id: "anvilcraft:acceleration_ring"}},
        {pos: [1, 1, 4], state: "anvilcraft:acceleration_ring{facing:north,half:mid_center,overload:false,switch:on}", nbt: {id: "anvilcraft:acceleration_ring"}},
        {pos: [1, 1, 5], state: "anvilcraft:acceleration_ring{facing:north,half:mid_s,overload:false,switch:on}", nbt: {id: "anvilcraft:acceleration_ring"}},
        {pos: [1, 1, 17], state: "anvilcraft:acceleration_ring{facing:north,half:mid_n,overload:false,switch:on}", nbt: {id: "anvilcraft:acceleration_ring"}},
        {pos: [1, 1, 18], state: "anvilcraft:acceleration_ring{facing:north,half:mid_center,overload:false,switch:on}", nbt: {id: "anvilcraft:acceleration_ring"}},
        {pos: [1, 1, 19], state: "anvilcraft:acceleration_ring{facing:north,half:mid_s,overload:false,switch:on}", nbt: {id: "anvilcraft:acceleration_ring"}},
        {pos: [1, 1, 20], state: "anvilcraft:deflection_ring{facing:down,half:mid_n,overload:false,switch:on}", nbt: {id: "anvilcraft:deflection_ring", lastEntitySpeed: 0.0d}},
        {pos: [1, 1, 21], state: "anvilcraft:deflection_ring{facing:down,half:mid_center,overload:false,switch:on}", nbt: {id: "anvilcraft:deflection_ring", lastEntitySpeed: 0.0d}},
        {pos: [1, 1, 22], state: "anvilcraft:deflection_ring{facing:down,half:mid_s,overload:false,switch:on}", nbt: {id: "anvilcraft:deflection_ring", lastEntitySpeed: 0.0d}},
        {pos: [2, 1, 0], state: "anvilcraft:deflection_ring{facing:down,half:mid_en,overload:false,switch:on}", nbt: {id: "anvilcraft:deflection_ring", lastEntitySpeed: 0.0d}},
        {pos: [2, 1, 1], state: "anvilcraft:deflection_ring{facing:down,half:mid_e,overload:false,switch:on}", nbt: {id: "anvilcraft:deflection_ring", lastEntitySpeed: 0.0d}},
        {pos: [2, 1, 2], state: "anvilcraft:deflection_ring{facing:down,half:mid_es,overload:false,switch:on}", nbt: {id: "anvilcraft:deflection_ring", lastEntitySpeed: 0.0d}},
        {pos: [2, 1, 3], state: "anvilcraft:acceleration_ring{facing:north,half:mid_en,overload:false,switch:on}", nbt: {id: "anvilcraft:acceleration_ring"}},
        {pos: [2, 1, 4], state: "anvilcraft:acceleration_ring{facing:north,half:mid_e,overload:false,switch:on}", nbt: {id: "anvilcraft:acceleration_ring"}},
        {pos: [2, 1, 5], state: "anvilcraft:acceleration_ring{facing:north,half:mid_es,overload:false,switch:on}", nbt: {id: "anvilcraft:acceleration_ring"}},
        {pos: [2, 1, 17], state: "anvilcraft:acceleration_ring{facing:north,half:mid_en,overload:false,switch:on}", nbt: {id: "anvilcraft:acceleration_ring"}},
        {pos: [2, 1, 18], state: "anvilcraft:acceleration_ring{facing:north,half:mid_e,overload:false,switch:on}", nbt: {id: "anvilcraft:acceleration_ring"}},
        {pos: [2, 1, 19], state: "anvilcraft:acceleration_ring{facing:north,half:mid_es,overload:false,switch:on}", nbt: {id: "anvilcraft:acceleration_ring"}},
        {pos: [2, 1, 20], state: "anvilcraft:deflection_ring{facing:down,half:mid_en,overload:false,switch:on}", nbt: {id: "anvilcraft:deflection_ring", lastEntitySpeed: 0.0d}},
        {pos: [2, 1, 21], state: "anvilcraft:deflection_ring{facing:down,half:mid_e,overload:false,switch:on}", nbt: {id: "anvilcraft:deflection_ring", lastEntitySpeed: 0.0d}},
        {pos: [2, 1, 22], state: "anvilcraft:deflection_ring{facing:down,half:mid_es,overload:false,switch:on}", nbt: {id: "anvilcraft:deflection_ring", lastEntitySpeed: 0.0d}},
        {pos: [3, 1, 0], state: "anvilcraft:acceleration_ring{facing:east,half:mid_wn,overload:false,switch:on}", nbt: {id: "anvilcraft:acceleration_ring"}},
        {pos: [3, 1, 1], state: "anvilcraft:acceleration_ring{facing:east,half:mid_w,overload:false,switch:on}", nbt: {id: "anvilcraft:acceleration_ring"}},
        {pos: [3, 1, 2], state: "anvilcraft:acceleration_ring{facing:east,half:mid_ws,overload:false,switch:on}", nbt: {id: "anvilcraft:acceleration_ring"}},
        {pos: [3, 1, 20], state: "anvilcraft:acceleration_ring{facing:west,half:mid_wn,overload:false,switch:on}", nbt: {id: "anvilcraft:acceleration_ring"}},
        {pos: [3, 1, 21], state: "anvilcraft:acceleration_ring{facing:west,half:mid_w,overload:false,switch:on}", nbt: {id: "anvilcraft:acceleration_ring"}},
        {pos: [3, 1, 22], state: "anvilcraft:acceleration_ring{facing:west,half:mid_ws,overload:false,switch:on}", nbt: {id: "anvilcraft:acceleration_ring"}},
        {pos: [4, 1, 0], state: "anvilcraft:acceleration_ring{facing:east,half:mid_n,overload:false,switch:on}", nbt: {id: "anvilcraft:acceleration_ring"}},
        {pos: [4, 1, 1], state: "anvilcraft:acceleration_ring{facing:east,half:mid_center,overload:false,switch:on}", nbt: {id: "anvilcraft:acceleration_ring"}},
        {pos: [4, 1, 2], state: "anvilcraft:acceleration_ring{facing:east,half:mid_s,overload:false,switch:on}", nbt: {id: "anvilcraft:acceleration_ring"}},
        {pos: [4, 1, 20], state: "anvilcraft:acceleration_ring{facing:west,half:mid_n,overload:false,switch:on}", nbt: {id: "anvilcraft:acceleration_ring"}},
        {pos: [4, 1, 21], state: "anvilcraft:acceleration_ring{facing:west,half:mid_center,overload:false,switch:on}", nbt: {id: "anvilcraft:acceleration_ring"}},
        {pos: [4, 1, 22], state: "anvilcraft:acceleration_ring{facing:west,half:mid_s,overload:false,switch:on}", nbt: {id: "anvilcraft:acceleration_ring"}},
        {pos: [5, 1, 0], state: "anvilcraft:acceleration_ring{facing:east,half:mid_en,overload:false,switch:on}", nbt: {id: "anvilcraft:acceleration_ring"}},
        {pos: [5, 1, 1], state: "anvilcraft:acceleration_ring{facing:east,half:mid_e,overload:false,switch:on}", nbt: {id: "anvilcraft:acceleration_ring"}},
        {pos: [5, 1, 2], state: "anvilcraft:acceleration_ring{facing:east,half:mid_es,overload:false,switch:on}", nbt: {id: "anvilcraft:acceleration_ring"}},
        {pos: [5, 1, 20], state: "anvilcraft:acceleration_ring{facing:west,half:mid_en,overload:false,switch:on}", nbt: {id: "anvilcraft:acceleration_ring"}},
        {pos: [5, 1, 21], state: "anvilcraft:acceleration_ring{facing:west,half:mid_e,overload:false,switch:on}", nbt: {id: "anvilcraft:acceleration_ring"}},
        {pos: [5, 1, 22], state: "anvilcraft:acceleration_ring{facing:west,half:mid_es,overload:false,switch:on}", nbt: {id: "anvilcraft:acceleration_ring"}},
        {pos: [11, 1, 11], state: "anvilcraft:remote_transmission_pole{half:lower,overload:true,switch:on}", nbt: {id: "anvilcraft:remote_transmission_pole"}},
        {pos: [17, 1, 0], state: "anvilcraft:acceleration_ring{facing:east,half:mid_wn,overload:false,switch:on}", nbt: {id: "anvilcraft:acceleration_ring"}},
        {pos: [17, 1, 1], state: "anvilcraft:acceleration_ring{facing:east,half:mid_w,overload:false,switch:on}", nbt: {id: "anvilcraft:acceleration_ring"}},
        {pos: [17, 1, 2], state: "anvilcraft:acceleration_ring{facing:east,half:mid_ws,overload:false,switch:on}", nbt: {id: "anvilcraft:acceleration_ring"}},
        {pos: [17, 1, 20], state: "anvilcraft:acceleration_ring{facing:west,half:mid_wn,overload:false,switch:on}", nbt: {id: "anvilcraft:acceleration_ring"}},
        {pos: [17, 1, 21], state: "anvilcraft:acceleration_ring{facing:west,half:mid_w,overload:false,switch:on}", nbt: {id: "anvilcraft:acceleration_ring"}},
        {pos: [17, 1, 22], state: "anvilcraft:acceleration_ring{facing:west,half:mid_ws,overload:false,switch:on}", nbt: {id: "anvilcraft:acceleration_ring"}},
        {pos: [18, 1, 0], state: "anvilcraft:acceleration_ring{facing:east,half:mid_n,overload:false,switch:on}", nbt: {id: "anvilcraft:acceleration_ring"}},
        {pos: [18, 1, 1], state: "anvilcraft:acceleration_ring{facing:east,half:mid_center,overload:false,switch:on}", nbt: {id: "anvilcraft:acceleration_ring"}},
        {pos: [18, 1, 2], state: "anvilcraft:acceleration_ring{facing:east,half:mid_s,overload:false,switch:on}", nbt: {id: "anvilcraft:acceleration_ring"}},
        {pos: [18, 1, 20], state: "anvilcraft:acceleration_ring{facing:west,half:mid_n,overload:false,switch:on}", nbt: {id: "anvilcraft:acceleration_ring"}},
        {pos: [18, 1, 21], state: "anvilcraft:acceleration_ring{facing:west,half:mid_center,overload:false,switch:on}", nbt: {id: "anvilcraft:acceleration_ring"}},
        {pos: [18, 1, 22], state: "anvilcraft:acceleration_ring{facing:west,half:mid_s,overload:false,switch:on}", nbt: {id: "anvilcraft:acceleration_ring"}},
        {pos: [19, 1, 0], state: "anvilcraft:acceleration_ring{facing:east,half:mid_en,overload:false,switch:on}", nbt: {id: "anvilcraft:acceleration_ring"}},
        {pos: [19, 1, 1], state: "anvilcraft:acceleration_ring{facing:east,half:mid_e,overload:false,switch:on}", nbt: {id: "anvilcraft:acceleration_ring"}},
        {pos: [19, 1, 2], state: "anvilcraft:acceleration_ring{facing:east,half:mid_es,overload:false,switch:on}", nbt: {id: "anvilcraft:acceleration_ring"}},
        {pos: [19, 1, 20], state: "anvilcraft:acceleration_ring{facing:west,half:mid_en,overload:false,switch:on}", nbt: {id: "anvilcraft:acceleration_ring"}},
        {pos: [19, 1, 21], state: "anvilcraft:acceleration_ring{facing:west,half:mid_e,overload:false,switch:on}", nbt: {id: "anvilcraft:acceleration_ring"}},
        {pos: [19, 1, 22], state: "anvilcraft:acceleration_ring{facing:west,half:mid_es,overload:false,switch:on}", nbt: {id: "anvilcraft:acceleration_ring"}},
        {pos: [20, 1, 0], state: "anvilcraft:deflection_ring{facing:down,half:mid_wn,overload:false,switch:on}", nbt: {id: "anvilcraft:deflection_ring", lastEntitySpeed: 0.0d}},
        {pos: [20, 1, 1], state: "anvilcraft:deflection_ring{facing:down,half:mid_w,overload:false,switch:on}", nbt: {id: "anvilcraft:deflection_ring", lastEntitySpeed: 0.0d}},
        {pos: [20, 1, 2], state: "anvilcraft:deflection_ring{facing:down,half:mid_ws,overload:false,switch:on}", nbt: {id: "anvilcraft:deflection_ring", lastEntitySpeed: 0.0d}},
        {pos: [20, 1, 3], state: "anvilcraft:acceleration_ring{facing:south,half:mid_wn,overload:false,switch:on}", nbt: {id: "anvilcraft:acceleration_ring"}},
        {pos: [20, 1, 4], state: "anvilcraft:acceleration_ring{facing:south,half:mid_w,overload:false,switch:on}", nbt: {id: "anvilcraft:acceleration_ring"}},
        {pos: [20, 1, 5], state: "anvilcraft:acceleration_ring{facing:south,half:mid_ws,overload:false,switch:on}", nbt: {id: "anvilcraft:acceleration_ring"}},
        {pos: [20, 1, 17], state: "anvilcraft:acceleration_ring{facing:south,half:mid_wn,overload:false,switch:on}", nbt: {id: "anvilcraft:acceleration_ring"}},
        {pos: [20, 1, 18], state: "anvilcraft:acceleration_ring{facing:south,half:mid_w,overload:false,switch:on}", nbt: {id: "anvilcraft:acceleration_ring"}},
        {pos: [20, 1, 19], state: "anvilcraft:acceleration_ring{facing:south,half:mid_ws,overload:false,switch:on}", nbt: {id: "anvilcraft:acceleration_ring"}},
        {pos: [20, 1, 20], state: "anvilcraft:deflection_ring{facing:down,half:mid_wn,overload:false,switch:on}", nbt: {id: "anvilcraft:deflection_ring", lastEntitySpeed: 0.0d}},
        {pos: [20, 1, 21], state: "anvilcraft:deflection_ring{facing:down,half:mid_w,overload:false,switch:on}", nbt: {id: "anvilcraft:deflection_ring", lastEntitySpeed: 0.0d}},
        {pos: [20, 1, 22], state: "anvilcraft:deflection_ring{facing:down,half:mid_ws,overload:false,switch:on}", nbt: {id: "anvilcraft:deflection_ring", lastEntitySpeed: 0.0d}},
        {pos: [21, 1, 0], state: "anvilcraft:deflection_ring{facing:down,half:mid_n,overload:false,switch:on}", nbt: {id: "anvilcraft:deflection_ring", lastEntitySpeed: 0.0d}},
        {pos: [21, 1, 1], state: "anvilcraft:deflection_ring{facing:down,half:mid_center,overload:false,switch:on}", nbt: {id: "anvilcraft:deflection_ring", lastEntitySpeed: 0.0d}},
        {pos: [21, 1, 2], state: "anvilcraft:deflection_ring{facing:down,half:mid_s,overload:false,switch:on}", nbt: {id: "anvilcraft:deflection_ring", lastEntitySpeed: 0.0d}},
        {pos: [21, 1, 3], state: "anvilcraft:acceleration_ring{facing:south,half:mid_n,overload:false,switch:on}", nbt: {id: "anvilcraft:acceleration_ring"}},
        {pos: [21, 1, 4], state: "anvilcraft:acceleration_ring{facing:south,half:mid_center,overload:false,switch:on}", nbt: {id: "anvilcraft:acceleration_ring"}},
        {pos: [21, 1, 5], state: "anvilcraft:acceleration_ring{facing:south,half:mid_s,overload:false,switch:on}", nbt: {id: "anvilcraft:acceleration_ring"}},
        {pos: [21, 1, 17], state: "anvilcraft:acceleration_ring{facing:south,half:mid_n,overload:false,switch:on}", nbt: {id: "anvilcraft:acceleration_ring"}},
        {pos: [21, 1, 18], state: "anvilcraft:acceleration_ring{facing:south,half:mid_center,overload:false,switch:on}", nbt: {id: "anvilcraft:acceleration_ring"}},
        {pos: [21, 1, 19], state: "anvilcraft:acceleration_ring{facing:south,half:mid_s,overload:false,switch:on}", nbt: {id: "anvilcraft:acceleration_ring"}},
        {pos: [21, 1, 20], state: "anvilcraft:deflection_ring{facing:down,half:mid_n,overload:false,switch:on}", nbt: {id: "anvilcraft:deflection_ring", lastEntitySpeed: 0.0d}},
        {pos: [21, 1, 21], state: "anvilcraft:deflection_ring{facing:down,half:mid_center,overload:false,switch:on}", nbt: {id: "anvilcraft:deflection_ring", lastEntitySpeed: 0.0d}},
        {pos: [21, 1, 22], state: "anvilcraft:deflection_ring{facing:down,half:mid_s,overload:false,switch:on}", nbt: {id: "anvilcraft:deflection_ring", lastEntitySpeed: 0.0d}},
        {pos: [22, 1, 0], state: "anvilcraft:deflection_ring{facing:down,half:mid_en,overload:false,switch:on}", nbt: {id: "anvilcraft:deflection_ring", lastEntitySpeed: 0.0d}},
        {pos: [22, 1, 1], state: "anvilcraft:deflection_ring{facing:down,half:mid_e,overload:false,switch:on}", nbt: {id: "anvilcraft:deflection_ring", lastEntitySpeed: 0.0d}},
        {pos: [22, 1, 2], state: "anvilcraft:deflection_ring{facing:down,half:mid_es,overload:false,switch:on}", nbt: {id: "anvilcraft:deflection_ring", lastEntitySpeed: 0.0d}},
        {pos: [22, 1, 3], state: "anvilcraft:acceleration_ring{facing:south,half:mid_en,overload:false,switch:on}", nbt: {id: "anvilcraft:acceleration_ring"}},
        {pos: [22, 1, 4], state: "anvilcraft:acceleration_ring{facing:south,half:mid_e,overload:false,switch:on}", nbt: {id: "anvilcraft:acceleration_ring"}},
        {pos: [22, 1, 5], state: "anvilcraft:acceleration_ring{facing:south,half:mid_es,overload:false,switch:on}", nbt: {id: "anvilcraft:acceleration_ring"}},
        {pos: [22, 1, 17], state: "anvilcraft:acceleration_ring{facing:south,half:mid_en,overload:false,switch:on}", nbt: {id: "anvilcraft:acceleration_ring"}},
        {pos: [22, 1, 18], state: "anvilcraft:acceleration_ring{facing:south,half:mid_e,overload:false,switch:on}", nbt: {id: "anvilcraft:acceleration_ring"}},
        {pos: [22, 1, 19], state: "anvilcraft:acceleration_ring{facing:south,half:mid_es,overload:false,switch:on}", nbt: {id: "anvilcraft:acceleration_ring"}},
        {pos: [22, 1, 20], state: "anvilcraft:deflection_ring{facing:down,half:mid_en,overload:false,switch:on}", nbt: {id: "anvilcraft:deflection_ring", lastEntitySpeed: 0.0d}},
        {pos: [22, 1, 21], state: "anvilcraft:deflection_ring{facing:down,half:mid_e,overload:false,switch:on}", nbt: {id: "anvilcraft:deflection_ring", lastEntitySpeed: 0.0d}},
        {pos: [22, 1, 22], state: "anvilcraft:deflection_ring{facing:down,half:mid_es,overload:false,switch:on}", nbt: {id: "anvilcraft:deflection_ring", lastEntitySpeed: 0.0d}},
        {pos: [0, 2, 0], state: "anvilcraft:deflection_ring{facing:down,half:top_wn,overload:false,switch:on}", nbt: {id: "anvilcraft:deflection_ring", lastEntitySpeed: 0.0d}},
        {pos: [0, 2, 1], state: "anvilcraft:deflection_ring{facing:down,half:top_w,overload:false,switch:on}", nbt: {id: "anvilcraft:deflection_ring", lastEntitySpeed: 0.0d}},
        {pos: [0, 2, 2], state: "anvilcraft:deflection_ring{facing:down,half:top_ws,overload:false,switch:on}", nbt: {id: "anvilcraft:deflection_ring", lastEntitySpeed: 0.0d}},
        {pos: [0, 2, 3], state: "anvilcraft:acceleration_ring{facing:north,half:top_wn,overload:false,switch:on}", nbt: {id: "anvilcraft:acceleration_ring"}},
        {pos: [0, 2, 4], state: "anvilcraft:acceleration_ring{facing:north,half:top_w,overload:false,switch:on}", nbt: {id: "anvilcraft:acceleration_ring"}},
        {pos: [0, 2, 5], state: "anvilcraft:acceleration_ring{facing:north,half:top_ws,overload:false,switch:on}", nbt: {id: "anvilcraft:acceleration_ring"}},
        {pos: [0, 2, 17], state: "anvilcraft:acceleration_ring{facing:north,half:top_wn,overload:false,switch:on}", nbt: {id: "anvilcraft:acceleration_ring"}},
        {pos: [0, 2, 18], state: "anvilcraft:acceleration_ring{facing:north,half:top_w,overload:false,switch:on}", nbt: {id: "anvilcraft:acceleration_ring"}},
        {pos: [0, 2, 19], state: "anvilcraft:acceleration_ring{facing:north,half:top_ws,overload:false,switch:on}", nbt: {id: "anvilcraft:acceleration_ring"}},
        {pos: [0, 2, 20], state: "anvilcraft:deflection_ring{facing:down,half:top_wn,overload:false,switch:on}", nbt: {id: "anvilcraft:deflection_ring", lastEntitySpeed: 0.0d}},
        {pos: [0, 2, 21], state: "anvilcraft:deflection_ring{facing:down,half:top_w,overload:false,switch:on}", nbt: {id: "anvilcraft:deflection_ring", lastEntitySpeed: 0.0d}},
        {pos: [0, 2, 22], state: "anvilcraft:deflection_ring{facing:down,half:top_ws,overload:false,switch:on}", nbt: {id: "anvilcraft:deflection_ring", lastEntitySpeed: 0.0d}},
        {pos: [1, 2, 0], state: "anvilcraft:deflection_ring{facing:down,half:top_n,overload:false,switch:on}", nbt: {id: "anvilcraft:deflection_ring", lastEntitySpeed: 0.0d}},
        {pos: [1, 2, 1], state: "anvilcraft:deflection_ring{facing:down,half:top_center,overload:false,switch:on}", nbt: {id: "anvilcraft:deflection_ring", lastEntitySpeed: 0.0d}},
        {pos: [1, 2, 2], state: "anvilcraft:deflection_ring{facing:down,half:top_s,overload:false,switch:on}", nbt: {id: "anvilcraft:deflection_ring", lastEntitySpeed: 0.0d}},
        {pos: [1, 2, 3], state: "anvilcraft:acceleration_ring{facing:north,half:top_n,overload:false,switch:on}", nbt: {id: "anvilcraft:acceleration_ring"}},
        {pos: [1, 2, 4], state: "anvilcraft:acceleration_ring{facing:north,half:top_center,overload:false,switch:on}", nbt: {id: "anvilcraft:acceleration_ring"}},
        {pos: [1, 2, 5], state: "anvilcraft:acceleration_ring{facing:north,half:top_s,overload:false,switch:on}", nbt: {id: "anvilcraft:acceleration_ring"}},
        {pos: [1, 2, 17], state: "anvilcraft:acceleration_ring{facing:north,half:top_n,overload:false,switch:on}", nbt: {id: "anvilcraft:acceleration_ring"}},
        {pos: [1, 2, 18], state: "anvilcraft:acceleration_ring{facing:north,half:top_center,overload:false,switch:on}", nbt: {id: "anvilcraft:acceleration_ring"}},
        {pos: [1, 2, 19], state: "anvilcraft:acceleration_ring{facing:north,half:top_s,overload:false,switch:on}", nbt: {id: "anvilcraft:acceleration_ring"}},
        {pos: [1, 2, 20], state: "anvilcraft:deflection_ring{facing:down,half:top_n,overload:false,switch:on}", nbt: {id: "anvilcraft:deflection_ring", lastEntitySpeed: 0.0d}},
        {pos: [1, 2, 21], state: "anvilcraft:deflection_ring{facing:down,half:top_center,overload:false,switch:on}", nbt: {id: "anvilcraft:deflection_ring", lastEntitySpeed: 0.0d}},
        {pos: [1, 2, 22], state: "anvilcraft:deflection_ring{facing:down,half:top_s,overload:false,switch:on}", nbt: {id: "anvilcraft:deflection_ring", lastEntitySpeed: 0.0d}},
        {pos: [2, 2, 0], state: "anvilcraft:deflection_ring{facing:down,half:top_en,overload:false,switch:on}", nbt: {id: "anvilcraft:deflection_ring", lastEntitySpeed: 0.0d}},
        {pos: [2, 2, 1], state: "anvilcraft:deflection_ring{facing:down,half:top_e,overload:false,switch:on}", nbt: {id: "anvilcraft:deflection_ring", lastEntitySpeed: 0.0d}},
        {pos: [2, 2, 2], state: "anvilcraft:deflection_ring{facing:down,half:top_es,overload:false,switch:on}", nbt: {id: "anvilcraft:deflection_ring", lastEntitySpeed: 0.0d}},
        {pos: [2, 2, 3], state: "anvilcraft:acceleration_ring{facing:north,half:top_en,overload:false,switch:on}", nbt: {id: "anvilcraft:acceleration_ring"}},
        {pos: [2, 2, 4], state: "anvilcraft:acceleration_ring{facing:north,half:top_e,overload:false,switch:on}", nbt: {id: "anvilcraft:acceleration_ring"}},
        {pos: [2, 2, 5], state: "anvilcraft:acceleration_ring{facing:north,half:top_es,overload:false,switch:on}", nbt: {id: "anvilcraft:acceleration_ring"}},
        {pos: [2, 2, 17], state: "anvilcraft:acceleration_ring{facing:north,half:top_en,overload:false,switch:on}", nbt: {id: "anvilcraft:acceleration_ring"}},
        {pos: [2, 2, 18], state: "anvilcraft:acceleration_ring{facing:north,half:top_e,overload:false,switch:on}", nbt: {id: "anvilcraft:acceleration_ring"}},
        {pos: [2, 2, 19], state: "anvilcraft:acceleration_ring{facing:north,half:top_es,overload:false,switch:on}", nbt: {id: "anvilcraft:acceleration_ring"}},
        {pos: [2, 2, 20], state: "anvilcraft:deflection_ring{facing:down,half:top_en,overload:false,switch:on}", nbt: {id: "anvilcraft:deflection_ring", lastEntitySpeed: 0.0d}},
        {pos: [2, 2, 21], state: "anvilcraft:deflection_ring{facing:down,half:top_e,overload:false,switch:on}", nbt: {id: "anvilcraft:deflection_ring", lastEntitySpeed: 0.0d}},
        {pos: [2, 2, 22], state: "anvilcraft:deflection_ring{facing:down,half:top_es,overload:false,switch:on}", nbt: {id: "anvilcraft:deflection_ring", lastEntitySpeed: 0.0d}},
        {pos: [3, 2, 0], state: "anvilcraft:acceleration_ring{facing:east,half:top_wn,overload:false,switch:on}", nbt: {id: "anvilcraft:acceleration_ring"}},
        {pos: [3, 2, 1], state: "anvilcraft:acceleration_ring{facing:east,half:top_w,overload:false,switch:on}", nbt: {id: "anvilcraft:acceleration_ring"}},
        {pos: [3, 2, 2], state: "anvilcraft:acceleration_ring{facing:east,half:top_ws,overload:false,switch:on}", nbt: {id: "anvilcraft:acceleration_ring"}},
        {pos: [3, 2, 20], state: "anvilcraft:acceleration_ring{facing:west,half:top_wn,overload:false,switch:on}", nbt: {id: "anvilcraft:acceleration_ring"}},
        {pos: [3, 2, 21], state: "anvilcraft:acceleration_ring{facing:west,half:top_w,overload:false,switch:on}", nbt: {id: "anvilcraft:acceleration_ring"}},
        {pos: [3, 2, 22], state: "anvilcraft:acceleration_ring{facing:west,half:top_ws,overload:false,switch:on}", nbt: {id: "anvilcraft:acceleration_ring"}},
        {pos: [4, 2, 0], state: "anvilcraft:acceleration_ring{facing:east,half:top_n,overload:false,switch:on}", nbt: {id: "anvilcraft:acceleration_ring"}},
        {pos: [4, 2, 1], state: "anvilcraft:acceleration_ring{facing:east,half:top_center,overload:false,switch:on}", nbt: {id: "anvilcraft:acceleration_ring"}},
        {pos: [4, 2, 2], state: "anvilcraft:acceleration_ring{facing:east,half:top_s,overload:false,switch:on}", nbt: {id: "anvilcraft:acceleration_ring"}},
        {pos: [4, 2, 20], state: "anvilcraft:acceleration_ring{facing:west,half:top_n,overload:false,switch:on}", nbt: {id: "anvilcraft:acceleration_ring"}},
        {pos: [4, 2, 21], state: "anvilcraft:acceleration_ring{facing:west,half:top_center,overload:false,switch:on}", nbt: {id: "anvilcraft:acceleration_ring"}},
        {pos: [4, 2, 22], state: "anvilcraft:acceleration_ring{facing:west,half:top_s,overload:false,switch:on}", nbt: {id: "anvilcraft:acceleration_ring"}},
        {pos: [5, 2, 0], state: "anvilcraft:acceleration_ring{facing:east,half:top_en,overload:false,switch:on}", nbt: {id: "anvilcraft:acceleration_ring"}},
        {pos: [5, 2, 1], state: "anvilcraft:acceleration_ring{facing:east,half:top_e,overload:false,switch:on}", nbt: {id: "anvilcraft:acceleration_ring"}},
        {pos: [5, 2, 2], state: "anvilcraft:acceleration_ring{facing:east,half:top_es,overload:false,switch:on}", nbt: {id: "anvilcraft:acceleration_ring"}},
        {pos: [5, 2, 20], state: "anvilcraft:acceleration_ring{facing:west,half:top_en,overload:false,switch:on}", nbt: {id: "anvilcraft:acceleration_ring"}},
        {pos: [5, 2, 21], state: "anvilcraft:acceleration_ring{facing:west,half:top_e,overload:false,switch:on}", nbt: {id: "anvilcraft:acceleration_ring"}},
        {pos: [5, 2, 22], state: "anvilcraft:acceleration_ring{facing:west,half:top_es,overload:false,switch:on}", nbt: {id: "anvilcraft:acceleration_ring"}},
        {pos: [11, 2, 11], state: "anvilcraft:remote_transmission_pole{half:upper,overload:true,switch:on}", nbt: {id: "anvilcraft:remote_transmission_pole"}},
        {pos: [17, 2, 0], state: "anvilcraft:acceleration_ring{facing:east,half:top_wn,overload:false,switch:on}", nbt: {id: "anvilcraft:acceleration_ring"}},
        {pos: [17, 2, 1], state: "anvilcraft:acceleration_ring{facing:east,half:top_w,overload:false,switch:on}", nbt: {id: "anvilcraft:acceleration_ring"}},
        {pos: [17, 2, 2], state: "anvilcraft:acceleration_ring{facing:east,half:top_ws,overload:false,switch:on}", nbt: {id: "anvilcraft:acceleration_ring"}},
        {pos: [17, 2, 20], state: "anvilcraft:acceleration_ring{facing:west,half:top_wn,overload:false,switch:on}", nbt: {id: "anvilcraft:acceleration_ring"}},
        {pos: [17, 2, 21], state: "anvilcraft:acceleration_ring{facing:west,half:top_w,overload:false,switch:on}", nbt: {id: "anvilcraft:acceleration_ring"}},
        {pos: [17, 2, 22], state: "anvilcraft:acceleration_ring{facing:west,half:top_ws,overload:false,switch:on}", nbt: {id: "anvilcraft:acceleration_ring"}},
        {pos: [18, 2, 0], state: "anvilcraft:acceleration_ring{facing:east,half:top_n,overload:false,switch:on}", nbt: {id: "anvilcraft:acceleration_ring"}},
        {pos: [18, 2, 1], state: "anvilcraft:acceleration_ring{facing:east,half:top_center,overload:false,switch:on}", nbt: {id: "anvilcraft:acceleration_ring"}},
        {pos: [18, 2, 2], state: "anvilcraft:acceleration_ring{facing:east,half:top_s,overload:false,switch:on}", nbt: {id: "anvilcraft:acceleration_ring"}},
        {pos: [18, 2, 20], state: "anvilcraft:acceleration_ring{facing:west,half:top_n,overload:false,switch:on}", nbt: {id: "anvilcraft:acceleration_ring"}},
        {pos: [18, 2, 21], state: "anvilcraft:acceleration_ring{facing:west,half:top_center,overload:false,switch:on}", nbt: {id: "anvilcraft:acceleration_ring"}},
        {pos: [18, 2, 22], state: "anvilcraft:acceleration_ring{facing:west,half:top_s,overload:false,switch:on}", nbt: {id: "anvilcraft:acceleration_ring"}},
        {pos: [19, 2, 0], state: "anvilcraft:acceleration_ring{facing:east,half:top_en,overload:false,switch:on}", nbt: {id: "anvilcraft:acceleration_ring"}},
        {pos: [19, 2, 1], state: "anvilcraft:acceleration_ring{facing:east,half:top_e,overload:false,switch:on}", nbt: {id: "anvilcraft:acceleration_ring"}},
        {pos: [19, 2, 2], state: "anvilcraft:acceleration_ring{facing:east,half:top_es,overload:false,switch:on}", nbt: {id: "anvilcraft:acceleration_ring"}},
        {pos: [19, 2, 20], state: "anvilcraft:acceleration_ring{facing:west,half:top_en,overload:false,switch:on}", nbt: {id: "anvilcraft:acceleration_ring"}},
        {pos: [19, 2, 21], state: "anvilcraft:acceleration_ring{facing:west,half:top_e,overload:false,switch:on}", nbt: {id: "anvilcraft:acceleration_ring"}},
        {pos: [19, 2, 22], state: "anvilcraft:acceleration_ring{facing:west,half:top_es,overload:false,switch:on}", nbt: {id: "anvilcraft:acceleration_ring"}},
        {pos: [20, 2, 0], state: "anvilcraft:deflection_ring{facing:down,half:top_wn,overload:false,switch:on}", nbt: {id: "anvilcraft:deflection_ring", lastEntitySpeed: 0.0d}},
        {pos: [20, 2, 1], state: "anvilcraft:deflection_ring{facing:down,half:top_w,overload:false,switch:on}", nbt: {id: "anvilcraft:deflection_ring", lastEntitySpeed: 0.0d}},
        {pos: [20, 2, 2], state: "anvilcraft:deflection_ring{facing:down,half:top_ws,overload:false,switch:on}", nbt: {id: "anvilcraft:deflection_ring", lastEntitySpeed: 0.0d}},
        {pos: [20, 2, 3], state: "anvilcraft:acceleration_ring{facing:south,half:top_wn,overload:false,switch:on}", nbt: {id: "anvilcraft:acceleration_ring"}},
        {pos: [20, 2, 4], state: "anvilcraft:acceleration_ring{facing:south,half:top_w,overload:false,switch:on}", nbt: {id: "anvilcraft:acceleration_ring"}},
        {pos: [20, 2, 5], state: "anvilcraft:acceleration_ring{facing:south,half:top_ws,overload:false,switch:on}", nbt: {id: "anvilcraft:acceleration_ring"}},
        {pos: [20, 2, 17], state: "anvilcraft:acceleration_ring{facing:south,half:top_wn,overload:false,switch:on}", nbt: {id: "anvilcraft:acceleration_ring"}},
        {pos: [20, 2, 18], state: "anvilcraft:acceleration_ring{facing:south,half:top_w,overload:false,switch:on}", nbt: {id: "anvilcraft:acceleration_ring"}},
        {pos: [20, 2, 19], state: "anvilcraft:acceleration_ring{facing:south,half:top_ws,overload:false,switch:on}", nbt: {id: "anvilcraft:acceleration_ring"}},
        {pos: [20, 2, 20], state: "anvilcraft:deflection_ring{facing:down,half:top_wn,overload:false,switch:on}", nbt: {id: "anvilcraft:deflection_ring", lastEntitySpeed: 0.0d}},
        {pos: [20, 2, 21], state: "anvilcraft:deflection_ring{facing:down,half:top_w,overload:false,switch:on}", nbt: {id: "anvilcraft:deflection_ring", lastEntitySpeed: 0.0d}},
        {pos: [20, 2, 22], state: "anvilcraft:deflection_ring{facing:down,half:top_ws,overload:false,switch:on}", nbt: {id: "anvilcraft:deflection_ring", lastEntitySpeed: 0.0d}},
        {pos: [21, 2, 0], state: "anvilcraft:deflection_ring{facing:down,half:top_n,overload:false,switch:on}", nbt: {id: "anvilcraft:deflection_ring", lastEntitySpeed: 0.0d}},
        {pos: [21, 2, 1], state: "anvilcraft:deflection_ring{facing:down,half:top_center,overload:false,switch:on}", nbt: {id: "anvilcraft:deflection_ring", lastEntitySpeed: 0.0d}},
        {pos: [21, 2, 2], state: "anvilcraft:deflection_ring{facing:down,half:top_s,overload:false,switch:on}", nbt: {id: "anvilcraft:deflection_ring", lastEntitySpeed: 0.0d}},
        {pos: [21, 2, 3], state: "anvilcraft:acceleration_ring{facing:south,half:top_n,overload:false,switch:on}", nbt: {id: "anvilcraft:acceleration_ring"}},
        {pos: [21, 2, 4], state: "anvilcraft:acceleration_ring{facing:south,half:top_center,overload:false,switch:on}", nbt: {id: "anvilcraft:acceleration_ring"}},
        {pos: [21, 2, 5], state: "anvilcraft:acceleration_ring{facing:south,half:top_s,overload:false,switch:on}", nbt: {id: "anvilcraft:acceleration_ring"}},
        {pos: [21, 2, 17], state: "anvilcraft:acceleration_ring{facing:south,half:top_n,overload:false,switch:on}", nbt: {id: "anvilcraft:acceleration_ring"}},
        {pos: [21, 2, 18], state: "anvilcraft:acceleration_ring{facing:south,half:top_center,overload:false,switch:on}", nbt: {id: "anvilcraft:acceleration_ring"}},
        {pos: [21, 2, 19], state: "anvilcraft:acceleration_ring{facing:south,half:top_s,overload:false,switch:on}", nbt: {id: "anvilcraft:acceleration_ring"}},
        {pos: [21, 2, 20], state: "anvilcraft:deflection_ring{facing:down,half:top_n,overload:false,switch:on}", nbt: {id: "anvilcraft:deflection_ring", lastEntitySpeed: 0.0d}},
        {pos: [21, 2, 21], state: "anvilcraft:deflection_ring{facing:down,half:top_center,overload:false,switch:on}", nbt: {id: "anvilcraft:deflection_ring", lastEntitySpeed: 0.0d}},
        {pos: [21, 2, 22], state: "anvilcraft:deflection_ring{facing:down,half:top_s,overload:false,switch:on}", nbt: {id: "anvilcraft:deflection_ring", lastEntitySpeed: 0.0d}},
        {pos: [22, 2, 0], state: "anvilcraft:deflection_ring{facing:down,half:top_en,overload:false,switch:on}", nbt: {id: "anvilcraft:deflection_ring", lastEntitySpeed: 0.0d}},
        {pos: [22, 2, 1], state: "anvilcraft:deflection_ring{facing:down,half:top_e,overload:false,switch:on}", nbt: {id: "anvilcraft:deflection_ring", lastEntitySpeed: 0.0d}},
        {pos: [22, 2, 2], state: "anvilcraft:deflection_ring{facing:down,half:top_es,overload:false,switch:on}", nbt: {id: "anvilcraft:deflection_ring", lastEntitySpeed: 0.0d}},
        {pos: [22, 2, 3], state: "anvilcraft:acceleration_ring{facing:south,half:top_en,overload:false,switch:on}", nbt: {id: "anvilcraft:acceleration_ring"}},
        {pos: [22, 2, 4], state: "anvilcraft:acceleration_ring{facing:south,half:top_e,overload:false,switch:on}", nbt: {id: "anvilcraft:acceleration_ring"}},
        {pos: [22, 2, 5], state: "anvilcraft:acceleration_ring{facing:south,half:top_es,overload:false,switch:on}", nbt: {id: "anvilcraft:acceleration_ring"}},
        {pos: [22, 2, 17], state: "anvilcraft:acceleration_ring{facing:south,half:top_en,overload:false,switch:on}", nbt: {id: "anvilcraft:acceleration_ring"}},
        {pos: [22, 2, 18], state: "anvilcraft:acceleration_ring{facing:south,half:top_e,overload:false,switch:on}", nbt: {id: "anvilcraft:acceleration_ring"}},
        {pos: [22, 2, 19], state: "anvilcraft:acceleration_ring{facing:south,half:top_es,overload:false,switch:on}", nbt: {id: "anvilcraft:acceleration_ring"}},
        {pos: [22, 2, 20], state: "anvilcraft:deflection_ring{facing:down,half:top_en,overload:false,switch:on}", nbt: {id: "anvilcraft:deflection_ring", lastEntitySpeed: 0.0d}},
        {pos: [22, 2, 21], state: "anvilcraft:deflection_ring{facing:down,half:top_e,overload:false,switch:on}", nbt: {id: "anvilcraft:deflection_ring", lastEntitySpeed: 0.0d}},
        {pos: [22, 2, 22], state: "anvilcraft:deflection_ring{facing:down,half:top_es,overload:false,switch:on}", nbt: {id: "anvilcraft:deflection_ring", lastEntitySpeed: 0.0d}},
        {pos: [11, 3, 11], state: "anvilcraft:remote_transmission_pole{half:top,overload:false,switch:on}", nbt: {id: "anvilcraft:remote_transmission_pole"}}
    ],
    entities: [],
    palette: [
        "minecraft:smooth_stone",
        "anvilcraft:deflection_ring{facing:down,half:bottom_wn,overload:false,switch:on}",
        "anvilcraft:deflection_ring{facing:down,half:bottom_w,overload:false,switch:on}",
        "anvilcraft:deflection_ring{facing:down,half:bottom_ws,overload:false,switch:on}",
        "anvilcraft:acceleration_ring{facing:north,half:bottom_wn,overload:false,switch:on}",
        "anvilcraft:acceleration_ring{facing:north,half:bottom_w,overload:false,switch:on}",
        "anvilcraft:acceleration_ring{facing:north,half:bottom_ws,overload:false,switch:on}",
        "anvilcraft:deflection_ring{facing:down,half:bottom_n,overload:false,switch:on}",
        "anvilcraft:deflection_ring{facing:down,half:bottom_center,overload:false,switch:on}",
        "anvilcraft:deflection_ring{facing:down,half:bottom_s,overload:false,switch:on}",
        "anvilcraft:acceleration_ring{facing:north,half:bottom_n,overload:false,switch:on}",
        "anvilcraft:acceleration_ring{facing:north,half:bottom_center,overload:false,switch:on}",
        "anvilcraft:acceleration_ring{facing:north,half:bottom_s,overload:false,switch:on}",
        "anvilcraft:deflection_ring{facing:down,half:bottom_en,overload:false,switch:on}",
        "anvilcraft:deflection_ring{facing:down,half:bottom_e,overload:false,switch:on}",
        "anvilcraft:deflection_ring{facing:down,half:bottom_es,overload:false,switch:on}",
        "anvilcraft:acceleration_ring{facing:north,half:bottom_en,overload:false,switch:on}",
        "anvilcraft:acceleration_ring{facing:north,half:bottom_e,overload:false,switch:on}",
        "anvilcraft:acceleration_ring{facing:north,half:bottom_es,overload:false,switch:on}",
        "anvilcraft:acceleration_ring{facing:east,half:bottom_wn,overload:false,switch:on}",
        "anvilcraft:acceleration_ring{facing:east,half:bottom_w,overload:false,switch:on}",
        "anvilcraft:acceleration_ring{facing:east,half:bottom_ws,overload:false,switch:on}",
        "anvilcraft:acceleration_ring{facing:west,half:bottom_wn,overload:false,switch:on}",
        "anvilcraft:acceleration_ring{facing:west,half:bottom_w,overload:false,switch:on}",
        "anvilcraft:acceleration_ring{facing:west,half:bottom_ws,overload:false,switch:on}",
        "anvilcraft:acceleration_ring{facing:east,half:bottom_n,overload:false,switch:on}",
        "anvilcraft:acceleration_ring{facing:east,half:bottom_center,overload:false,switch:on}",
        "anvilcraft:acceleration_ring{facing:east,half:bottom_s,overload:false,switch:on}",
        "anvilcraft:acceleration_ring{facing:west,half:bottom_n,overload:false,switch:on}",
        "anvilcraft:acceleration_ring{facing:west,half:bottom_center,overload:false,switch:on}",
        "anvilcraft:acceleration_ring{facing:west,half:bottom_s,overload:false,switch:on}",
        "anvilcraft:acceleration_ring{facing:east,half:bottom_en,overload:false,switch:on}",
        "anvilcraft:acceleration_ring{facing:east,half:bottom_e,overload:false,switch:on}",
        "anvilcraft:acceleration_ring{facing:east,half:bottom_es,overload:false,switch:on}",
        "anvilcraft:acceleration_ring{facing:west,half:bottom_en,overload:false,switch:on}",
        "anvilcraft:acceleration_ring{facing:west,half:bottom_e,overload:false,switch:on}",
        "anvilcraft:acceleration_ring{facing:west,half:bottom_es,overload:false,switch:on}",
        "anvilcraft:remote_transmission_pole{half:bottom,overload:true,switch:on}",
        "anvilcraft:acceleration_ring{facing:south,half:bottom_wn,overload:false,switch:on}",
        "anvilcraft:acceleration_ring{facing:south,half:bottom_w,overload:false,switch:on}",
        "anvilcraft:acceleration_ring{facing:south,half:bottom_ws,overload:false,switch:on}",
        "anvilcraft:acceleration_ring{facing:south,half:bottom_n,overload:false,switch:on}",
        "anvilcraft:acceleration_ring{facing:south,half:bottom_center,overload:false,switch:on}",
        "anvilcraft:acceleration_ring{facing:south,half:bottom_s,overload:false,switch:on}",
        "anvilcraft:acceleration_ring{facing:south,half:bottom_en,overload:false,switch:on}",
        "anvilcraft:acceleration_ring{facing:south,half:bottom_e,overload:false,switch:on}",
        "anvilcraft:acceleration_ring{facing:south,half:bottom_es,overload:false,switch:on}",
        "anvilcraft:deflection_ring{facing:down,half:mid_wn,overload:false,switch:on}",
        "anvilcraft:deflection_ring{facing:down,half:mid_w,overload:false,switch:on}",
        "anvilcraft:deflection_ring{facing:down,half:mid_ws,overload:false,switch:on}",
        "anvilcraft:acceleration_ring{facing:north,half:mid_wn,overload:false,switch:on}",
        "anvilcraft:acceleration_ring{facing:north,half:mid_w,overload:false,switch:on}",
        "anvilcraft:acceleration_ring{facing:north,half:mid_ws,overload:false,switch:on}",
        "anvilcraft:deflection_ring{facing:down,half:mid_n,overload:false,switch:on}",
        "anvilcraft:deflection_ring{facing:down,half:mid_center,overload:false,switch:on}",
        "anvilcraft:deflection_ring{facing:down,half:mid_s,overload:false,switch:on}",
        "anvilcraft:acceleration_ring{facing:north,half:mid_n,overload:false,switch:on}",
        "anvilcraft:acceleration_ring{facing:north,half:mid_center,overload:false,switch:on}",
        "anvilcraft:acceleration_ring{facing:north,half:mid_s,overload:false,switch:on}",
        "anvilcraft:deflection_ring{facing:down,half:mid_en,overload:false,switch:on}",
        "anvilcraft:deflection_ring{facing:down,half:mid_e,overload:false,switch:on}",
        "anvilcraft:deflection_ring{facing:down,half:mid_es,overload:false,switch:on}",
        "anvilcraft:acceleration_ring{facing:north,half:mid_en,overload:false,switch:on}",
        "anvilcraft:acceleration_ring{facing:north,half:mid_e,overload:false,switch:on}",
        "anvilcraft:acceleration_ring{facing:north,half:mid_es,overload:false,switch:on}",
        "anvilcraft:acceleration_ring{facing:east,half:mid_wn,overload:false,switch:on}",
        "anvilcraft:acceleration_ring{facing:east,half:mid_w,overload:false,switch:on}",
        "anvilcraft:acceleration_ring{facing:east,half:mid_ws,overload:false,switch:on}",
        "anvilcraft:acceleration_ring{facing:west,half:mid_wn,overload:false,switch:on}",
        "anvilcraft:acceleration_ring{facing:west,half:mid_w,overload:false,switch:on}",
        "anvilcraft:acceleration_ring{facing:west,half:mid_ws,overload:false,switch:on}",
        "anvilcraft:acceleration_ring{facing:east,half:mid_n,overload:false,switch:on}",
        "anvilcraft:acceleration_ring{facing:east,half:mid_center,overload:false,switch:on}",
        "anvilcraft:acceleration_ring{facing:east,half:mid_s,overload:false,switch:on}",
        "anvilcraft:acceleration_ring{facing:west,half:mid_n,overload:false,switch:on}",
        "anvilcraft:acceleration_ring{facing:west,half:mid_center,overload:false,switch:on}",
        "anvilcraft:acceleration_ring{facing:west,half:mid_s,overload:false,switch:on}",
        "anvilcraft:acceleration_ring{facing:east,half:mid_en,overload:false,switch:on}",
        "anvilcraft:acceleration_ring{facing:east,half:mid_e,overload:false,switch:on}",
        "anvilcraft:acceleration_ring{facing:east,half:mid_es,overload:false,switch:on}",
        "anvilcraft:acceleration_ring{facing:west,half:mid_en,overload:false,switch:on}",
        "anvilcraft:acceleration_ring{facing:west,half:mid_e,overload:false,switch:on}",
        "anvilcraft:acceleration_ring{facing:west,half:mid_es,overload:false,switch:on}",
        "anvilcraft:remote_transmission_pole{half:lower,overload:true,switch:on}",
        "anvilcraft:acceleration_ring{facing:south,half:mid_wn,overload:false,switch:on}",
        "anvilcraft:acceleration_ring{facing:south,half:mid_w,overload:false,switch:on}",
        "anvilcraft:acceleration_ring{facing:south,half:mid_ws,overload:false,switch:on}",
        "anvilcraft:acceleration_ring{facing:south,half:mid_n,overload:false,switch:on}",
        "anvilcraft:acceleration_ring{facing:south,half:mid_center,overload:false,switch:on}",
        "anvilcraft:acceleration_ring{facing:south,half:mid_s,overload:false,switch:on}",
        "anvilcraft:acceleration_ring{facing:south,half:mid_en,overload:false,switch:on}",
        "anvilcraft:acceleration_ring{facing:south,half:mid_e,overload:false,switch:on}",
        "anvilcraft:acceleration_ring{facing:south,half:mid_es,overload:false,switch:on}",
        "anvilcraft:deflection_ring{facing:down,half:top_wn,overload:false,switch:on}",
        "anvilcraft:deflection_ring{facing:down,half:top_w,overload:false,switch:on}",
        "anvilcraft:deflection_ring{facing:down,half:top_ws,overload:false,switch:on}",
        "anvilcraft:acceleration_ring{facing:north,half:top_wn,overload:false,switch:on}",
        "anvilcraft:acceleration_ring{facing:north,half:top_w,overload:false,switch:on}",
        "anvilcraft:acceleration_ring{facing:north,half:top_ws,overload:false,switch:on}",
        "anvilcraft:deflection_ring{facing:down,half:top_n,overload:false,switch:on}",
        "anvilcraft:deflection_ring{facing:down,half:top_center,overload:false,switch:on}",
        "anvilcraft:deflection_ring{facing:down,half:top_s,overload:false,switch:on}",
        "anvilcraft:acceleration_ring{facing:north,half:top_n,overload:false,switch:on}",
        "anvilcraft:acceleration_ring{facing:north,half:top_center,overload:false,switch:on}",
        "anvilcraft:acceleration_ring{facing:north,half:top_s,overload:false,switch:on}",
        "anvilcraft:deflection_ring{facing:down,half:top_en,overload:false,switch:on}",
        "anvilcraft:deflection_ring{facing:down,half:top_e,overload:false,switch:on}",
        "anvilcraft:deflection_ring{facing:down,half:top_es,overload:false,switch:on}",
        "anvilcraft:acceleration_ring{facing:north,half:top_en,overload:false,switch:on}",
        "anvilcraft:acceleration_ring{facing:north,half:top_e,overload:false,switch:on}",
        "anvilcraft:acceleration_ring{facing:north,half:top_es,overload:false,switch:on}",
        "anvilcraft:acceleration_ring{facing:east,half:top_wn,overload:false,switch:on}",
        "anvilcraft:acceleration_ring{facing:east,half:top_w,overload:false,switch:on}",
        "anvilcraft:acceleration_ring{facing:east,half:top_ws,overload:false,switch:on}",
        "anvilcraft:acceleration_ring{facing:west,half:top_wn,overload:false,switch:on}",
        "anvilcraft:acceleration_ring{facing:west,half:top_w,overload:false,switch:on}",
        "anvilcraft:acceleration_ring{facing:west,half:top_ws,overload:false,switch:on}",
        "anvilcraft:acceleration_ring{facing:east,half:top_n,overload:false,switch:on}",
        "anvilcraft:acceleration_ring{facing:east,half:top_center,overload:false,switch:on}",
        "anvilcraft:acceleration_ring{facing:east,half:top_s,overload:false,switch:on}",
        "anvilcraft:acceleration_ring{facing:west,half:top_n,overload:false,switch:on}",
        "anvilcraft:acceleration_ring{facing:west,half:top_center,overload:false,switch:on}",
        "anvilcraft:acceleration_ring{facing:west,half:top_s,overload:false,switch:on}",
        "anvilcraft:acceleration_ring{facing:east,half:top_en,overload:false,switch:on}",
        "anvilcraft:acceleration_ring{facing:east,half:top_e,overload:false,switch:on}",
        "anvilcraft:acceleration_ring{facing:east,half:top_es,overload:false,switch:on}",
        "anvilcraft:acceleration_ring{facing:west,half:top_en,overload:false,switch:on}",
        "anvilcraft:acceleration_ring{facing:west,half:top_e,overload:false,switch:on}",
        "anvilcraft:acceleration_ring{facing:west,half:top_es,overload:false,switch:on}",
        "anvilcraft:remote_transmission_pole{half:upper,overload:true,switch:on}",
        "anvilcraft:acceleration_ring{facing:south,half:top_wn,overload:false,switch:on}",
        "anvilcraft:acceleration_ring{facing:south,half:top_w,overload:false,switch:on}",
        "anvilcraft:acceleration_ring{facing:south,half:top_ws,overload:false,switch:on}",
        "anvilcraft:acceleration_ring{facing:south,half:top_n,overload:false,switch:on}",
        "anvilcraft:acceleration_ring{facing:south,half:top_center,overload:false,switch:on}",
        "anvilcraft:acceleration_ring{facing:south,half:top_s,overload:false,switch:on}",
        "anvilcraft:acceleration_ring{facing:south,half:top_en,overload:false,switch:on}",
        "anvilcraft:acceleration_ring{facing:south,half:top_e,overload:false,switch:on}",
        "anvilcraft:acceleration_ring{facing:south,half:top_es,overload:false,switch:on}",
        "anvilcraft:remote_transmission_pole{half:top,overload:false,switch:on}"
    ]
}