{
    DataVersion: 3955,
    size: [9, 3, 3],
    data: [
        {pos: [0, 0, 0], state: "anvilcraft:cake_block"},
        {pos: [0, 0, 1], state: "anvilcraft:cake_block"},
        {pos: [0, 0, 2], state: "anvilcraft:cake_block"},
        {pos: [1, 0, 0], state: "anvilcraft:cake_block"},
        {pos: [1, 0, 1], state: "anvilcraft:cake_block"},
        {pos: [1, 0, 2], state: "anvilcraft:cake_block"},
        {pos: [2, 0, 0], state: "anvilcraft:cake_block"},
        {pos: [2, 0, 1], state: "anvilcraft:cake_block"},
        {pos: [2, 0, 2], state: "anvilcraft:cake_block"},
        {pos: [6, 0, 0], state: "anvilcraft:large_cake{half:bottom_wn}"},
        {pos: [6, 0, 1], state: "anvilcraft:large_cake{half:bottom_w}"},
        {pos: [6, 0, 2], state: "anvilcraft:large_cake{half:bottom_ws}"},
        {pos: [7, 0, 0], state: "anvilcraft:large_cake{half:bottom_n}"},
        {pos: [7, 0, 1], state: "anvilcraft:large_cake{half:bottom_center}"},
        {pos: [7, 0, 2], state: "anvilcraft:large_cake{half:bottom_s}"},
        {pos: [8, 0, 0], state: "anvilcraft:large_cake{half:bottom_en}"},
        {pos: [8, 0, 1], state: "anvilcraft:large_cake{half:bottom_e}"},
        {pos: [8, 0, 2], state: "anvilcraft:large_cake{half:bottom_es}"},
        {pos: [0, 1, 1], state: "anvilcraft:berry_cake_block"},
        {pos: [1, 1, 0], state: "anvilcraft:berry_cake_block"},
        {pos: [1, 1, 1], state: "anvilcraft:berry_cake_block"},
        {pos: [1, 1, 2], state: "anvilcraft:berry_cake_block"},
        {pos: [2, 1, 1], state: "anvilcraft:berry_cake_block"},
        {pos: [6, 1, 0], state: "anvilcraft:large_cake{half:mid_wn}"},
        {pos: [6, 1, 1], state: "anvilcraft:large_cake{half:mid_w}"},
        {pos: [6, 1, 2], state: "anvilcraft:large_cake{half:mid_ws}"},
        {pos: [7, 1, 0], state: "anvilcraft:large_cake{half:mid_n}"},
        {pos: [7, 1, 1], state: "anvilcraft:large_cake{half:mid_center}"},
        {pos: [7, 1, 2], state: "anvilcraft:large_cake{half:mid_s}"},
        {pos: [8, 1, 0], state: "anvilcraft:large_cake{half:mid_en}"},
        {pos: [8, 1, 1], state: "anvilcraft:large_cake{half:mid_e}"},
        {pos: [8, 1, 2], state: "anvilcraft:large_cake{half:mid_es}"},
        {pos: [1, 2, 1], state: "anvilcraft:chocolate_cake_block"},
        {pos: [6, 2, 0], state: "anvilcraft:large_cake{half:top_wn}"},
        {pos: [6, 2, 1], state: "anvilcraft:large_cake{half:top_w}"},
        {pos: [6, 2, 2], state: "anvilcraft:large_cake{half:top_ws}"},
        {pos: [7, 2, 0], state: "anvilcraft:large_cake{half:top_n}"},
        {pos: [7, 2, 1], state: "anvilcraft:large_cake{half:top_center}"},
        {pos: [7, 2, 2], state: "anvilcraft:large_cake{half:top_s}"},
        {pos: [8, 2, 0], state: "anvilcraft:large_cake{half:top_en}"},
        {pos: [8, 2, 1], state: "anvilcraft:large_cake{half:top_e}"},
        {pos: [8, 2, 2], state: "anvilcraft:large_cake{half:top_es}"}
    ],
    entities: [],
    palette: [
        "anvilcraft:cake_block",
        "anvilcraft:berry_cake_block",
        "anvilcraft:chocolate_cake_block",
        "anvilcraft:large_cake{half:bottom_wn}",
        "anvilcraft:large_cake{half:bottom_w}",
        "anvilcraft:large_cake{half:bottom_ws}",
        "anvilcraft:large_cake{half:bottom_n}",
        "anvilcraft:large_cake{half:bottom_center}",
        "anvilcraft:large_cake{half:bottom_s}",
        "anvilcraft:large_cake{half:bottom_en}",
        "anvilcraft:large_cake{half:bottom_e}",
        "anvilcraft:large_cake{half:bottom_es}",
        "anvilcraft:large_cake{half:mid_wn}",
        "anvilcraft:large_cake{half:mid_w}",
        "anvilcraft:large_cake{half:mid_ws}",
        "anvilcraft:large_cake{half:mid_n}",
        "anvilcraft:large_cake{half:mid_center}",
        "anvilcraft:large_cake{half:mid_s}",
        "anvilcraft:large_cake{half:mid_en}",
        "anvilcraft:large_cake{half:mid_e}",
        "anvilcraft:large_cake{half:mid_es}",
        "anvilcraft:large_cake{half:top_wn}",
        "anvilcraft:large_cake{half:top_w}",
        "anvilcraft:large_cake{half:top_ws}",
        "anvilcraft:large_cake{half:top_n}",
        "anvilcraft:large_cake{half:top_center}",
        "anvilcraft:large_cake{half:top_s}",
        "anvilcraft:large_cake{half:top_en}",
        "anvilcraft:large_cake{half:top_e}",
        "anvilcraft:large_cake{half:top_es}"
    ]
}