{
    DataVersion: 3955,
    size: [9, 4, 3],
    data: [
        {pos: [1, 0, 1], state: "minecraft:soul_soil"},
        {pos: [7, 0, 1], state: "minecraft:soul_soil"},
        {pos: [0, 1, 0], state: "anvilcraft:cursed_gold_block"},
        {pos: [0, 1, 1], state: "minecraft:chain{axis:z,waterlogged:false}"},
        {pos: [0, 1, 2], state: "anvilcraft:cursed_gold_block"},
        {pos: [1, 1, 0], state: "minecraft:chain{axis:x,waterlogged:false}"},
        {pos: [1, 1, 1], state: "minecraft:soul_fire"},
        {pos: [1, 1, 2], state: "minecraft:chain{axis:x,waterlogged:false}"},
        {pos: [2, 1, 0], state: "anvilcraft:cursed_gold_block"},
        {pos: [2, 1, 1], state: "minecraft:chain{axis:z,waterlogged:false}"},
        {pos: [2, 1, 2], state: "anvilcraft:cursed_gold_block"},
        {pos: [6, 1, 0], state: "minecraft:sculk"},
        {pos: [6, 1, 1], state: "minecraft:cobweb"},
        {pos: [6, 1, 2], state: "minecraft:sculk"},
        {pos: [7, 1, 0], state: "minecraft:cobweb"},
        {pos: [7, 1, 2], state: "minecraft:cobweb"},
        {pos: [8, 1, 0], state: "minecraft:sculk"},
        {pos: [8, 1, 1], state: "minecraft:cobweb"},
        {pos: [8, 1, 2], state: "minecraft:sculk"},
        {pos: [0, 2, 0], state: "minecraft:chain{axis:y,waterlogged:false}"},
        {pos: [0, 2, 2], state: "minecraft:chain{axis:y,waterlogged:false}"},
        {pos: [1, 2, 1], state: "anvilcraft:resentful_amber_block{facing:north}", nbt: {entity: {AbsorptionAmount: 0.0f, Air: 300s, ArmorDropChances: [0.085f, 0.085f, 0.085f, 0.085f], ArmorItems: [{}, {}, {}, {}], Brain: {memories: {}}, CanBreakDoors: 0b, CanPickUpLoot: 0b, DeathTime: 0s, DrownedConversionTime: -1, FallDistance: 0.0f, FallFlying: 0b, Fire: 0s, HandDropChances: [0.085f, 0.085f], HandItems: [{}, {}], Health: 20.0f, HurtByTimestamp: 0, HurtTime: 0s, InWaterTime: -1, Invulnerable: 0b, IsBaby: 0b, LeftHanded: 0b, Motion: [0.0d, 0.0d, 0.0d], OnGround: 0b, PersistenceRequired: 0b, PortalCooldown: 0, Pos: [0.0d, 0.0d, 0.0d], Rotation: [0.0f, 0.0f], attributes: [{base: 0.23000000417232513d, id: "minecraft:generic.movement_speed"}], id: "minecraft:zombie"}, id: "anvilcraft:resentful_amber_block"}},
        {pos: [2, 2, 0], state: "minecraft:chain{axis:y,waterlogged:false}"},
        {pos: [2, 2, 2], state: "minecraft:chain{axis:y,waterlogged:false}"},
        {pos: [4, 2, 1], state: "anvilcraft:arrow{facing:east}"},
        {pos: [6, 2, 0], state: "minecraft:cobweb"},
        {pos: [6, 2, 2], state: "minecraft:cobweb"},
        {pos: [7, 2, 1], state: "minecraft:spawner", nbt: {Delay: 0s, MaxNearbyEntities: 6s, MaxSpawnDelay: 800s, MinSpawnDelay: 200s, RequiredPlayerRange: 16s, SpawnCount: 4s, SpawnData: {entity: {id: "minecraft:zombie"}}, SpawnPotentials: [], SpawnRange: 4s, id: "minecraft:mob_spawner"}},
        {pos: [8, 2, 0], state: "minecraft:cobweb"},
        {pos: [8, 2, 2], state: "minecraft:cobweb"},
        {pos: [0, 3, 0], state: "anvilcraft:cursed_gold_block"},
        {pos: [0, 3, 1], state: "minecraft:chain{axis:z,waterlogged:false}"},
        {pos: [0, 3, 2], state: "anvilcraft:cursed_gold_block"},
        {pos: [1, 3, 0], state: "minecraft:chain{axis:x,waterlogged:false}"},
        {pos: [1, 3, 2], state: "minecraft:chain{axis:x,waterlogged:false}"},
        {pos: [2, 3, 0], state: "anvilcraft:cursed_gold_block"},
        {pos: [2, 3, 1], state: "minecraft:chain{axis:z,waterlogged:false}"},
        {pos: [2, 3, 2], state: "anvilcraft:cursed_gold_block"},
        {pos: [6, 3, 0], state: "minecraft:sculk"},
        {pos: [6, 3, 1], state: "minecraft:cobweb"},
        {pos: [6, 3, 2], state: "minecraft:sculk"},
        {pos: [7, 3, 0], state: "minecraft:cobweb"},
        {pos: [7, 3, 2], state: "minecraft:cobweb"},
        {pos: [8, 3, 0], state: "minecraft:sculk"},
        {pos: [8, 3, 1], state: "minecraft:cobweb"},
        {pos: [8, 3, 2], state: "minecraft:sculk"}
    ],
    entities: [],
    palette: [
        "minecraft:soul_soil",
        "anvilcraft:cursed_gold_block",
        "minecraft:sculk",
        "minecraft:chain{axis:z,waterlogged:false}",
        "minecraft:chain{axis:x,waterlogged:false}",
        "minecraft:soul_fire",
        "minecraft:cobweb",
        "minecraft:chain{axis:y,waterlogged:false}",
        "anvilcraft:arrow{facing:east}",
        "anvilcraft:resentful_amber_block{facing:north}",
        "minecraft:spawner"
    ]
}