{
    DataVersion: 3955,
    size: [3, 7, 4],
    data: [
        {pos: [1, 0, 2], state: "anvilcraft:heater{overload:false}", nbt: {id: "anvilcraft:heater"}},
        {pos: [1, 1, 2], state: "anvilcraft:fire_cauldron{level:2}"},
        {pos: [0, 2, 1], state: "anvilcraft:charge_collector{powered:false}", nbt: {ChargeCount: 128.0d, Charges: [I; 0, 128, 128, 128, 128, 128, 128, 128, 128, 128, 128], InputCooldownCount: 1, OutputCooldownCount: 5, Power: 93, id: "anvilcraft:charge_collector"}},
        {pos: [0, 2, 2], state: "anvilcraft:glowing_tungsten_block", nbt: {duration: 440, id: "anvilcraft:glowing_block"}},
        {pos: [0, 2, 3], state: "anvilcraft:charge_collector{powered:false}", nbt: {ChargeCount: 0.0d, Charges: [I; 128, 128, 128, 128, 128, 128, 128, 128, 128, 128, 128], InputCooldownCount: 2, OutputCooldownCount: 8, Power: 116, id: "anvilcraft:charge_collector"}},
        {pos: [1, 2, 1], state: "anvilcraft:magnet_block{lit:false}"},
        {pos: [1, 2, 3], state: "anvilcraft:magnet_block{lit:false}"},
        {pos: [2, 2, 1], state: "anvilcraft:charge_collector{powered:false}", nbt: {ChargeCount: 128.0d, Charges: [I; 0, 128, 128, 128, 128, 128, 128, 128, 128, 128, 128], InputCooldownCount: 1, OutputCooldownCount: 1, Power: 69, id: "anvilcraft:charge_collector"}},
        {pos: [2, 2, 2], state: "anvilcraft:glowing_tungsten_block", nbt: {duration: 440, id: "anvilcraft:glowing_block"}},
        {pos: [2, 2, 3], state: "anvilcraft:charge_collector{powered:false}", nbt: {ChargeCount: 0.0d, Charges: [I; 128, 128, 128, 128, 128, 128, 128, 128, 128, 128, 128], InputCooldownCount: 2, OutputCooldownCount: 10, Power: 128, id: "anvilcraft:charge_collector"}},
        {pos: [0, 3, 1], state: "anvilcraft:charge_collector{powered:false}", nbt: {ChargeCount: 128.0d, Charges: [I; 0, 128, 128, 128, 128, 128, 128, 128, 128, 128, 128], InputCooldownCount: 1, OutputCooldownCount: 5, Power: 93, id: "anvilcraft:charge_collector"}},
        {pos: [0, 3, 2], state: "anvilcraft:glowing_tungsten_block", nbt: {duration: 440, id: "anvilcraft:glowing_block"}},
        {pos: [0, 3, 3], state: "anvilcraft:charge_collector{powered:false}", nbt: {ChargeCount: 128.0d, Charges: [I; 0, 128, 128, 128, 128, 128, 128, 128, 128, 128, 128], InputCooldownCount: 1, OutputCooldownCount: 9, Power: 116, id: "anvilcraft:charge_collector"}},
        {pos: [1, 3, 0], state: "anvilcraft:heat_collector{powered:false}", nbt: {id: "anvilcraft:heat_collector", tickCache: 52}},
        {pos: [1, 3, 1], state: "anvilcraft:magnet_block{lit:false}"},
        {pos: [1, 3, 3], state: "anvilcraft:magnet_block{lit:false}"},
        {pos: [2, 3, 1], state: "anvilcraft:charge_collector{powered:false}", nbt: {ChargeCount: 0.0d, Charges: [I; 128, 128, 128, 128, 128, 128, 128, 128, 128, 128, 128], InputCooldownCount: 2, OutputCooldownCount: 2, Power: 81, id: "anvilcraft:charge_collector"}},
        {pos: [2, 3, 2], state: "anvilcraft:glowing_tungsten_block", nbt: {duration: 440, id: "anvilcraft:glowing_block"}},
        {pos: [2, 3, 3], state: "anvilcraft:charge_collector{powered:false}", nbt: {ChargeCount: 0.0d, Charges: [I; 128, 128, 128, 128, 128, 128, 128, 128, 128, 128, 128], InputCooldownCount: 2, OutputCooldownCount: 10, Power: 128, id: "anvilcraft:charge_collector"}},
        {pos: [0, 4, 1], state: "anvilcraft:charge_collector{powered:false}", nbt: {ChargeCount: 128.0d, Charges: [I; 0, 128, 128, 128, 128, 128, 128, 128, 128, 128, 128], InputCooldownCount: 1, OutputCooldownCount: 5, Power: 93, id: "anvilcraft:charge_collector"}},
        {pos: [0, 4, 2], state: "anvilcraft:glowing_tungsten_block", nbt: {duration: 440, id: "anvilcraft:glowing_block"}},
        {pos: [0, 4, 3], state: "anvilcraft:charge_collector{powered:false}", nbt: {ChargeCount: 128.0d, Charges: [I; 0, 128, 128, 128, 128, 128, 128, 128, 128, 128, 128], InputCooldownCount: 1, OutputCooldownCount: 9, Power: 116, id: "anvilcraft:charge_collector"}},
        {pos: [1, 4, 1], state: "anvilcraft:magnet_block{lit:false}"},
        {pos: [1, 4, 3], state: "anvilcraft:magnet_block{lit:false}"},
        {pos: [2, 4, 1], state: "anvilcraft:charge_collector{powered:false}", nbt: {ChargeCount: 0.0d, Charges: [I; 128, 128, 128, 128, 128, 128, 128, 128, 128, 128, 128], InputCooldownCount: 2, OutputCooldownCount: 2, Power: 81, id: "anvilcraft:charge_collector"}},
        {pos: [2, 4, 2], state: "anvilcraft:glowing_tungsten_block", nbt: {duration: 440, id: "anvilcraft:glowing_block"}},
        {pos: [2, 4, 3], state: "anvilcraft:charge_collector{powered:false}", nbt: {ChargeCount: 0.0d, Charges: [I; 128, 128, 128, 128, 128, 128, 128, 128, 128, 128, 128], InputCooldownCount: 2, OutputCooldownCount: 10, Power: 128, id: "anvilcraft:charge_collector"}},
        {pos: [0, 5, 1], state: "anvilcraft:charge_collector{powered:false}", nbt: {ChargeCount: 0.0d, Charges: [I; 128, 128, 128, 128, 128, 128, 128, 128, 128, 128, 128], InputCooldownCount: 2, OutputCooldownCount: 6, Power: 104, id: "anvilcraft:charge_collector"}},
        {pos: [0, 5, 2], state: "anvilcraft:glowing_tungsten_block", nbt: {duration: 440, id: "anvilcraft:glowing_block"}},
        {pos: [0, 5, 3], state: "anvilcraft:charge_collector{powered:false}", nbt: {ChargeCount: 128.0d, Charges: [I; 0, 128, 128, 128, 128, 128, 128, 128, 128, 128, 128], InputCooldownCount: 1, OutputCooldownCount: 9, Power: 116, id: "anvilcraft:charge_collector"}},
        {pos: [1, 5, 1], state: "anvilcraft:magnet_block{lit:false}"},
        {pos: [1, 5, 3], state: "anvilcraft:magnet_block{lit:false}"},
        {pos: [2, 5, 1], state: "anvilcraft:charge_collector{powered:false}", nbt: {ChargeCount: 0.0d, Charges: [I; 128, 128, 128, 128, 128, 128, 128, 128, 128, 128, 128], InputCooldownCount: 2, OutputCooldownCount: 4, Power: 93, id: "anvilcraft:charge_collector"}},
        {pos: [2, 5, 2], state: "anvilcraft:glowing_tungsten_block", nbt: {duration: 440, id: "anvilcraft:glowing_block"}},
        {pos: [2, 5, 3], state: "anvilcraft:charge_collector{powered:false}", nbt: {ChargeCount: 0.0d, Charges: [I; 128, 128, 128, 128, 128, 128, 128, 128, 128, 128, 128], InputCooldownCount: 2, OutputCooldownCount: 10, Power: 128, id: "anvilcraft:charge_collector"}},
        {pos: [1, 6, 2], state: "anvilcraft:plasma_jets", nbt: {duration: 11554, id: "anvilcraft:plasma_jets", tube_walls: [{center: [I; 12, -58, 8]}, {center: [I; 12, -57, 8]}, {center: [I; 12, -56, 8]}, {center: [I; 12, -55, 8]}]}}
    ],
    entities: [],
    palette: [
        "anvilcraft:magnet_block{lit:false}",
        "anvilcraft:fire_cauldron{level:2}",
        "anvilcraft:heater{overload:false}",
        "anvilcraft:charge_collector{powered:false}",
        "anvilcraft:glowing_tungsten_block",
        "anvilcraft:heat_collector{powered:false}",
        "anvilcraft:plasma_jets"
    ]
}