{
    DataVersion: 3955,
    size: [9, 8, 3],
    data: [
        {pos: [0, 0, 0], state: "anvilcraft:cut_heavy_iron_block"},
        {pos: [0, 0, 1], state: "anvilcraft:cut_heavy_iron_block"},
        {pos: [0, 0, 2], state: "anvilcraft:cut_heavy_iron_block"},
        {pos: [1, 0, 0], state: "anvilcraft:cut_heavy_iron_block"},
        {pos: [1, 0, 1], state: "anvilcraft:cut_heavy_iron_block"},
        {pos: [1, 0, 2], state: "anvilcraft:cut_heavy_iron_block"},
        {pos: [2, 0, 0], state: "anvilcraft:cut_heavy_iron_block"},
        {pos: [2, 0, 1], state: "anvilcraft:cut_heavy_iron_block"},
        {pos: [2, 0, 2], state: "anvilcraft:cut_heavy_iron_block"},
        {pos: [6, 0, 0], state: "anvilcraft:giant_anvil{cube:corner,half:bottom_wn}"},
        {pos: [6, 0, 1], state: "anvilcraft:giant_anvil{cube:corner,half:bottom_w}"},
        {pos: [6, 0, 2], state: "anvilcraft:giant_anvil{cube:corner,half:bottom_ws}"},
        {pos: [7, 0, 0], state: "anvilcraft:giant_anvil{cube:corner,half:bottom_n}"},
        {pos: [7, 0, 1], state: "anvilcraft:giant_anvil{cube:corner,half:bottom_center}"},
        {pos: [7, 0, 2], state: "anvilcraft:giant_anvil{cube:corner,half:bottom_s}"},
        {pos: [8, 0, 0], state: "anvilcraft:giant_anvil{cube:corner,half:bottom_en}"},
        {pos: [8, 0, 1], state: "anvilcraft:giant_anvil{cube:corner,half:bottom_e}"},
        {pos: [8, 0, 2], state: "anvilcraft:giant_anvil{cube:corner,half:bottom_es}"},
        {pos: [1, 1, 1], state: "anvilcraft:heavy_iron_column"},
        {pos: [4, 1, 1], state: "anvilcraft:arrow{facing:east}"},
        {pos: [6, 1, 0], state: "anvilcraft:giant_anvil{cube:corner,half:mid_wn}"},
        {pos: [6, 1, 1], state: "anvilcraft:giant_anvil{cube:corner,half:mid_w}"},
        {pos: [6, 1, 2], state: "anvilcraft:giant_anvil{cube:corner,half:mid_ws}"},
        {pos: [7, 1, 0], state: "anvilcraft:giant_anvil{cube:corner,half:mid_n}"},
        {pos: [7, 1, 1], state: "anvilcraft:giant_anvil{cube:center,half:mid_center}"},
        {pos: [7, 1, 2], state: "anvilcraft:giant_anvil{cube:corner,half:mid_s}"},
        {pos: [8, 1, 0], state: "anvilcraft:giant_anvil{cube:corner,half:mid_en}"},
        {pos: [8, 1, 1], state: "anvilcraft:giant_anvil{cube:corner,half:mid_e}"},
        {pos: [8, 1, 2], state: "anvilcraft:giant_anvil{cube:corner,half:mid_es}"},
        {pos: [0, 2, 0], state: "anvilcraft:polished_heavy_iron_block"},
        {pos: [0, 2, 1], state: "anvilcraft:polished_heavy_iron_block"},
        {pos: [0, 2, 2], state: "anvilcraft:polished_heavy_iron_block"},
        {pos: [1, 2, 0], state: "anvilcraft:polished_heavy_iron_block"},
        {pos: [1, 2, 1], state: "anvilcraft:polished_heavy_iron_block"},
        {pos: [1, 2, 2], state: "anvilcraft:polished_heavy_iron_block"},
        {pos: [2, 2, 0], state: "anvilcraft:polished_heavy_iron_block"},
        {pos: [2, 2, 1], state: "anvilcraft:polished_heavy_iron_block"},
        {pos: [2, 2, 2], state: "anvilcraft:polished_heavy_iron_block"},
        {pos: [6, 2, 0], state: "anvilcraft:giant_anvil{cube:corner,half:top_wn}"},
        {pos: [6, 2, 1], state: "anvilcraft:giant_anvil{cube:corner,half:top_w}"},
        {pos: [6, 2, 2], state: "anvilcraft:giant_anvil{cube:corner,half:top_ws}"},
        {pos: [7, 2, 0], state: "anvilcraft:giant_anvil{cube:corner,half:top_n}"},
        {pos: [7, 2, 1], state: "anvilcraft:giant_anvil{cube:corner,half:top_center}"},
        {pos: [7, 2, 2], state: "anvilcraft:giant_anvil{cube:corner,half:top_s}"},
        {pos: [8, 2, 0], state: "anvilcraft:giant_anvil{cube:corner,half:top_en}"},
        {pos: [8, 2, 1], state: "anvilcraft:giant_anvil{cube:corner,half:top_e}"},
        {pos: [8, 2, 2], state: "anvilcraft:giant_anvil{cube:corner,half:top_es}"},
        {pos: [0, 3, 0], state: "minecraft:crafting_table"},
        {pos: [0, 3, 1], state: "minecraft:crafting_table"},
        {pos: [0, 3, 2], state: "minecraft:crafting_table"},
        {pos: [1, 3, 0], state: "minecraft:crafting_table"},
        {pos: [1, 3, 1], state: "minecraft:crafting_table"},
        {pos: [1, 3, 2], state: "minecraft:crafting_table"},
        {pos: [2, 3, 0], state: "minecraft:crafting_table"},
        {pos: [2, 3, 1], state: "minecraft:crafting_table"},
        {pos: [2, 3, 2], state: "minecraft:crafting_table"},
        {pos: [6, 3, 0], state: "minecraft:crafting_table"},
        {pos: [6, 3, 1], state: "minecraft:crafting_table"},
        {pos: [6, 3, 2], state: "minecraft:crafting_table"},
        {pos: [7, 3, 0], state: "minecraft:crafting_table"},
        {pos: [7, 3, 1], state: "minecraft:crafting_table"},
        {pos: [7, 3, 2], state: "minecraft:crafting_table"},
        {pos: [8, 3, 0], state: "minecraft:crafting_table"},
        {pos: [8, 3, 1], state: "minecraft:crafting_table"},
        {pos: [8, 3, 2], state: "minecraft:crafting_table"},
        {pos: [6, 4, 0], state: "anvilcraft:giant_anvil{cube:corner,half:bottom_wn}"},
        {pos: [6, 4, 1], state: "anvilcraft:giant_anvil{cube:corner,half:bottom_w}"},
        {pos: [6, 4, 2], state: "anvilcraft:giant_anvil{cube:corner,half:bottom_ws}"},
        {pos: [7, 4, 0], state: "anvilcraft:giant_anvil{cube:corner,half:bottom_n}"},
        {pos: [7, 4, 1], state: "anvilcraft:giant_anvil{cube:corner,half:bottom_center}"},
        {pos: [7, 4, 2], state: "anvilcraft:giant_anvil{cube:corner,half:bottom_s}"},
        {pos: [8, 4, 0], state: "anvilcraft:giant_anvil{cube:corner,half:bottom_en}"},
        {pos: [8, 4, 1], state: "anvilcraft:giant_anvil{cube:corner,half:bottom_e}"},
        {pos: [8, 4, 2], state: "anvilcraft:giant_anvil{cube:corner,half:bottom_es}"},
        {pos: [0, 5, 0], state: "anvilcraft:giant_anvil{cube:corner,half:bottom_wn}"},
        {pos: [0, 5, 1], state: "anvilcraft:giant_anvil{cube:corner,half:bottom_w}"},
        {pos: [0, 5, 2], state: "anvilcraft:giant_anvil{cube:corner,half:bottom_ws}"},
        {pos: [1, 5, 0], state: "anvilcraft:giant_anvil{cube:corner,half:bottom_n}"},
        {pos: [1, 5, 1], state: "anvilcraft:giant_anvil{cube:corner,half:bottom_center}"},
        {pos: [1, 5, 2], state: "anvilcraft:giant_anvil{cube:corner,half:bottom_s}"},
        {pos: [2, 5, 0], state: "anvilcraft:giant_anvil{cube:corner,half:bottom_en}"},
        {pos: [2, 5, 1], state: "anvilcraft:giant_anvil{cube:corner,half:bottom_e}"},
        {pos: [2, 5, 2], state: "anvilcraft:giant_anvil{cube:corner,half:bottom_es}"},
        {pos: [6, 5, 0], state: "anvilcraft:giant_anvil{cube:corner,half:mid_wn}"},
        {pos: [6, 5, 1], state: "anvilcraft:giant_anvil{cube:corner,half:mid_w}"},
        {pos: [6, 5, 2], state: "anvilcraft:giant_anvil{cube:corner,half:mid_ws}"},
        {pos: [7, 5, 0], state: "anvilcraft:giant_anvil{cube:corner,half:mid_n}"},
        {pos: [7, 5, 1], state: "anvilcraft:giant_anvil{cube:center,half:mid_center}"},
        {pos: [7, 5, 2], state: "anvilcraft:giant_anvil{cube:corner,half:mid_s}"},
        {pos: [8, 5, 0], state: "anvilcraft:giant_anvil{cube:corner,half:mid_en}"},
        {pos: [8, 5, 1], state: "anvilcraft:giant_anvil{cube:corner,half:mid_e}"},
        {pos: [8, 5, 2], state: "anvilcraft:giant_anvil{cube:corner,half:mid_es}"},
        {pos: [0, 6, 0], state: "anvilcraft:giant_anvil{cube:corner,half:mid_wn}"},
        {pos: [0, 6, 1], state: "anvilcraft:giant_anvil{cube:corner,half:mid_w}"},
        {pos: [0, 6, 2], state: "anvilcraft:giant_anvil{cube:corner,half:mid_ws}"},
        {pos: [1, 6, 0], state: "anvilcraft:giant_anvil{cube:corner,half:mid_n}"},
        {pos: [1, 6, 1], state: "anvilcraft:giant_anvil{cube:center,half:mid_center}"},
        {pos: [1, 6, 2], state: "anvilcraft:giant_anvil{cube:corner,half:mid_s}"},
        {pos: [2, 6, 0], state: "anvilcraft:giant_anvil{cube:corner,half:mid_en}"},
        {pos: [2, 6, 1], state: "anvilcraft:giant_anvil{cube:corner,half:mid_e}"},
        {pos: [2, 6, 2], state: "anvilcraft:giant_anvil{cube:corner,half:mid_es}"},
        {pos: [6, 6, 0], state: "anvilcraft:giant_anvil{cube:corner,half:top_wn}"},
        {pos: [6, 6, 1], state: "anvilcraft:giant_anvil{cube:corner,half:top_w}"},
        {pos: [6, 6, 2], state: "anvilcraft:giant_anvil{cube:corner,half:top_ws}"},
        {pos: [7, 6, 0], state: "anvilcraft:giant_anvil{cube:corner,half:top_n}"},
        {pos: [7, 6, 1], state: "anvilcraft:giant_anvil{cube:corner,half:top_center}"},
        {pos: [7, 6, 2], state: "anvilcraft:giant_anvil{cube:corner,half:top_s}"},
        {pos: [8, 6, 0], state: "anvilcraft:giant_anvil{cube:corner,half:top_en}"},
        {pos: [8, 6, 1], state: "anvilcraft:giant_anvil{cube:corner,half:top_e}"},
        {pos: [8, 6, 2], state: "anvilcraft:giant_anvil{cube:corner,half:top_es}"},
        {pos: [0, 7, 0], state: "anvilcraft:giant_anvil{cube:corner,half:top_wn}"},
        {pos: [0, 7, 1], state: "anvilcraft:giant_anvil{cube:corner,half:top_w}"},
        {pos: [0, 7, 2], state: "anvilcraft:giant_anvil{cube:corner,half:top_ws}"},
        {pos: [1, 7, 0], state: "anvilcraft:giant_anvil{cube:corner,half:top_n}"},
        {pos: [1, 7, 1], state: "anvilcraft:giant_anvil{cube:corner,half:top_center}"},
        {pos: [1, 7, 2], state: "anvilcraft:giant_anvil{cube:corner,half:top_s}"},
        {pos: [2, 7, 0], state: "anvilcraft:giant_anvil{cube:corner,half:top_en}"},
        {pos: [2, 7, 1], state: "anvilcraft:giant_anvil{cube:corner,half:top_e}"},
        {pos: [2, 7, 2], state: "anvilcraft:giant_anvil{cube:corner,half:top_es}"}
    ],
    entities: [],
    palette: [
        "anvilcraft:cut_heavy_iron_block",
        "anvilcraft:heavy_iron_column",
        "anvilcraft:polished_heavy_iron_block",
        "minecraft:crafting_table",
        "anvilcraft:giant_anvil{cube:corner,half:bottom_wn}",
        "anvilcraft:giant_anvil{cube:corner,half:bottom_w}",
        "anvilcraft:giant_anvil{cube:corner,half:bottom_ws}",
        "anvilcraft:giant_anvil{cube:corner,half:bottom_n}",
        "anvilcraft:giant_anvil{cube:corner,half:bottom_center}",
        "anvilcraft:giant_anvil{cube:corner,half:bottom_s}",
        "anvilcraft:giant_anvil{cube:corner,half:bottom_en}",
        "anvilcraft:giant_anvil{cube:corner,half:bottom_e}",
        "anvilcraft:giant_anvil{cube:corner,half:bottom_es}",
        "anvilcraft:arrow{facing:east}",
        "anvilcraft:giant_anvil{cube:corner,half:mid_wn}",
        "anvilcraft:giant_anvil{cube:corner,half:mid_w}",
        "anvilcraft:giant_anvil{cube:corner,half:mid_ws}",
        "anvilcraft:giant_anvil{cube:corner,half:mid_n}",
        "anvilcraft:giant_anvil{cube:center,half:mid_center}",
        "anvilcraft:giant_anvil{cube:corner,half:mid_s}",
        "anvilcraft:giant_anvil{cube:corner,half:mid_en}",
        "anvilcraft:giant_anvil{cube:corner,half:mid_e}",
        "anvilcraft:giant_anvil{cube:corner,half:mid_es}",
        "anvilcraft:giant_anvil{cube:corner,half:top_wn}",
        "anvilcraft:giant_anvil{cube:corner,half:top_w}",
        "anvilcraft:giant_anvil{cube:corner,half:top_ws}",
        "anvilcraft:giant_anvil{cube:corner,half:top_n}",
        "anvilcraft:giant_anvil{cube:corner,half:top_center}",
        "anvilcraft:giant_anvil{cube:corner,half:top_s}",
        "anvilcraft:giant_anvil{cube:corner,half:top_en}",
        "anvilcraft:giant_anvil{cube:corner,half:top_e}",
        "anvilcraft:giant_anvil{cube:corner,half:top_es}"
    ]
}