{
    DataVersion: 3955,
    size: [7, 8, 5],
    data: [
        {pos: [1, 0, 3], state: "minecraft:smooth_stone"},
        {pos: [2, 0, 3], state: "minecraft:smooth_stone"},
        {pos: [3, 0, 2], state: "minecraft:chest{facing:north,type:left,waterlogged:false}", nbt: {Items: [], id: "minecraft:chest"}},
        {pos: [3, 0, 3], state: "anvilcraft:chute{enabled:true,facing:north}", nbt: {Cooldown: 0, Inventory: {FilterEnabled: 0b, Inventory: [{Disabled: 0b, IsEmptySlot: 1b, Slot: 0, SlotFilterEnabled: 0b, SlotLimit: 64}, {Disabled: 0b, IsEmptySlot: 1b, Slot: 1, SlotFilterEnabled: 0b, SlotLimit: 64}, {Disabled: 0b, IsEmptySlot: 1b, Slot: 2, SlotFilterEnabled: 0b, SlotLimit: 64}, {Disabled: 0b, IsEmptySlot: 1b, Slot: 3, SlotFilterEnabled: 0b, SlotLimit: 64}, {Disabled: 0b, IsEmptySlot: 1b, Slot: 4, SlotFilterEnabled: 0b, SlotLimit: 64}, {Disabled: 0b, IsEmptySlot: 1b, Slot: 5, SlotFilterEnabled: 0b, SlotLimit: 64}, {Disabled: 0b, IsEmptySlot: 1b, Slot: 6, SlotFilterEnabled: 0b, SlotLimit: 64}, {Disabled: 0b, IsEmptySlot: 1b, Slot: 7, SlotFilterEnabled: 0b, SlotLimit: 64}, {Disabled: 0b, IsEmptySlot: 1b, Slot: 8, SlotFilterEnabled: 0b, SlotLimit: 64}], Size: 9}, id: "anvilcraft:chute"}},
        {pos: [4, 0, 2], state: "minecraft:chest{facing:north,type:right,waterlogged:false}", nbt: {Items: [{Slot: 0b, count: 64, id: "minecraft:cobblestone"}, {Slot: 1b, count: 64, id: "minecraft:cobblestone"}, {Slot: 2b, count: 64, id: "minecraft:cobblestone"}, {Slot: 3b, count: 64, id: "minecraft:cobblestone"}, {Slot: 4b, count: 64, id: "minecraft:cobblestone"}, {Slot: 5b, count: 51, id: "minecraft:cobblestone"}, {Slot: 6b, count: 64, id: "minecraft:gravel"}, {Slot: 7b, count: 64, id: "minecraft:gravel"}, {Slot: 8b, count: 64, id: "minecraft:gravel"}, {Slot: 9b, count: 64, id: "minecraft:gravel"}, {Slot: 10b, count: 64, id: "minecraft:gravel"}, {Slot: 11b, count: 35, id: "minecraft:gravel"}, {Slot: 12b, count: 64, id: "minecraft:sand"}, {Slot: 13b, count: 1, id: "minecraft:sand"}], id: "minecraft:chest"}},
        {pos: [4, 0, 3], state: "minecraft:smooth_stone"},
        {pos: [5, 0, 3], state: "minecraft:smooth_stone"},
        {pos: [0, 1, 2], state: "minecraft:lever{face:wall,facing:north,powered:true}"},
        {pos: [0, 1, 3], state: "minecraft:smooth_stone"},
        {pos: [1, 1, 2], state: "minecraft:glass"},
        {pos: [1, 1, 3], state: "minecraft:powered_rail{powered:true,shape:east_west,waterlogged:false}"},
        {pos: [1, 1, 4], state: "minecraft:smooth_stone"},
        {pos: [2, 1, 2], state: "minecraft:glass"},
        {pos: [2, 1, 3], state: "minecraft:rail{shape:east_west,waterlogged:false}"},
        {pos: [2, 1, 4], state: "minecraft:smooth_stone"},
        {pos: [3, 1, 2], state: "minecraft:glass"},
        {pos: [3, 1, 3], state: "minecraft:rail{shape:east_west,waterlogged:false}"},
        {pos: [3, 1, 4], state: "minecraft:smooth_stone"},
        {pos: [4, 1, 2], state: "minecraft:glass"},
        {pos: [4, 1, 3], state: "minecraft:rail{shape:east_west,waterlogged:false}"},
        {pos: [4, 1, 4], state: "minecraft:smooth_stone"},
        {pos: [5, 1, 2], state: "minecraft:glass"},
        {pos: [5, 1, 3], state: "minecraft:powered_rail{powered:true,shape:east_west,waterlogged:false}"},
        {pos: [5, 1, 4], state: "minecraft:smooth_stone"},
        {pos: [6, 1, 2], state: "minecraft:lever{face:wall,facing:north,powered:true}"},
        {pos: [6, 1, 3], state: "minecraft:smooth_stone"},
        {pos: [1, 2, 1], state: "minecraft:sticky_piston{extended:true,facing:south}"},
        {pos: [1, 2, 2], state: "minecraft:piston_head{facing:south,short:false,type:sticky}"},
        {pos: [1, 2, 3], state: "minecraft:stonecutter{facing:west}"},
        {pos: [2, 2, 1], state: "minecraft:sticky_piston{extended:true,facing:south}"},
        {pos: [2, 2, 2], state: "minecraft:piston_head{facing:south,short:false,type:sticky}"},
        {pos: [2, 2, 3], state: "minecraft:stonecutter{facing:west}"},
        {pos: [3, 2, 1], state: "minecraft:sticky_piston{extended:true,facing:south}"},
        {pos: [3, 2, 2], state: "minecraft:piston_head{facing:south,short:false,type:sticky}"},
        {pos: [3, 2, 3], state: "minecraft:stonecutter{facing:west}"},
        {pos: [4, 2, 1], state: "minecraft:sticky_piston{extended:true,facing:south}"},
        {pos: [4, 2, 2], state: "minecraft:piston_head{facing:south,short:false,type:sticky}"},
        {pos: [4, 2, 3], state: "minecraft:stonecutter{facing:west}"},
        {pos: [5, 2, 1], state: "minecraft:sticky_piston{extended:true,facing:south}"},
        {pos: [5, 2, 2], state: "minecraft:piston_head{facing:south,short:false,type:sticky}"},
        {pos: [5, 2, 3], state: "minecraft:stonecutter{facing:west}"},
        {pos: [0, 3, 2], state: "minecraft:smooth_stone"},
        {pos: [1, 3, 0], state: "minecraft:lever{face:wall,facing:north,powered:true}"},
        {pos: [1, 3, 1], state: "minecraft:smooth_stone"},
        {pos: [1, 3, 2], state: "minecraft:lava{level:4}"},
        {pos: [1, 3, 3], state: "minecraft:cobblestone"},
        {pos: [1, 3, 4], state: "minecraft:oak_leaves{distance:7,persistent:true,waterlogged:true}"},
        {pos: [2, 3, 1], state: "minecraft:smooth_stone"},
        {pos: [2, 3, 2], state: "minecraft:lava{level:2}"},
        {pos: [2, 3, 3], state: "minecraft:cobblestone"},
        {pos: [2, 3, 4], state: "minecraft:oak_leaves{distance:7,persistent:true,waterlogged:true}"},
        {pos: [3, 3, 1], state: "minecraft:smooth_stone"},
        {pos: [3, 3, 2], state: "minecraft:lava{level:0}"},
        {pos: [3, 3, 3], state: "minecraft:cobblestone"},
        {pos: [3, 3, 4], state: "minecraft:oak_leaves{distance:7,persistent:true,waterlogged:true}"},
        {pos: [4, 3, 1], state: "minecraft:smooth_stone"},
        {pos: [4, 3, 2], state: "minecraft:lava{level:2}"},
        {pos: [4, 3, 3], state: "minecraft:cobblestone"},
        {pos: [4, 3, 4], state: "minecraft:oak_leaves{distance:7,persistent:true,waterlogged:true}"},
        {pos: [5, 3, 1], state: "minecraft:smooth_stone"},
        {pos: [5, 3, 2], state: "minecraft:lava{level:4}"},
        {pos: [5, 3, 3], state: "minecraft:cobblestone"},
        {pos: [5, 3, 4], state: "minecraft:oak_leaves{distance:7,persistent:true,waterlogged:true}"},
        {pos: [6, 3, 2], state: "minecraft:smooth_stone"},
        {pos: [1, 4, 1], state: "minecraft:redstone_wire{east:side,north:none,power:15,south:none,west:side}"},
        {pos: [2, 4, 1], state: "minecraft:redstone_wire{east:side,north:none,power:14,south:none,west:side}"},
        {pos: [3, 4, 1], state: "minecraft:redstone_wire{east:side,north:none,power:13,south:none,west:side}"},
        {pos: [4, 4, 1], state: "minecraft:redstone_wire{east:up,north:none,power:12,south:none,west:side}"},
        {pos: [5, 4, 1], state: "minecraft:smooth_stone"},
        {pos: [1, 5, 3], state: "minecraft:anvil{facing:east}"},
        {pos: [2, 5, 3], state: "minecraft:anvil{facing:east}"},
        {pos: [3, 5, 3], state: "minecraft:anvil{facing:east}"},
        {pos: [4, 5, 3], state: "minecraft:anvil{facing:east}"},
        {pos: [5, 5, 1], state: "minecraft:redstone_wire{east:side,north:none,power:11,south:none,west:side}"},
        {pos: [5, 5, 3], state: "minecraft:anvil{facing:east}"},
        {pos: [1, 6, 0], state: "minecraft:lever{face:wall,facing:north,powered:true}"},
        {pos: [1, 6, 1], state: "minecraft:smooth_stone"},
        {pos: [1, 6, 2], state: "anvilcraft:pulse_generator{facing:north,powered:false}", nbt: {ExtraData: {Inputting: 1b, OutputMode: 0b, SignalDuration: 5, StartMode: 2b, State: 0b, WaitingTime: 10}, id: "anvilcraft:pulse_generator"}},
        {pos: [1, 6, 3], state: "anvilcraft:magnet_block{lit:false}"},
        {pos: [2, 6, 0], state: "minecraft:lever{face:wall,facing:north,powered:false}"},
        {pos: [2, 6, 1], state: "minecraft:smooth_stone"},
        {pos: [2, 6, 3], state: "anvilcraft:magnet_block{lit:false}"},
        {pos: [3, 6, 1], state: "minecraft:sticky_piston{extended:false,facing:east}"},
        {pos: [3, 6, 3], state: "anvilcraft:magnet_block{lit:false}"},
        {pos: [4, 6, 1], state: "minecraft:smooth_stone"},
        {pos: [4, 6, 3], state: "anvilcraft:magnet_block{lit:false}"},
        {pos: [5, 6, 2], state: "anvilcraft:pulse_generator{facing:south,powered:false}", nbt: {ExtraData: {Inputting: 0b, OutputMode: 0b, SignalDuration: 17, StartMode: 0b, State: 0b, WaitingTime: 6}, id: "anvilcraft:pulse_generator"}},
        {pos: [5, 6, 3], state: "anvilcraft:magnet_block{lit:false}"},
        {pos: [1, 7, 3], state: "minecraft:redstone_wire{east:side,north:none,power:0,south:none,west:side}"},
        {pos: [2, 7, 3], state: "minecraft:redstone_wire{east:side,north:none,power:0,south:none,west:side}"},
        {pos: [3, 7, 3], state: "minecraft:redstone_wire{east:side,north:none,power:0,south:none,west:side}"},
        {pos: [4, 7, 3], state: "minecraft:redstone_wire{east:side,north:none,power:0,south:none,west:side}"},
        {pos: [5, 7, 3], state: "minecraft:redstone_wire{east:side,north:none,power:0,south:none,west:side}"}
    ],
    entities: [],
    palette: [
        "minecraft:smooth_stone",
        "minecraft:glass",
        "minecraft:cobblestone",
        "minecraft:oak_leaves{distance:7,persistent:true,waterlogged:true}",
        "anvilcraft:magnet_block{lit:false}",
        "minecraft:sticky_piston{extended:false,facing:east}",
        "minecraft:lever{face:wall,facing:north,powered:true}",
        "minecraft:powered_rail{powered:true,shape:east_west,waterlogged:false}",
        "minecraft:rail{shape:east_west,waterlogged:false}",
        "minecraft:sticky_piston{extended:true,facing:south}",
        "minecraft:piston_head{facing:south,short:false,type:sticky}",
        "minecraft:stonecutter{facing:west}",
        "minecraft:lava{level:4}",
        "minecraft:lava{level:2}",
        "minecraft:lava{level:0}",
        "minecraft:redstone_wire{east:side,north:none,power:15,south:none,west:side}",
        "minecraft:redstone_wire{east:side,north:none,power:14,south:none,west:side}",
        "minecraft:redstone_wire{east:side,north:none,power:13,south:none,west:side}",
        "minecraft:redstone_wire{east:up,north:none,power:12,south:none,west:side}",
        "minecraft:anvil{facing:east}",
        "minecraft:redstone_wire{east:side,north:none,power:11,south:none,west:side}",
        "minecraft:lever{face:wall,facing:north,powered:false}",
        "minecraft:redstone_wire{east:side,north:none,power:0,south:none,west:side}",
        "minecraft:chest{facing:north,type:left,waterlogged:false}",
        "anvilcraft:chute{enabled:true,facing:north}",
        "minecraft:chest{facing:north,type:right,waterlogged:false}",
        "anvilcraft:pulse_generator{facing:north,powered:false}",
        "anvilcraft:pulse_generator{facing:south,powered:false}"
    ]
}