{
    DataVersion: 3955,
    size: [8, 7, 5],
    data: [
        {pos: [2, 0, 1], state: "anvilcraft:chute{enabled:true,facing:south}", nbt: {Cooldown: 0, Inventory: {FilterEnabled: 0b, Inventory: [{Disabled: 0b, IsEmptySlot: 1b, Slot: 0, SlotFilterEnabled: 0b, SlotLimit: 64}, {Disabled: 0b, IsEmptySlot: 1b, Slot: 1, SlotFilterEnabled: 0b, SlotLimit: 64}, {Disabled: 0b, IsEmptySlot: 1b, Slot: 2, SlotFilterEnabled: 0b, SlotLimit: 64}, {Disabled: 0b, IsEmptySlot: 1b, Slot: 3, SlotFilterEnabled: 0b, SlotLimit: 64}, {Disabled: 0b, IsEmptySlot: 1b, Slot: 4, SlotFilterEnabled: 0b, SlotLimit: 64}, {Disabled: 0b, IsEmptySlot: 1b, Slot: 5, SlotFilterEnabled: 0b, SlotLimit: 64}, {Disabled: 0b, IsEmptySlot: 1b, Slot: 6, SlotFilterEnabled: 0b, SlotLimit: 64}, {Disabled: 0b, IsEmptySlot: 1b, Slot: 7, SlotFilterEnabled: 0b, SlotLimit: 64}, {Disabled: 0b, IsEmptySlot: 1b, Slot: 8, SlotFilterEnabled: 0b, SlotLimit: 64}], Size: 9}, id: "anvilcraft:chute"}},
        {pos: [2, 0, 2], state: "anvilcraft:simple_chute{enabled:true,facing:east,tall:false,waterlogged:false}", nbt: {Cooldown: 0, Inventory: {Items: [], Size: 1}, id: "anvilcraft:simple_chute"}},
        {pos: [2, 0, 3], state: "anvilcraft:chute{enabled:true,facing:north}", nbt: {Cooldown: 0, Inventory: {FilterEnabled: 0b, Inventory: [{Disabled: 0b, IsEmptySlot: 1b, Slot: 0, SlotFilterEnabled: 0b, SlotLimit: 64}, {Disabled: 0b, IsEmptySlot: 1b, Slot: 1, SlotFilterEnabled: 0b, SlotLimit: 64}, {Disabled: 0b, IsEmptySlot: 1b, Slot: 2, SlotFilterEnabled: 0b, SlotLimit: 64}, {Disabled: 0b, IsEmptySlot: 1b, Slot: 3, SlotFilterEnabled: 0b, SlotLimit: 64}, {Disabled: 0b, IsEmptySlot: 1b, Slot: 4, SlotFilterEnabled: 0b, SlotLimit: 64}, {Disabled: 0b, IsEmptySlot: 1b, Slot: 5, SlotFilterEnabled: 0b, SlotLimit: 64}, {Disabled: 0b, IsEmptySlot: 1b, Slot: 6, SlotFilterEnabled: 0b, SlotLimit: 64}, {Disabled: 0b, IsEmptySlot: 1b, Slot: 7, SlotFilterEnabled: 0b, SlotLimit: 64}, {Disabled: 0b, IsEmptySlot: 1b, Slot: 8, SlotFilterEnabled: 0b, SlotLimit: 64}], Size: 9}, id: "anvilcraft:chute"}},
        {pos: [3, 0, 1], state: "anvilcraft:chute{enabled:true,facing:south}", nbt: {Cooldown: 0, Inventory: {FilterEnabled: 0b, Inventory: [{Disabled: 0b, IsEmptySlot: 1b, Slot: 0, SlotFilterEnabled: 0b, SlotLimit: 64}, {Disabled: 0b, IsEmptySlot: 1b, Slot: 1, SlotFilterEnabled: 0b, SlotLimit: 64}, {Disabled: 0b, IsEmptySlot: 1b, Slot: 2, SlotFilterEnabled: 0b, SlotLimit: 64}, {Disabled: 0b, IsEmptySlot: 1b, Slot: 3, SlotFilterEnabled: 0b, SlotLimit: 64}, {Disabled: 0b, IsEmptySlot: 1b, Slot: 4, SlotFilterEnabled: 0b, SlotLimit: 64}, {Disabled: 0b, IsEmptySlot: 1b, Slot: 5, SlotFilterEnabled: 0b, SlotLimit: 64}, {Disabled: 0b, IsEmptySlot: 1b, Slot: 6, SlotFilterEnabled: 0b, SlotLimit: 64}, {Disabled: 0b, IsEmptySlot: 1b, Slot: 7, SlotFilterEnabled: 0b, SlotLimit: 64}, {Disabled: 0b, IsEmptySlot: 1b, Slot: 8, SlotFilterEnabled: 0b, SlotLimit: 64}], Size: 9}, id: "anvilcraft:chute"}},
        {pos: [3, 0, 2], state: "anvilcraft:simple_chute{enabled:true,facing:east,tall:false,waterlogged:false}", nbt: {Cooldown: 0, Inventory: {Items: [], Size: 1}, id: "anvilcraft:simple_chute"}},
        {pos: [3, 0, 3], state: "anvilcraft:chute{enabled:true,facing:north}", nbt: {Cooldown: 0, Inventory: {FilterEnabled: 0b, Inventory: [{Disabled: 0b, IsEmptySlot: 1b, Slot: 0, SlotFilterEnabled: 0b, SlotLimit: 64}, {Disabled: 0b, IsEmptySlot: 1b, Slot: 1, SlotFilterEnabled: 0b, SlotLimit: 64}, {Disabled: 0b, IsEmptySlot: 1b, Slot: 2, SlotFilterEnabled: 0b, SlotLimit: 64}, {Disabled: 0b, IsEmptySlot: 1b, Slot: 3, SlotFilterEnabled: 0b, SlotLimit: 64}, {Disabled: 0b, IsEmptySlot: 1b, Slot: 4, SlotFilterEnabled: 0b, SlotLimit: 64}, {Disabled: 0b, IsEmptySlot: 1b, Slot: 5, SlotFilterEnabled: 0b, SlotLimit: 64}, {Disabled: 0b, IsEmptySlot: 1b, Slot: 6, SlotFilterEnabled: 0b, SlotLimit: 64}, {Disabled: 0b, IsEmptySlot: 1b, Slot: 7, SlotFilterEnabled: 0b, SlotLimit: 64}, {Disabled: 0b, IsEmptySlot: 1b, Slot: 8, SlotFilterEnabled: 0b, SlotLimit: 64}], Size: 9}, id: "anvilcraft:chute"}},
        {pos: [4, 0, 1], state: "anvilcraft:chute{enabled:true,facing:south}", nbt: {Cooldown: 0, Inventory: {FilterEnabled: 0b, Inventory: [{Disabled: 0b, IsEmptySlot: 1b, Slot: 0, SlotFilterEnabled: 0b, SlotLimit: 64}, {Disabled: 0b, IsEmptySlot: 1b, Slot: 1, SlotFilterEnabled: 0b, SlotLimit: 64}, {Disabled: 0b, IsEmptySlot: 1b, Slot: 2, SlotFilterEnabled: 0b, SlotLimit: 64}, {Disabled: 0b, IsEmptySlot: 1b, Slot: 3, SlotFilterEnabled: 0b, SlotLimit: 64}, {Disabled: 0b, IsEmptySlot: 1b, Slot: 4, SlotFilterEnabled: 0b, SlotLimit: 64}, {Disabled: 0b, IsEmptySlot: 1b, Slot: 5, SlotFilterEnabled: 0b, SlotLimit: 64}, {Disabled: 0b, IsEmptySlot: 1b, Slot: 6, SlotFilterEnabled: 0b, SlotLimit: 64}, {Disabled: 0b, IsEmptySlot: 1b, Slot: 7, SlotFilterEnabled: 0b, SlotLimit: 64}, {Disabled: 0b, IsEmptySlot: 1b, Slot: 8, SlotFilterEnabled: 0b, SlotLimit: 64}], Size: 9}, id: "anvilcraft:chute"}},
        {pos: [4, 0, 2], state: "anvilcraft:simple_chute{enabled:true,facing:east,tall:false,waterlogged:false}", nbt: {Cooldown: 0, Inventory: {Items: [], Size: 1}, id: "anvilcraft:simple_chute"}},
        {pos: [4, 0, 3], state: "anvilcraft:chute{enabled:true,facing:north}", nbt: {Cooldown: 0, Inventory: {FilterEnabled: 0b, Inventory: [{Disabled: 0b, IsEmptySlot: 1b, Slot: 0, SlotFilterEnabled: 0b, SlotLimit: 64}, {Disabled: 0b, IsEmptySlot: 1b, Slot: 1, SlotFilterEnabled: 0b, SlotLimit: 64}, {Disabled: 0b, IsEmptySlot: 1b, Slot: 2, SlotFilterEnabled: 0b, SlotLimit: 64}, {Disabled: 0b, IsEmptySlot: 1b, Slot: 3, SlotFilterEnabled: 0b, SlotLimit: 64}, {Disabled: 0b, IsEmptySlot: 1b, Slot: 4, SlotFilterEnabled: 0b, SlotLimit: 64}, {Disabled: 0b, IsEmptySlot: 1b, Slot: 5, SlotFilterEnabled: 0b, SlotLimit: 64}, {Disabled: 0b, IsEmptySlot: 1b, Slot: 6, SlotFilterEnabled: 0b, SlotLimit: 64}, {Disabled: 0b, IsEmptySlot: 1b, Slot: 7, SlotFilterEnabled: 0b, SlotLimit: 64}, {Disabled: 0b, IsEmptySlot: 1b, Slot: 8, SlotFilterEnabled: 0b, SlotLimit: 64}], Size: 9}, id: "anvilcraft:chute"}},
        {pos: [5, 0, 1], state: "anvilcraft:chute{enabled:true,facing:south}", nbt: {Cooldown: 0, Inventory: {FilterEnabled: 0b, Inventory: [{Disabled: 0b, IsEmptySlot: 1b, Slot: 0, SlotFilterEnabled: 0b, SlotLimit: 64}, {Disabled: 0b, IsEmptySlot: 1b, Slot: 1, SlotFilterEnabled: 0b, SlotLimit: 64}, {Disabled: 0b, IsEmptySlot: 1b, Slot: 2, SlotFilterEnabled: 0b, SlotLimit: 64}, {Disabled: 0b, IsEmptySlot: 1b, Slot: 3, SlotFilterEnabled: 0b, SlotLimit: 64}, {Disabled: 0b, IsEmptySlot: 1b, Slot: 4, SlotFilterEnabled: 0b, SlotLimit: 64}, {Disabled: 0b, IsEmptySlot: 1b, Slot: 5, SlotFilterEnabled: 0b, SlotLimit: 64}, {Disabled: 0b, IsEmptySlot: 1b, Slot: 6, SlotFilterEnabled: 0b, SlotLimit: 64}, {Disabled: 0b, IsEmptySlot: 1b, Slot: 7, SlotFilterEnabled: 0b, SlotLimit: 64}, {Disabled: 0b, IsEmptySlot: 1b, Slot: 8, SlotFilterEnabled: 0b, SlotLimit: 64}], Size: 9}, id: "anvilcraft:chute"}},
        {pos: [5, 0, 2], state: "minecraft:chest{facing:north,type:left,waterlogged:false}", nbt: {Items: [], id: "minecraft:chest"}},
        {pos: [5, 0, 3], state: "anvilcraft:chute{enabled:true,facing:north}", nbt: {Cooldown: 0, Inventory: {FilterEnabled: 0b, Inventory: [{Disabled: 0b, IsEmptySlot: 1b, Slot: 0, SlotFilterEnabled: 0b, SlotLimit: 64}, {Disabled: 0b, IsEmptySlot: 1b, Slot: 1, SlotFilterEnabled: 0b, SlotLimit: 64}, {Disabled: 0b, IsEmptySlot: 1b, Slot: 2, SlotFilterEnabled: 0b, SlotLimit: 64}, {Disabled: 0b, IsEmptySlot: 1b, Slot: 3, SlotFilterEnabled: 0b, SlotLimit: 64}, {Disabled: 0b, IsEmptySlot: 1b, Slot: 4, SlotFilterEnabled: 0b, SlotLimit: 64}, {Disabled: 0b, IsEmptySlot: 1b, Slot: 5, SlotFilterEnabled: 0b, SlotLimit: 64}, {Disabled: 0b, IsEmptySlot: 1b, Slot: 6, SlotFilterEnabled: 0b, SlotLimit: 64}, {Disabled: 0b, IsEmptySlot: 1b, Slot: 7, SlotFilterEnabled: 0b, SlotLimit: 64}, {Disabled: 0b, IsEmptySlot: 1b, Slot: 8, SlotFilterEnabled: 0b, SlotLimit: 64}], Size: 9}, id: "anvilcraft:chute"}},
        {pos: [6, 0, 1], state: "anvilcraft:chute{enabled:true,facing:south}", nbt: {Cooldown: 0, Inventory: {FilterEnabled: 0b, Inventory: [{Disabled: 0b, IsEmptySlot: 1b, Slot: 0, SlotFilterEnabled: 0b, SlotLimit: 64}, {Disabled: 0b, IsEmptySlot: 1b, Slot: 1, SlotFilterEnabled: 0b, SlotLimit: 64}, {Disabled: 0b, IsEmptySlot: 1b, Slot: 2, SlotFilterEnabled: 0b, SlotLimit: 64}, {Disabled: 0b, IsEmptySlot: 1b, Slot: 3, SlotFilterEnabled: 0b, SlotLimit: 64}, {Disabled: 0b, IsEmptySlot: 1b, Slot: 4, SlotFilterEnabled: 0b, SlotLimit: 64}, {Disabled: 0b, IsEmptySlot: 1b, Slot: 5, SlotFilterEnabled: 0b, SlotLimit: 64}, {Disabled: 0b, IsEmptySlot: 1b, Slot: 6, SlotFilterEnabled: 0b, SlotLimit: 64}, {Disabled: 0b, IsEmptySlot: 1b, Slot: 7, SlotFilterEnabled: 0b, SlotLimit: 64}, {Disabled: 0b, IsEmptySlot: 1b, Slot: 8, SlotFilterEnabled: 0b, SlotLimit: 64}], Size: 9}, id: "anvilcraft:chute"}},
        {pos: [6, 0, 2], state: "minecraft:chest{facing:north,type:right,waterlogged:false}", nbt: {Items: [], id: "minecraft:chest"}},
        {pos: [6, 0, 3], state: "anvilcraft:chute{enabled:true,facing:north}", nbt: {Cooldown: 0, Inventory: {FilterEnabled: 0b, Inventory: [{Disabled: 0b, IsEmptySlot: 1b, Slot: 0, SlotFilterEnabled: 0b, SlotLimit: 64}, {Disabled: 0b, IsEmptySlot: 1b, Slot: 1, SlotFilterEnabled: 0b, SlotLimit: 64}, {Disabled: 0b, IsEmptySlot: 1b, Slot: 2, SlotFilterEnabled: 0b, SlotLimit: 64}, {Disabled: 0b, IsEmptySlot: 1b, Slot: 3, SlotFilterEnabled: 0b, SlotLimit: 64}, {Disabled: 0b, IsEmptySlot: 1b, Slot: 4, SlotFilterEnabled: 0b, SlotLimit: 64}, {Disabled: 0b, IsEmptySlot: 1b, Slot: 5, SlotFilterEnabled: 0b, SlotLimit: 64}, {Disabled: 0b, IsEmptySlot: 1b, Slot: 6, SlotFilterEnabled: 0b, SlotLimit: 64}, {Disabled: 0b, IsEmptySlot: 1b, Slot: 7, SlotFilterEnabled: 0b, SlotLimit: 64}, {Disabled: 0b, IsEmptySlot: 1b, Slot: 8, SlotFilterEnabled: 0b, SlotLimit: 64}], Size: 9}, id: "anvilcraft:chute"}},
        {pos: [2, 1, 1], state: "minecraft:stonecutter{facing:south}"},
        {pos: [2, 1, 2], state: "minecraft:smooth_stone_slab{type:top,waterlogged:false}"},
        {pos: [2, 1, 3], state: "minecraft:stonecutter{facing:south}"},
        {pos: [3, 1, 1], state: "minecraft:stonecutter{facing:south}"},
        {pos: [3, 1, 2], state: "minecraft:smooth_stone_slab{type:top,waterlogged:false}"},
        {pos: [3, 1, 3], state: "minecraft:stonecutter{facing:south}"},
        {pos: [4, 1, 1], state: "minecraft:stonecutter{facing:south}"},
        {pos: [4, 1, 2], state: "minecraft:smooth_stone_slab{type:top,waterlogged:false}"},
        {pos: [4, 1, 3], state: "minecraft:stonecutter{facing:south}"},
        {pos: [5, 1, 1], state: "minecraft:stonecutter{facing:south}"},
        {pos: [5, 1, 2], state: "minecraft:smooth_stone_slab{type:top,waterlogged:false}"},
        {pos: [5, 1, 3], state: "minecraft:stonecutter{facing:south}"},
        {pos: [6, 1, 1], state: "minecraft:stonecutter{facing:south}"},
        {pos: [6, 1, 2], state: "minecraft:smooth_stone_slab{type:top,waterlogged:false}"},
        {pos: [6, 1, 3], state: "minecraft:stonecutter{facing:south}"},
        {pos: [1, 2, 2], state: "minecraft:smooth_stone_slab{type:bottom,waterlogged:false}"},
        {pos: [2, 2, 0], state: "minecraft:oak_leaves{distance:7,persistent:true,waterlogged:true}"},
        {pos: [2, 2, 1], state: "minecraft:cobblestone"},
        {pos: [2, 2, 2], state: "minecraft:lava{level:4}"},
        {pos: [2, 2, 3], state: "minecraft:cobblestone"},
        {pos: [2, 2, 4], state: "minecraft:oak_leaves{distance:7,persistent:true,waterlogged:true}"},
        {pos: [3, 2, 0], state: "minecraft:oak_leaves{distance:7,persistent:true,waterlogged:true}"},
        {pos: [3, 2, 1], state: "minecraft:cobblestone"},
        {pos: [3, 2, 2], state: "minecraft:lava{level:2}"},
        {pos: [3, 2, 3], state: "minecraft:cobblestone"},
        {pos: [3, 2, 4], state: "minecraft:oak_leaves{distance:7,persistent:true,waterlogged:true}"},
        {pos: [4, 2, 0], state: "minecraft:oak_leaves{distance:7,persistent:true,waterlogged:true}"},
        {pos: [4, 2, 1], state: "minecraft:cobblestone"},
        {pos: [4, 2, 2], state: "minecraft:lava{level:0}"},
        {pos: [4, 2, 3], state: "minecraft:cobblestone"},
        {pos: [4, 2, 4], state: "minecraft:oak_leaves{distance:7,persistent:true,waterlogged:true}"},
        {pos: [5, 2, 0], state: "minecraft:oak_leaves{distance:7,persistent:true,waterlogged:true}"},
        {pos: [5, 2, 1], state: "minecraft:cobblestone"},
        {pos: [5, 2, 2], state: "minecraft:lava{level:2}"},
        {pos: [5, 2, 3], state: "minecraft:cobblestone"},
        {pos: [5, 2, 4], state: "minecraft:oak_leaves{distance:7,persistent:true,waterlogged:true}"},
        {pos: [6, 2, 0], state: "minecraft:oak_leaves{distance:7,persistent:true,waterlogged:true}"},
        {pos: [6, 2, 1], state: "minecraft:cobblestone"},
        {pos: [6, 2, 2], state: "minecraft:lava{level:4}"},
        {pos: [6, 2, 3], state: "minecraft:cobblestone"},
        {pos: [6, 2, 4], state: "minecraft:oak_leaves{distance:7,persistent:true,waterlogged:true}"},
        {pos: [7, 2, 2], state: "minecraft:smooth_stone_slab{type:bottom,waterlogged:false}"},
        {pos: [2, 4, 1], state: "minecraft:anvil{facing:east}"},
        {pos: [2, 4, 3], state: "minecraft:anvil{facing:east}"},
        {pos: [3, 4, 1], state: "minecraft:anvil{facing:east}"},
        {pos: [3, 4, 3], state: "minecraft:anvil{facing:east}"},
        {pos: [4, 4, 1], state: "minecraft:anvil{facing:east}"},
        {pos: [4, 4, 3], state: "minecraft:anvil{facing:east}"},
        {pos: [5, 4, 1], state: "minecraft:anvil{facing:east}"},
        {pos: [5, 4, 3], state: "minecraft:anvil{facing:east}"},
        {pos: [6, 4, 1], state: "minecraft:anvil{facing:east}"},
        {pos: [6, 4, 3], state: "minecraft:anvil{facing:east}"},
        {pos: [0, 5, 1], state: "minecraft:lever{face:ceiling,facing:north,powered:true}"},
        {pos: [0, 5, 2], state: "minecraft:smooth_stone"},
        {pos: [0, 5, 3], state: "minecraft:smooth_stone"},
        {pos: [1, 5, 1], state: "minecraft:smooth_stone"},
        {pos: [1, 5, 2], state: "minecraft:smooth_stone"},
        {pos: [1, 5, 3], state: "minecraft:smooth_stone"},
        {pos: [2, 5, 1], state: "anvilcraft:hollow_magnet_block{lit:false,waterlogged:false}"},
        {pos: [2, 5, 2], state: "minecraft:smooth_stone"},
        {pos: [2, 5, 3], state: "anvilcraft:hollow_magnet_block{lit:false,waterlogged:false}"},
        {pos: [3, 5, 1], state: "anvilcraft:hollow_magnet_block{lit:false,waterlogged:false}"},
        {pos: [3, 5, 2], state: "minecraft:smooth_stone"},
        {pos: [3, 5, 3], state: "anvilcraft:hollow_magnet_block{lit:false,waterlogged:false}"},
        {pos: [4, 5, 1], state: "anvilcraft:hollow_magnet_block{lit:false,waterlogged:false}"},
        {pos: [4, 5, 2], state: "minecraft:smooth_stone"},
        {pos: [4, 5, 3], state: "anvilcraft:hollow_magnet_block{lit:false,waterlogged:false}"},
        {pos: [5, 5, 1], state: "anvilcraft:hollow_magnet_block{lit:false,waterlogged:false}"},
        {pos: [5, 5, 2], state: "minecraft:smooth_stone"},
        {pos: [5, 5, 3], state: "anvilcraft:hollow_magnet_block{lit:false,waterlogged:false}"},
        {pos: [6, 5, 1], state: "anvilcraft:hollow_magnet_block{lit:false,waterlogged:false}"},
        {pos: [6, 5, 2], state: "minecraft:smooth_stone"},
        {pos: [6, 5, 3], state: "anvilcraft:hollow_magnet_block{lit:false,waterlogged:false}"},
        {pos: [0, 6, 1], state: "minecraft:smooth_stone"},
        {pos: [0, 6, 2], state: "minecraft:repeater{delay:2,facing:south,locked:false,powered:false}"},
        {pos: [0, 6, 3], state: "minecraft:redstone_wire{east:side,north:side,power:0,south:none,west:none}"},
        {pos: [1, 6, 1], state: "minecraft:redstone_wall_torch{facing:east,lit:false}"},
        {pos: [1, 6, 2], state: "minecraft:redstone_wire{east:side,north:side,power:0,south:side,west:none}"},
        {pos: [1, 6, 3], state: "minecraft:redstone_wire{east:none,north:side,power:0,south:none,west:side}"},
        {pos: [2, 6, 2], state: "minecraft:redstone_wire{east:side,north:none,power:0,south:none,west:side}"},
        {pos: [3, 6, 2], state: "minecraft:redstone_wire{east:side,north:none,power:0,south:none,west:side}"},
        {pos: [4, 6, 2], state: "minecraft:redstone_wire{east:side,north:none,power:0,south:none,west:side}"},
        {pos: [5, 6, 2], state: "minecraft:redstone_wire{east:side,north:none,power:0,south:none,west:side}"},
        {pos: [6, 6, 2], state: "minecraft:redstone_wire{east:side,north:none,power:0,south:none,west:side}"}
    ],
    entities: [],
    palette: [
        "minecraft:oak_leaves{distance:7,persistent:true,waterlogged:true}",
        "minecraft:cobblestone",
        "minecraft:smooth_stone",
        "minecraft:stonecutter{facing:south}",
        "minecraft:smooth_stone_slab{type:top,waterlogged:false}",
        "minecraft:smooth_stone_slab{type:bottom,waterlogged:false}",
        "minecraft:lava{level:4}",
        "minecraft:lava{level:2}",
        "minecraft:lava{level:0}",
        "minecraft:anvil{facing:east}",
        "minecraft:lever{face:ceiling,facing:north,powered:true}",
        "anvilcraft:hollow_magnet_block{lit:false,waterlogged:false}",
        "minecraft:repeater{delay:2,facing:south,locked:false,powered:false}",
        "minecraft:redstone_wire{east:side,north:side,power:0,south:none,west:none}",
        "minecraft:redstone_wall_torch{facing:east,lit:false}",
        "minecraft:redstone_wire{east:side,north:side,power:0,south:side,west:none}",
        "minecraft:redstone_wire{east:none,north:side,power:0,south:none,west:side}",
        "minecraft:redstone_wire{east:side,north:none,power:0,south:none,west:side}",
        "anvilcraft:chute{enabled:true,facing:south}",
        "anvilcraft:simple_chute{enabled:true,facing:east,tall:false,waterlogged:false}",
        "anvilcraft:chute{enabled:true,facing:north}",
        "minecraft:chest{facing:north,type:left,waterlogged:false}",
        "minecraft:chest{facing:north,type:right,waterlogged:false}"
    ]
}