{
    DataVersion: 3955,
    size: [7, 11, 7],
    data: [
        {pos: [0, 0, 0], state: "minecraft:podzol{snowy:false}"},
        {pos: [0, 0, 1], state: "minecraft:podzol{snowy:false}"},
        {pos: [1, 0, 0], state: "minecraft:podzol{snowy:false}"},
        {pos: [1, 0, 1], state: "minecraft:podzol{snowy:false}"},
        {pos: [1, 0, 2], state: "minecraft:smooth_stone"},
        {pos: [1, 0, 3], state: "minecraft:smooth_stone"},
        {pos: [2, 0, 0], state: "anvilcraft:induction_light{axis:y,color:pink,overload:false,powered:false,waterlogged:false}", nbt: {id: "anvilcraft:induction_light"}},
        {pos: [2, 0, 1], state: "minecraft:smooth_stone"},
        {pos: [2, 0, 2], state: "minecraft:smooth_stone"},
        {pos: [4, 0, 3], state: "anvilcraft:chute{enabled:true,facing:east}", nbt: {Cooldown: 0, Inventory: {FilterEnabled: 1b, Inventory: [{Disabled: 0b, IsEmptySlot: 1b, Slot: 0, SlotFilterEnabled: 1b, SlotFilterItem: {count: 1, id: "minecraft:spruce_log"}, SlotLimit: 64}, {Disabled: 0b, IsEmptySlot: 1b, Slot: 1, SlotFilterEnabled: 1b, SlotFilterItem: {count: 1, id: "minecraft:spruce_log"}, SlotLimit: 64}, {Disabled: 0b, IsEmptySlot: 1b, Slot: 2, SlotFilterEnabled: 1b, SlotFilterItem: {count: 1, id: "minecraft:spruce_log"}, SlotLimit: 64}, {Disabled: 0b, IsEmptySlot: 1b, Slot: 3, SlotFilterEnabled: 1b, SlotFilterItem: {count: 1, id: "minecraft:spruce_log"}, SlotLimit: 64}, {Disabled: 0b, IsEmptySlot: 1b, Slot: 4, SlotFilterEnabled: 1b, SlotFilterItem: {count: 1, id: "minecraft:spruce_log"}, SlotLimit: 64}, {Disabled: 0b, IsEmptySlot: 1b, Slot: 5, SlotFilterEnabled: 1b, SlotFilterItem: {count: 1, id: "minecraft:spruce_log"}, SlotLimit: 64}, {Disabled: 0b, IsEmptySlot: 1b, Slot: 6, SlotFilterEnabled: 1b, SlotFilterItem: {count: 1, id: "minecraft:spruce_log"}, SlotLimit: 64}, {Disabled: 0b, IsEmptySlot: 1b, Slot: 7, SlotFilterEnabled: 1b, SlotFilterItem: {count: 1, id: "minecraft:spruce_log"}, SlotLimit: 64}, {Disabled: 0b, IsEmptySlot: 1b, Slot: 8, SlotFilterEnabled: 1b, SlotFilterItem: {count: 1, id: "minecraft:stick"}, SlotLimit: 64}], Size: 9}, id: "anvilcraft:chute"}},
        {pos: [4, 0, 4], state: "minecraft:spruce_log{axis:y}"},
        {pos: [4, 0, 5], state: "minecraft:anvil{facing:east}"},
        {pos: [4, 0, 6], state: "minecraft:spruce_log{axis:y}"},
        {pos: [5, 0, 0], state: "minecraft:chest{facing:east,type:left,waterlogged:false}", nbt: {Items: [], id: "minecraft:chest"}},
        {pos: [5, 0, 1], state: "minecraft:chest{facing:east,type:right,waterlogged:false}", nbt: {Items: [{Slot: 0b, count: 64, id: "minecraft:spruce_log"}, {Slot: 1b, count: 20, id: "minecraft:stick"}, {Slot: 2b, count: 64, id: "minecraft:spruce_log"}, {Slot: 3b, count: 64, id: "minecraft:spruce_log"}, {Slot: 4b, count: 64, id: "minecraft:spruce_log"}, {Slot: 5b, count: 64, id: "minecraft:spruce_log"}, {Slot: 6b, count: 60, id: "minecraft:spruce_log"}], id: "minecraft:chest"}},
        {pos: [5, 0, 2], state: "anvilcraft:magnetic_chute{enabled:true,facing:north}", nbt: {Cooldown: 0, Inventory: {FilterEnabled: 0b, Inventory: [{Disabled: 0b, IsEmptySlot: 1b, Slot: 0, SlotFilterEnabled: 0b, SlotLimit: 64}, {Disabled: 0b, IsEmptySlot: 1b, Slot: 1, SlotFilterEnabled: 0b, SlotLimit: 64}, {Disabled: 0b, IsEmptySlot: 1b, Slot: 2, SlotFilterEnabled: 0b, SlotLimit: 64}, {Disabled: 0b, IsEmptySlot: 1b, Slot: 3, SlotFilterEnabled: 0b, SlotLimit: 64}, {Disabled: 0b, IsEmptySlot: 1b, Slot: 4, SlotFilterEnabled: 0b, SlotLimit: 64}, {Disabled: 0b, IsEmptySlot: 1b, Slot: 5, SlotFilterEnabled: 0b, SlotLimit: 64}, {Disabled: 0b, IsEmptySlot: 1b, Slot: 6, SlotFilterEnabled: 0b, SlotLimit: 64}, {Disabled: 0b, IsEmptySlot: 1b, Slot: 7, SlotFilterEnabled: 0b, SlotLimit: 64}, {Disabled: 0b, IsEmptySlot: 1b, Slot: 8, SlotFilterEnabled: 0b, SlotLimit: 64}], Size: 9}, id: "anvilcraft:magnetic_chute"}},
        {pos: [5, 0, 3], state: "anvilcraft:simple_chute{enabled:true,facing:east,tall:false,waterlogged:false}", nbt: {Cooldown: 0, Inventory: {Items: [], Size: 1}, id: "anvilcraft:simple_chute"}},
        {pos: [5, 0, 4], state: "minecraft:anvil{facing:north}"},
        {pos: [5, 0, 5], state: "anvilcraft:heavy_iron_block"},
        {pos: [5, 0, 6], state: "minecraft:anvil{facing:north}"},
        {pos: [6, 0, 3], state: "minecraft:lava_cauldron"},
        {pos: [6, 0, 4], state: "minecraft:spruce_log{axis:y}"},
        {pos: [6, 0, 5], state: "minecraft:anvil{facing:west}"},
        {pos: [6, 0, 6], state: "minecraft:spruce_log{axis:y}"},
        {pos: [0, 1, 0], state: "minecraft:spruce_sapling{stage:0}"},
        {pos: [0, 1, 1], state: "minecraft:spruce_sapling{stage:0}"},
        {pos: [1, 1, 0], state: "minecraft:spruce_sapling{stage:0}"},
        {pos: [1, 1, 1], state: "minecraft:spruce_sapling{stage:0}"},
        {pos: [1, 1, 2], state: "minecraft:repeater{delay:1,facing:south,locked:false,powered:true}"},
        {pos: [1, 1, 3], state: "minecraft:lever{face:floor,facing:north,powered:true}"},
        {pos: [2, 1, 1], state: "minecraft:redstone_wire{east:none,north:side,power:0,south:side,west:none}"},
        {pos: [2, 1, 2], state: "minecraft:redstone_wire{east:none,north:side,power:0,south:up,west:none}"},
        {pos: [2, 1, 3], state: "minecraft:smooth_stone"},
        {pos: [3, 1, 0], state: "anvilcraft:block_placer{orientation:west_up,triggered:false}"},
        {pos: [3, 1, 1], state: "anvilcraft:block_placer{orientation:west_up,triggered:false}"},
        {pos: [4, 1, 0], state: "anvilcraft:block_placer{orientation:west_up,triggered:false}"},
        {pos: [4, 1, 1], state: "anvilcraft:block_placer{orientation:west_up,triggered:false}"},
        {pos: [4, 1, 3], state: "anvilcraft:item_collector{overload:false,powered:false}", nbt: {Cooldown: 2, Inventory: {FilterEnabled: 0b, Inventory: [{Disabled: 0b, IsEmptySlot: 1b, Slot: 0, SlotFilterEnabled: 0b, SlotLimit: 64}, {Disabled: 0b, IsEmptySlot: 1b, Slot: 1, SlotFilterEnabled: 0b, SlotLimit: 64}, {Disabled: 0b, IsEmptySlot: 1b, Slot: 2, SlotFilterEnabled: 0b, SlotLimit: 64}, {Disabled: 0b, IsEmptySlot: 1b, Slot: 3, SlotFilterEnabled: 0b, SlotLimit: 64}, {Disabled: 0b, IsEmptySlot: 1b, Slot: 4, SlotFilterEnabled: 0b, SlotLimit: 64}, {Disabled: 0b, IsEmptySlot: 1b, Slot: 5, SlotFilterEnabled: 0b, SlotLimit: 64}, {Disabled: 0b, IsEmptySlot: 1b, Slot: 6, SlotFilterEnabled: 0b, SlotLimit: 64}, {Disabled: 0b, IsEmptySlot: 1b, Slot: 7, SlotFilterEnabled: 0b, SlotLimit: 64}, {Disabled: 0b, IsEmptySlot: 1b, Slot: 8, SlotFilterEnabled: 0b, SlotLimit: 64}], Size: 9}, RangeRadius: 3, cd: 2, id: "anvilcraft:item_collector"}},
        {pos: [5, 1, 0], state: "minecraft:chest{facing:east,type:left,waterlogged:false}", nbt: {Items: [], id: "minecraft:chest"}},
        {pos: [5, 1, 1], state: "minecraft:chest{facing:east,type:right,waterlogged:false}", nbt: {Items: [{Slot: 0b, count: 64, id: "minecraft:spruce_sapling"}, {Slot: 1b, count: 33, id: "minecraft:spruce_sapling"}], id: "minecraft:chest"}},
        {pos: [5, 1, 2], state: "anvilcraft:magnetic_chute{enabled:true,facing:north}", nbt: {Cooldown: 0, Inventory: {FilterEnabled: 0b, Inventory: [{Disabled: 0b, IsEmptySlot: 1b, Slot: 0, SlotFilterEnabled: 0b, SlotLimit: 64}, {Disabled: 0b, IsEmptySlot: 1b, Slot: 1, SlotFilterEnabled: 0b, SlotLimit: 64}, {Disabled: 0b, IsEmptySlot: 1b, Slot: 2, SlotFilterEnabled: 0b, SlotLimit: 64}, {Disabled: 0b, IsEmptySlot: 1b, Slot: 3, SlotFilterEnabled: 0b, SlotLimit: 64}, {Disabled: 0b, IsEmptySlot: 1b, Slot: 4, SlotFilterEnabled: 0b, SlotLimit: 64}, {Disabled: 0b, IsEmptySlot: 1b, Slot: 5, SlotFilterEnabled: 0b, SlotLimit: 64}, {Disabled: 0b, IsEmptySlot: 1b, Slot: 6, SlotFilterEnabled: 0b, SlotLimit: 64}, {Disabled: 0b, IsEmptySlot: 1b, Slot: 7, SlotFilterEnabled: 0b, SlotLimit: 64}, {Disabled: 0b, IsEmptySlot: 1b, Slot: 8, SlotFilterEnabled: 0b, SlotLimit: 64}], Size: 9}, id: "anvilcraft:magnetic_chute"}},
        {pos: [5, 1, 3], state: "anvilcraft:magnetic_chute{enabled:true,facing:east}", nbt: {Cooldown: 0, Inventory: {FilterEnabled: 1b, Inventory: [{Disabled: 0b, IsEmptySlot: 1b, Slot: 0, SlotFilterEnabled: 1b, SlotFilterItem: {count: 1, id: "minecraft:spruce_sapling"}, SlotLimit: 64}, {Disabled: 0b, IsEmptySlot: 1b, Slot: 1, SlotFilterEnabled: 1b, SlotFilterItem: {count: 1, id: "minecraft:spruce_sapling"}, SlotLimit: 64}, {Disabled: 0b, IsEmptySlot: 1b, Slot: 2, SlotFilterEnabled: 0b, SlotLimit: 64}, {Disabled: 0b, IsEmptySlot: 1b, Slot: 3, SlotFilterEnabled: 0b, SlotLimit: 64}, {Disabled: 0b, IsEmptySlot: 1b, Slot: 4, SlotFilterEnabled: 0b, SlotLimit: 64}, {Disabled: 0b, IsEmptySlot: 1b, Slot: 5, SlotFilterEnabled: 0b, SlotLimit: 64}, {Disabled: 0b, IsEmptySlot: 1b, Slot: 6, SlotFilterEnabled: 0b, SlotLimit: 64}, {Disabled: 0b, IsEmptySlot: 1b, Slot: 7, SlotFilterEnabled: 0b, SlotLimit: 64}, {Disabled: 0b, IsEmptySlot: 1b, Slot: 8, SlotFilterEnabled: 0b, SlotLimit: 64}], Size: 9}, id: "anvilcraft:magnetic_chute"}},
        {pos: [6, 1, 3], state: "anvilcraft:simple_chute{enabled:true,facing:down,tall:false,waterlogged:false}", nbt: {Cooldown: 0, Inventory: {Items: [], Size: 1}, id: "anvilcraft:simple_chute"}},
        {pos: [2, 2, 3], state: "minecraft:redstone_wire{east:up,north:side,power:0,south:none,west:none}"},
        {pos: [3, 2, 0], state: "anvilcraft:spectral_anvil{facing:north,powered:false}"},
        {pos: [3, 2, 1], state: "anvilcraft:spectral_anvil{facing:north,powered:false}"},
        {pos: [3, 2, 3], state: "minecraft:smooth_stone"},
        {pos: [4, 2, 0], state: "anvilcraft:spectral_anvil{facing:north,powered:false}"},
        {pos: [4, 2, 1], state: "anvilcraft:spectral_anvil{facing:north,powered:false}"},
        {pos: [3, 3, 0], state: "anvilcraft:magnet_block{lit:true}"},
        {pos: [3, 3, 1], state: "anvilcraft:magnet_block{lit:true}"},
        {pos: [3, 3, 3], state: "minecraft:redstone_wire{east:side,north:none,power:0,south:none,west:side}"},
        {pos: [4, 3, 0], state: "anvilcraft:magnet_block{lit:true}"},
        {pos: [4, 3, 1], state: "anvilcraft:magnet_block{lit:true}"},
        {pos: [4, 3, 2], state: "minecraft:smooth_stone"},
        {pos: [4, 3, 3], state: "minecraft:smooth_stone"},
        {pos: [4, 4, 0], state: "minecraft:redstone_wire{east:none,north:side,power:13,south:side,west:none}"},
        {pos: [4, 4, 1], state: "minecraft:redstone_wire{east:none,north:side,power:14,south:side,west:none}"},
        {pos: [4, 4, 2], state: "minecraft:redstone_wire{east:none,north:side,power:15,south:side,west:none}"},
        {pos: [4, 4, 3], state: "minecraft:redstone_torch{lit:true}"},
        {pos: [4, 5, 3], state: "minecraft:smooth_stone"},
        {pos: [4, 5, 4], state: "anvilcraft:giant_anvil{cube:corner,half:bottom_wn}"},
        {pos: [4, 5, 5], state: "anvilcraft:giant_anvil{cube:corner,half:bottom_w}"},
        {pos: [4, 5, 6], state: "anvilcraft:giant_anvil{cube:corner,half:bottom_ws}"},
        {pos: [5, 5, 4], state: "anvilcraft:giant_anvil{cube:corner,half:bottom_n}"},
        {pos: [5, 5, 5], state: "anvilcraft:giant_anvil{cube:corner,half:bottom_center}"},
        {pos: [5, 5, 6], state: "anvilcraft:giant_anvil{cube:corner,half:bottom_s}"},
        {pos: [6, 5, 4], state: "anvilcraft:giant_anvil{cube:corner,half:bottom_en}"},
        {pos: [6, 5, 5], state: "anvilcraft:giant_anvil{cube:corner,half:bottom_e}"},
        {pos: [6, 5, 6], state: "anvilcraft:giant_anvil{cube:corner,half:bottom_es}"},
        {pos: [4, 6, 3], state: "minecraft:redstone_torch{lit:false}"},
        {pos: [4, 6, 4], state: "anvilcraft:giant_anvil{cube:corner,half:mid_wn}"},
        {pos: [4, 6, 5], state: "anvilcraft:giant_anvil{cube:corner,half:mid_w}"},
        {pos: [4, 6, 6], state: "anvilcraft:giant_anvil{cube:corner,half:mid_ws}"},
        {pos: [5, 6, 4], state: "anvilcraft:giant_anvil{cube:corner,half:mid_n}"},
        {pos: [5, 6, 5], state: "anvilcraft:giant_anvil{cube:center,half:mid_center}"},
        {pos: [5, 6, 6], state: "anvilcraft:giant_anvil{cube:corner,half:mid_s}"},
        {pos: [6, 6, 4], state: "anvilcraft:giant_anvil{cube:corner,half:mid_en}"},
        {pos: [6, 6, 5], state: "anvilcraft:giant_anvil{cube:corner,half:mid_e}"},
        {pos: [6, 6, 6], state: "anvilcraft:giant_anvil{cube:corner,half:mid_es}"},
        {pos: [4, 7, 3], state: "minecraft:smooth_stone"},
        {pos: [4, 7, 4], state: "anvilcraft:giant_anvil{cube:corner,half:top_wn}"},
        {pos: [4, 7, 5], state: "anvilcraft:giant_anvil{cube:corner,half:top_w}"},
        {pos: [4, 7, 6], state: "anvilcraft:giant_anvil{cube:corner,half:top_ws}"},
        {pos: [5, 7, 4], state: "anvilcraft:giant_anvil{cube:corner,half:top_n}"},
        {pos: [5, 7, 5], state: "anvilcraft:giant_anvil{cube:corner,half:top_center}"},
        {pos: [5, 7, 6], state: "anvilcraft:giant_anvil{cube:corner,half:top_s}"},
        {pos: [6, 7, 4], state: "anvilcraft:giant_anvil{cube:corner,half:top_en}"},
        {pos: [6, 7, 5], state: "anvilcraft:giant_anvil{cube:corner,half:top_e}"},
        {pos: [6, 7, 6], state: "anvilcraft:giant_anvil{cube:corner,half:top_es}"},
        {pos: [4, 8, 3], state: "minecraft:redstone_wire{east:side,north:side,power:0,south:side,west:side}"},
        {pos: [4, 8, 4], state: "anvilcraft:deflection_ring{facing:up,half:bottom_wn,overload:false,switch:on}", nbt: {id: "anvilcraft:deflection_ring", lastEntitySpeed: 0.0d}},
        {pos: [4, 8, 5], state: "anvilcraft:deflection_ring{facing:up,half:bottom_w,overload:false,switch:on}", nbt: {id: "anvilcraft:deflection_ring", lastEntitySpeed: 0.0d}},
        {pos: [4, 8, 6], state: "anvilcraft:deflection_ring{facing:up,half:bottom_ws,overload:false,switch:on}", nbt: {id: "anvilcraft:deflection_ring", lastEntitySpeed: 0.0d}},
        {pos: [5, 8, 4], state: "anvilcraft:deflection_ring{facing:up,half:bottom_n,overload:false,switch:on}", nbt: {id: "anvilcraft:deflection_ring", lastEntitySpeed: 0.0d}},
        {pos: [5, 8, 5], state: "anvilcraft:deflection_ring{facing:up,half:bottom_center,overload:false,switch:on}", nbt: {id: "anvilcraft:deflection_ring", lastEntitySpeed: 0.0d}},
        {pos: [5, 8, 6], state: "anvilcraft:deflection_ring{facing:up,half:bottom_s,overload:false,switch:on}", nbt: {id: "anvilcraft:deflection_ring", lastEntitySpeed: 0.0d}},
        {pos: [6, 8, 4], state: "anvilcraft:deflection_ring{facing:up,half:bottom_en,overload:false,switch:on}", nbt: {id: "anvilcraft:deflection_ring", lastEntitySpeed: 0.0d}},
        {pos: [6, 8, 5], state: "anvilcraft:deflection_ring{facing:up,half:bottom_e,overload:false,switch:on}", nbt: {id: "anvilcraft:deflection_ring", lastEntitySpeed: 0.0d}},
        {pos: [6, 8, 6], state: "anvilcraft:deflection_ring{facing:up,half:bottom_es,overload:false,switch:on}", nbt: {id: "anvilcraft:deflection_ring", lastEntitySpeed: 0.0d}},
        {pos: [4, 9, 4], state: "anvilcraft:deflection_ring{facing:up,half:mid_wn,overload:false,switch:on}", nbt: {id: "anvilcraft:deflection_ring", lastEntitySpeed: 0.0d}},
        {pos: [4, 9, 5], state: "anvilcraft:deflection_ring{facing:up,half:mid_w,overload:false,switch:on}", nbt: {id: "anvilcraft:deflection_ring", lastEntitySpeed: 0.0d}},
        {pos: [4, 9, 6], state: "anvilcraft:deflection_ring{facing:up,half:mid_ws,overload:false,switch:on}", nbt: {id: "anvilcraft:deflection_ring", lastEntitySpeed: 0.0d}},
        {pos: [5, 9, 4], state: "anvilcraft:deflection_ring{facing:up,half:mid_n,overload:false,switch:on}", nbt: {id: "anvilcraft:deflection_ring", lastEntitySpeed: 0.0d}},
        {pos: [5, 9, 5], state: "anvilcraft:deflection_ring{facing:up,half:mid_center,overload:false,switch:on}", nbt: {id: "anvilcraft:deflection_ring", lastEntitySpeed: 0.0d}},
        {pos: [5, 9, 6], state: "anvilcraft:deflection_ring{facing:up,half:mid_s,overload:false,switch:on}", nbt: {id: "anvilcraft:deflection_ring", lastEntitySpeed: 0.0d}},
        {pos: [6, 9, 4], state: "anvilcraft:deflection_ring{facing:up,half:mid_en,overload:false,switch:on}", nbt: {id: "anvilcraft:deflection_ring", lastEntitySpeed: 0.0d}},
        {pos: [6, 9, 5], state: "anvilcraft:deflection_ring{facing:up,half:mid_e,overload:false,switch:on}", nbt: {id: "anvilcraft:deflection_ring", lastEntitySpeed: 0.0d}},
        {pos: [6, 9, 6], state: "anvilcraft:deflection_ring{facing:up,half:mid_es,overload:false,switch:on}", nbt: {id: "anvilcraft:deflection_ring", lastEntitySpeed: 0.0d}},
        {pos: [4, 10, 4], state: "anvilcraft:deflection_ring{facing:up,half:top_wn,overload:false,switch:on}", nbt: {id: "anvilcraft:deflection_ring", lastEntitySpeed: 0.0d}},
        {pos: [4, 10, 5], state: "anvilcraft:deflection_ring{facing:up,half:top_w,overload:false,switch:on}", nbt: {id: "anvilcraft:deflection_ring", lastEntitySpeed: 0.0d}},
        {pos: [4, 10, 6], state: "anvilcraft:deflection_ring{facing:up,half:top_ws,overload:false,switch:on}", nbt: {id: "anvilcraft:deflection_ring", lastEntitySpeed: 0.0d}},
        {pos: [5, 10, 4], state: "anvilcraft:deflection_ring{facing:up,half:top_n,overload:false,switch:on}", nbt: {id: "anvilcraft:deflection_ring", lastEntitySpeed: 0.0d}},
        {pos: [5, 10, 5], state: "anvilcraft:deflection_ring{facing:up,half:top_center,overload:false,switch:on}", nbt: {id: "anvilcraft:deflection_ring", lastEntitySpeed: 0.0d}},
        {pos: [5, 10, 6], state: "anvilcraft:deflection_ring{facing:up,half:top_s,overload:false,switch:on}", nbt: {id: "anvilcraft:deflection_ring", lastEntitySpeed: 0.0d}},
        {pos: [6, 10, 4], state: "anvilcraft:deflection_ring{facing:up,half:top_en,overload:false,switch:on}", nbt: {id: "anvilcraft:deflection_ring", lastEntitySpeed: 0.0d}},
        {pos: [6, 10, 5], state: "anvilcraft:deflection_ring{facing:up,half:top_e,overload:false,switch:on}", nbt: {id: "anvilcraft:deflection_ring", lastEntitySpeed: 0.0d}},
        {pos: [6, 10, 6], state: "anvilcraft:deflection_ring{facing:up,half:top_es,overload:false,switch:on}", nbt: {id: "anvilcraft:deflection_ring", lastEntitySpeed: 0.0d}}
    ],
    entities: [],
    palette: [
        "minecraft:podzol{snowy:false}",
        "minecraft:smooth_stone",
        "minecraft:spruce_log{axis:y}",
        "anvilcraft:heavy_iron_block",
        "anvilcraft:magnet_block{lit:true}",
        "minecraft:anvil{facing:east}",
        "minecraft:anvil{facing:north}",
        "minecraft:lava_cauldron",
        "minecraft:anvil{facing:west}",
        "minecraft:spruce_sapling{stage:0}",
        "minecraft:repeater{delay:1,facing:south,locked:false,powered:true}",
        "minecraft:lever{face:floor,facing:north,powered:true}",
        "minecraft:redstone_wire{east:none,north:side,power:0,south:side,west:none}",
        "minecraft:redstone_wire{east:none,north:side,power:0,south:up,west:none}",
        "anvilcraft:block_placer{orientation:west_up,triggered:false}",
        "minecraft:redstone_wire{east:up,north:side,power:0,south:none,west:none}",
        "anvilcraft:spectral_anvil{facing:north,powered:false}",
        "minecraft:redstone_wire{east:side,north:none,power:0,south:none,west:side}",
        "minecraft:redstone_wire{east:none,north:side,power:13,south:side,west:none}",
        "minecraft:redstone_wire{east:none,north:side,power:14,south:side,west:none}",
        "minecraft:redstone_wire{east:none,north:side,power:15,south:side,west:none}",
        "minecraft:redstone_torch{lit:true}",
        "anvilcraft:giant_anvil{cube:corner,half:bottom_wn}",
        "anvilcraft:giant_anvil{cube:corner,half:bottom_w}",
        "anvilcraft:giant_anvil{cube:corner,half:bottom_ws}",
        "anvilcraft:giant_anvil{cube:corner,half:bottom_n}",
        "anvilcraft:giant_anvil{cube:corner,half:bottom_center}",
        "anvilcraft:giant_anvil{cube:corner,half:bottom_s}",
        "anvilcraft:giant_anvil{cube:corner,half:bottom_en}",
        "anvilcraft:giant_anvil{cube:corner,half:bottom_e}",
        "anvilcraft:giant_anvil{cube:corner,half:bottom_es}",
        "minecraft:redstone_torch{lit:false}",
        "anvilcraft:giant_anvil{cube:corner,half:mid_wn}",
        "anvilcraft:giant_anvil{cube:corner,half:mid_w}",
        "anvilcraft:giant_anvil{cube:corner,half:mid_ws}",
        "anvilcraft:giant_anvil{cube:corner,half:mid_n}",
        "anvilcraft:giant_anvil{cube:center,half:mid_center}",
        "anvilcraft:giant_anvil{cube:corner,half:mid_s}",
        "anvilcraft:giant_anvil{cube:corner,half:mid_en}",
        "anvilcraft:giant_anvil{cube:corner,half:mid_e}",
        "anvilcraft:giant_anvil{cube:corner,half:mid_es}",
        "anvilcraft:giant_anvil{cube:corner,half:top_wn}",
        "anvilcraft:giant_anvil{cube:corner,half:top_w}",
        "anvilcraft:giant_anvil{cube:corner,half:top_ws}",
        "anvilcraft:giant_anvil{cube:corner,half:top_n}",
        "anvilcraft:giant_anvil{cube:corner,half:top_center}",
        "anvilcraft:giant_anvil{cube:corner,half:top_s}",
        "anvilcraft:giant_anvil{cube:corner,half:top_en}",
        "anvilcraft:giant_anvil{cube:corner,half:top_e}",
        "anvilcraft:giant_anvil{cube:corner,half:top_es}",
        "minecraft:redstone_wire{east:side,north:side,power:0,south:side,west:side}",
        "anvilcraft:induction_light{axis:y,color:pink,overload:false,powered:false,waterlogged:false}",
        "anvilcraft:chute{enabled:true,facing:east}",
        "minecraft:chest{facing:east,type:left,waterlogged:false}",
        "minecraft:chest{facing:east,type:right,waterlogged:false}",
        "anvilcraft:magnetic_chute{enabled:true,facing:north}",
        "anvilcraft:simple_chute{enabled:true,facing:east,tall:false,waterlogged:false}",
        "anvilcraft:item_collector{overload:false,powered:false}",
        "anvilcraft:magnetic_chute{enabled:true,facing:east}",
        "anvilcraft:simple_chute{enabled:true,facing:down,tall:false,waterlogged:false}",
        "anvilcraft:deflection_ring{facing:up,half:bottom_wn,overload:false,switch:on}",
        "anvilcraft:deflection_ring{facing:up,half:bottom_w,overload:false,switch:on}",
        "anvilcraft:deflection_ring{facing:up,half:bottom_ws,overload:false,switch:on}",
        "anvilcraft:deflection_ring{facing:up,half:bottom_n,overload:false,switch:on}",
        "anvilcraft:deflection_ring{facing:up,half:bottom_center,overload:false,switch:on}",
        "anvilcraft:deflection_ring{facing:up,half:bottom_s,overload:false,switch:on}",
        "anvilcraft:deflection_ring{facing:up,half:bottom_en,overload:false,switch:on}",
        "anvilcraft:deflection_ring{facing:up,half:bottom_e,overload:false,switch:on}",
        "anvilcraft:deflection_ring{facing:up,half:bottom_es,overload:false,switch:on}",
        "anvilcraft:deflection_ring{facing:up,half:mid_wn,overload:false,switch:on}",
        "anvilcraft:deflection_ring{facing:up,half:mid_w,overload:false,switch:on}",
        "anvilcraft:deflection_ring{facing:up,half:mid_ws,overload:false,switch:on}",
        "anvilcraft:deflection_ring{facing:up,half:mid_n,overload:false,switch:on}",
        "anvilcraft:deflection_ring{facing:up,half:mid_center,overload:false,switch:on}",
        "anvilcraft:deflection_ring{facing:up,half:mid_s,overload:false,switch:on}",
        "anvilcraft:deflection_ring{facing:up,half:mid_en,overload:false,switch:on}",
        "anvilcraft:deflection_ring{facing:up,half:mid_e,overload:false,switch:on}",
        "anvilcraft:deflection_ring{facing:up,half:mid_es,overload:false,switch:on}",
        "anvilcraft:deflection_ring{facing:up,half:top_wn,overload:false,switch:on}",
        "anvilcraft:deflection_ring{facing:up,half:top_w,overload:false,switch:on}",
        "anvilcraft:deflection_ring{facing:up,half:top_ws,overload:false,switch:on}",
        "anvilcraft:deflection_ring{facing:up,half:top_n,overload:false,switch:on}",
        "anvilcraft:deflection_ring{facing:up,half:top_center,overload:false,switch:on}",
        "anvilcraft:deflection_ring{facing:up,half:top_s,overload:false,switch:on}",
        "anvilcraft:deflection_ring{facing:up,half:top_en,overload:false,switch:on}",
        "anvilcraft:deflection_ring{facing:up,half:top_e,overload:false,switch:on}",
        "anvilcraft:deflection_ring{facing:up,half:top_es,overload:false,switch:on}"
    ]
}